==90231== Memcheck, a memory error detector
==90231== Copyright (C) 2002-2024, and GNU GPL'd, by Julian Seward et al.
==90231== Using Valgrind-3.23.0 and LibVEX; rerun with -h for copyright info
==90231== Command: python3 test.py
==90231== Parent PID: 90028
==90231== 
==90231== 
==90231== HEAP SUMMARY:
==90231==     in use at exit: 621,828 bytes in 309 blocks
==90231==   total heap usage: 18,904 allocs, 18,595 frees, 45,450,647 bytes allocated
==90231== 
==90231== 175 bytes in 8 blocks are still reachable in loss record 1 of 72
==90231==    at 0x4842788: malloc (vg_replace_malloc.c:446)
==90231==    by 0x402587F: malloc (rtld-malloc.h:56)
==90231==    by 0x402587F: strdup (strdup.c:42)
==90231==    by 0x4014B49: _dl_load_cache_lookup (dl-cache.c:515)
==90231==    by 0x4008EFF: _dl_map_object (dl-load.c:2116)
==90231==    by 0x400287C: openaux (dl-deps.c:64)
==90231==    by 0x4001522: _dl_catch_exception (dl-catch.c:237)
==90231==    by 0x4002D04: _dl_map_object_deps (dl-deps.c:232)
==90231==    by 0x400CA04: dl_open_worker_begin (dl-open.c:638)
==90231==    by 0x4001522: _dl_catch_exception (dl-catch.c:237)
==90231==    by 0x400C0DF: dl_open_worker (dl-open.c:803)
==90231==    by 0x4001522: _dl_catch_exception (dl-catch.c:237)
==90231==    by 0x400C533: _dl_open (dl-open.c:905)
==90231== 
==90231== 175 bytes in 8 blocks are still reachable in loss record 2 of 72
==90231==    at 0x4842788: malloc (vg_replace_malloc.c:446)
==90231==    by 0x400BE60: malloc (rtld-malloc.h:56)
==90231==    by 0x400BE60: _dl_new_object (dl-object.c:199)
==90231==    by 0x4007269: _dl_map_object_from_fd (dl-load.c:1053)
==90231==    by 0x4008C97: _dl_map_object (dl-load.c:2249)
==90231==    by 0x400287C: openaux (dl-deps.c:64)
==90231==    by 0x4001522: _dl_catch_exception (dl-catch.c:237)
==90231==    by 0x4002D04: _dl_map_object_deps (dl-deps.c:232)
==90231==    by 0x400CA04: dl_open_worker_begin (dl-open.c:638)
==90231==    by 0x4001522: _dl_catch_exception (dl-catch.c:237)
==90231==    by 0x400C0DF: dl_open_worker (dl-open.c:803)
==90231==    by 0x4001522: _dl_catch_exception (dl-catch.c:237)
==90231==    by 0x400C533: _dl_open (dl-open.c:905)
==90231== 
==90231== 568 bytes in 1 blocks are still reachable in loss record 3 of 72
==90231==    at 0x4842788: malloc (vg_replace_malloc.c:446)
==90231==    by 0x49F0714: UnknownInlinedFun (obmalloc.c:45)
==90231==    by 0x49F0714: UnknownInlinedFun (obmalloc.c:662)
==90231==    by 0x49F0714: UnknownInlinedFun (obmalloc.c:1569)
==90231==    by 0x49F0714: UnknownInlinedFun (obmalloc.c:801)
==90231==    by 0x49F0714: UnknownInlinedFun (dictobject.c:641)
==90231==    by 0x49F0714: dictresize (dictobject.c:1449)
==90231==    by 0x49EFD72: UnknownInlinedFun (dictobject.c:1194)
==90231==    by 0x49EFD72: insertdict (dictobject.c:1261)
==90231==    by 0x4AC4949: add_subclass (typeobject.c:7618)
==90231==    by 0x49E7029: UnknownInlinedFun (typeobject.c:7352)
==90231==    by 0x49E7029: type_ready (typeobject.c:7515)
==90231==    by 0x4AC7DB8: UnknownInlinedFun (typeobject.c:3795)
==90231==    by 0x4AC7DB8: type_new (typeobject.c:3929)
==90231==    by 0x6494078: PyCFuncPtrType_new (_ctypes.c:2553)
==90231==    by 0x49FD975: UnknownInlinedFun (typeobject.c:1664)
==90231==    by 0x49FD975: _PyObject_MakeTpCall (call.c:240)
==90231==    by 0x4ACB65B: builtin___build_class__ (bltinmodule.c:208)
==90231==    by 0x4A097D8: _PyEval_EvalFrameDefault (bytecodes.c:2974)
==90231==    by 0x4ACB621: builtin___build_class__ (bltinmodule.c:200)
==90231==    by 0x4A21CBD: cfunction_vectorcall_FASTCALL_KEYWORDS (methodobject.c:438)
==90231== 
==90231== 657 bytes in 1 blocks are still reachable in loss record 4 of 72
==90231==    at 0x4842788: malloc (vg_replace_malloc.c:446)
==90231==    by 0x49E42F6: UnknownInlinedFun (obmalloc.c:45)
==90231==    by 0x49E42F6: UnknownInlinedFun (obmalloc.c:662)
==90231==    by 0x49E42F6: UnknownInlinedFun (obmalloc.c:1569)
==90231==    by 0x49E42F6: PyObject_Malloc (obmalloc.c:801)
==90231==    by 0x4AC823C: UnknownInlinedFun (typeobject.c:3467)
==90231==    by 0x4AC823C: UnknownInlinedFun (typeobject.c:3679)
==90231==    by 0x4AC823C: UnknownInlinedFun (typeobject.c:3790)
==90231==    by 0x4AC823C: type_new (typeobject.c:3929)
==90231==    by 0x49FD975: UnknownInlinedFun (typeobject.c:1664)
==90231==    by 0x49FD975: _PyObject_MakeTpCall (call.c:240)
==90231==    by 0x4A0093B: _PyObject_FastCallDictTstate (call.c:133)
==90231==    by 0x4ACB65B: builtin___build_class__ (bltinmodule.c:208)
==90231==    by 0x4A21CBD: cfunction_vectorcall_FASTCALL_KEYWORDS (methodobject.c:438)
==90231==    by 0x4A21B6C: UnknownInlinedFun (pycore_call.h:92)
==90231==    by 0x4A21B6C: PyObject_Vectorcall (call.c:325)
==90231==    by 0x4A0631E: _PyEval_EvalFrameDefault (bytecodes.c:2714)
==90231==    by 0x4ACA0F4: PyEval_EvalCode (ceval.c:578)
==90231==    by 0x4AE5705: UnknownInlinedFun (bltinmodule.c:1096)
==90231==    by 0x4AE5705: builtin_exec (bltinmodule.c.h:586)
==90231==    by 0x4A097D8: _PyEval_EvalFrameDefault (bytecodes.c:2974)
==90231== 
==90231== 768 bytes in 1 blocks are still reachable in loss record 5 of 72
==90231==    at 0x4849E20: realloc (vg_replace_malloc.c:1800)
==90231==    by 0x4ABF4B9: UnknownInlinedFun (obmalloc.c:680)
==90231==    by 0x4ABF4B9: UnknownInlinedFun (obmalloc.c:1175)
==90231==    by 0x4ABF4B9: allocate_from_new_pool (obmalloc.c:1389)
==90231==    by 0x49E40D8: UnknownInlinedFun (obmalloc.c:1553)
==90231==    by 0x49E40D8: UnknownInlinedFun (obmalloc.c:1564)
==90231==    by 0x49E40D8: UnknownInlinedFun (obmalloc.c:801)
==90231==    by 0x49E40D8: UnknownInlinedFun (gcmodule.c:2307)
==90231==    by 0x49E40D8: _PyObject_GC_New (gcmodule.c:2322)
==90231==    by 0x49E3DE3: UnknownInlinedFun (dictobject.c:748)
==90231==    by 0x49E3DE3: PyDict_New (dictobject.c:851)
==90231==    by 0x4ABCBC2: UnknownInlinedFun (unicodeobject.c:287)
==90231==    by 0x4ABCBC2: UnknownInlinedFun (unicodeobject.c:14708)
==90231==    by 0x4ABCBC2: UnknownInlinedFun (pylifecycle.c:678)
==90231==    by 0x4ABCBC2: pycore_interp_init (pylifecycle.c:826)
==90231==    by 0x4AB76ED: UnknownInlinedFun (pylifecycle.c:897)
==90231==    by 0x4AB76ED: pyinit_core.constprop.0 (pylifecycle.c:1060)
==90231==    by 0x4AB6EF2: Py_InitializeFromConfig (pylifecycle.c:1282)
==90231==    by 0x4AB6C10: pymain_init (main.c:67)
==90231==    by 0x4AB5AB0: pymain_main (main.c:730)
==90231==    by 0x4AB560B: Py_BytesMain (main.c:763)
==90231==    by 0x4ECDC87: (below main) (libc_start_call_main.h:58)
==90231== 
==90231== 768 bytes in 1 blocks are still reachable in loss record 6 of 72
==90231==    at 0x4842788: malloc (vg_replace_malloc.c:446)
==90231==    by 0x49F42E6: UnknownInlinedFun (obmalloc.c:45)
==90231==    by 0x49F42E6: UnknownInlinedFun (obmalloc.c:662)
==90231==    by 0x49F42E6: UnknownInlinedFun (obmalloc.c:1569)
==90231==    by 0x49F42E6: UnknownInlinedFun (obmalloc.c:801)
==90231==    by 0x49F42E6: clone_combined_dict_keys (dictobject.c:799)
==90231==    by 0x4AC605C: PyDict_Copy (dictobject.c:3071)
==90231==    by 0x4AC7955: UnknownInlinedFun (typeobject.c:3748)
==90231==    by 0x4AC7955: UnknownInlinedFun (typeobject.c:3785)
==90231==    by 0x4AC7955: type_new (typeobject.c:3929)
==90231==    by 0x4A5F465: tp_new_wrapper (typeobject.c:8312)
==90231==    by 0x4A2DA86: cfunction_call (methodobject.c:537)
==90231==    by 0x4A3FA59: _PyObject_Call (call.c:367)
==90231==    by 0x4A0B71A: UnknownInlinedFun (call.c:387)
==90231==    by 0x4A0B71A: _PyEval_EvalFrameDefault (bytecodes.c:3262)
==90231==    by 0x4A00845: UnknownInlinedFun (pycore_ceval.h:89)
==90231==    by 0x4A00845: UnknownInlinedFun (ceval.c:1683)
==90231==    by 0x4A00845: UnknownInlinedFun (call.c:419)
==90231==    by 0x4A00845: _PyObject_FastCallDictTstate (call.c:133)
==90231==    by 0x4A5F116: UnknownInlinedFun (call.c:508)
==90231==    by 0x4A5F116: slot_tp_new (typeobject.c:9050)
==90231==    by 0x49FD975: UnknownInlinedFun (typeobject.c:1664)
==90231==    by 0x49FD975: _PyObject_MakeTpCall (call.c:240)
==90231==    by 0x4ACB65B: builtin___build_class__ (bltinmodule.c:208)
==90231== 
==90231== 768 bytes in 1 blocks are still reachable in loss record 7 of 72
==90231==    at 0x4842788: malloc (vg_replace_malloc.c:446)
==90231==    by 0x49E42F6: UnknownInlinedFun (obmalloc.c:45)
==90231==    by 0x49E42F6: UnknownInlinedFun (obmalloc.c:662)
==90231==    by 0x49E42F6: UnknownInlinedFun (obmalloc.c:1569)
==90231==    by 0x49E42F6: PyObject_Malloc (obmalloc.c:801)
==90231==    by 0x4AC4555: new_keys_object (dictobject.c:641)
==90231==    by 0x49E7B62: UnknownInlinedFun (dictobject.c:5321)
==90231==    by 0x49E7B62: UnknownInlinedFun (typeobject.c:7420)
==90231==    by 0x49E7B62: type_ready (typeobject.c:7519)
==90231==    by 0x4AC7DB8: UnknownInlinedFun (typeobject.c:3795)
==90231==    by 0x4AC7DB8: type_new (typeobject.c:3929)
==90231==    by 0x49FD975: UnknownInlinedFun (typeobject.c:1664)
==90231==    by 0x49FD975: _PyObject_MakeTpCall (call.c:240)
==90231==    by 0x4ACB65B: builtin___build_class__ (bltinmodule.c:208)
==90231==    by 0x4A21CBD: cfunction_vectorcall_FASTCALL_KEYWORDS (methodobject.c:438)
==90231==    by 0x4A21B6C: UnknownInlinedFun (pycore_call.h:92)
==90231==    by 0x4A21B6C: PyObject_Vectorcall (call.c:325)
==90231==    by 0x4A0631E: _PyEval_EvalFrameDefault (bytecodes.c:2714)
==90231==    by 0x4ACA0F4: PyEval_EvalCode (ceval.c:578)
==90231==    by 0x4AE5705: UnknownInlinedFun (bltinmodule.c:1096)
==90231==    by 0x4AE5705: builtin_exec (bltinmodule.c.h:586)
==90231== 
==90231== 768 bytes in 1 blocks are still reachable in loss record 8 of 72
==90231==    at 0x4842788: malloc (vg_replace_malloc.c:446)
==90231==    by 0x49E42F6: UnknownInlinedFun (obmalloc.c:45)
==90231==    by 0x49E42F6: UnknownInlinedFun (obmalloc.c:662)
==90231==    by 0x49E42F6: UnknownInlinedFun (obmalloc.c:1569)
==90231==    by 0x49E42F6: PyObject_Malloc (obmalloc.c:801)
==90231==    by 0x4AC4555: new_keys_object (dictobject.c:641)
==90231==    by 0x49E7B62: UnknownInlinedFun (dictobject.c:5321)
==90231==    by 0x49E7B62: UnknownInlinedFun (typeobject.c:7420)
==90231==    by 0x49E7B62: type_ready (typeobject.c:7519)
==90231==    by 0x4AC7DB8: UnknownInlinedFun (typeobject.c:3795)
==90231==    by 0x4AC7DB8: type_new (typeobject.c:3929)
==90231==    by 0x6494078: PyCFuncPtrType_new (_ctypes.c:2553)
==90231==    by 0x49FD975: UnknownInlinedFun (typeobject.c:1664)
==90231==    by 0x49FD975: _PyObject_MakeTpCall (call.c:240)
==90231==    by 0x4ACB65B: builtin___build_class__ (bltinmodule.c:208)
==90231==    by 0x4A21CBD: cfunction_vectorcall_FASTCALL_KEYWORDS (methodobject.c:438)
==90231==    by 0x4A21B6C: UnknownInlinedFun (pycore_call.h:92)
==90231==    by 0x4A21B6C: PyObject_Vectorcall (call.c:325)
==90231==    by 0x4A0631E: _PyEval_EvalFrameDefault (bytecodes.c:2714)
==90231==    by 0x4A00845: UnknownInlinedFun (pycore_ceval.h:89)
==90231==    by 0x4A00845: UnknownInlinedFun (ceval.c:1683)
==90231==    by 0x4A00845: UnknownInlinedFun (call.c:419)
==90231==    by 0x4A00845: _PyObject_FastCallDictTstate (call.c:133)
==90231== 
==90231== 768 bytes in 1 blocks are still reachable in loss record 9 of 72
==90231==    at 0x4842788: malloc (vg_replace_malloc.c:446)
==90231==    by 0x49E42F6: UnknownInlinedFun (obmalloc.c:45)
==90231==    by 0x49E42F6: UnknownInlinedFun (obmalloc.c:662)
==90231==    by 0x49E42F6: UnknownInlinedFun (obmalloc.c:1569)
==90231==    by 0x49E42F6: PyObject_Malloc (obmalloc.c:801)
==90231==    by 0x4AC4555: new_keys_object (dictobject.c:641)
==90231==    by 0x49E7B62: UnknownInlinedFun (dictobject.c:5321)
==90231==    by 0x49E7B62: UnknownInlinedFun (typeobject.c:7420)
==90231==    by 0x49E7B62: type_ready (typeobject.c:7519)
==90231==    by 0x4AC7DB8: UnknownInlinedFun (typeobject.c:3795)
==90231==    by 0x4AC7DB8: type_new (typeobject.c:3929)
==90231==    by 0x6494078: PyCFuncPtrType_new (_ctypes.c:2553)
==90231==    by 0x49FD975: UnknownInlinedFun (typeobject.c:1664)
==90231==    by 0x49FD975: _PyObject_MakeTpCall (call.c:240)
==90231==    by 0x4ACB65B: builtin___build_class__ (bltinmodule.c:208)
==90231==    by 0x4A097D8: _PyEval_EvalFrameDefault (bytecodes.c:2974)
==90231==    by 0x4ACA0F4: PyEval_EvalCode (ceval.c:578)
==90231==    by 0x4AE5705: UnknownInlinedFun (bltinmodule.c:1096)
==90231==    by 0x4AE5705: builtin_exec (bltinmodule.c.h:586)
==90231==    by 0x4A21CBD: cfunction_vectorcall_FASTCALL_KEYWORDS (methodobject.c:438)
==90231== 
==90231== 768 bytes in 1 blocks are still reachable in loss record 10 of 72
==90231==    at 0x4842788: malloc (vg_replace_malloc.c:446)
==90231==    by 0x49F0714: UnknownInlinedFun (obmalloc.c:45)
==90231==    by 0x49F0714: UnknownInlinedFun (obmalloc.c:662)
==90231==    by 0x49F0714: UnknownInlinedFun (obmalloc.c:1569)
==90231==    by 0x49F0714: UnknownInlinedFun (obmalloc.c:801)
==90231==    by 0x49F0714: UnknownInlinedFun (dictobject.c:641)
==90231==    by 0x49F0714: dictresize (dictobject.c:1449)
==90231==    by 0x49F0ECE: PyDict_SetDefault (dictobject.c:3332)
==90231==    by 0x49E7CAC: UnknownInlinedFun (typeobject.c:6628)
==90231==    by 0x49E7CAC: UnknownInlinedFun (typeobject.c:6654)
==90231==    by 0x49E7CAC: UnknownInlinedFun (typeobject.c:7155)
==90231==    by 0x49E7CAC: type_ready (typeobject.c:7501)
==90231==    by 0x4AD652F: PyModule_AddType (modsupport.c:688)
==90231==    by 0x75C51F4: UnknownInlinedFun (_datetimemodule.c:6734)
==90231==    by 0x75C51F4: PyInit__datetime (_datetimemodule.c:6936)
==90231==    by 0x4AFE037: UnknownInlinedFun (importdl.c:169)
==90231==    by 0x4AFE037: UnknownInlinedFun (import.c:3775)
==90231==    by 0x4AFE037: _imp_create_dynamic (import.c.h:506)
==90231==    by 0x4A2E3CA: cfunction_vectorcall_FASTCALL (methodobject.c:422)
==90231==    by 0x4A0B71A: UnknownInlinedFun (call.c:387)
==90231==    by 0x4A0B71A: _PyEval_EvalFrameDefault (bytecodes.c:3262)
==90231==    by 0x4A2C9FA: UnknownInlinedFun (pycore_call.h:92)
==90231==    by 0x4A2C9FA: object_vacall (call.c:850)
==90231==    by 0x4A5DF4A: PyObject_CallMethodObjArgs (call.c:911)
==90231==    by 0x4A5D020: UnknownInlinedFun (import.c:2779)
==90231==    by 0x4A5D020: PyImport_ImportModuleLevelObject (import.c:2862)
==90231== 
==90231== 768 bytes in 1 blocks are still reachable in loss record 11 of 72
==90231==    at 0x4842788: malloc (vg_replace_malloc.c:446)
==90231==    by 0x49F0714: UnknownInlinedFun (obmalloc.c:45)
==90231==    by 0x49F0714: UnknownInlinedFun (obmalloc.c:662)
==90231==    by 0x49F0714: UnknownInlinedFun (obmalloc.c:1569)
==90231==    by 0x49F0714: UnknownInlinedFun (obmalloc.c:801)
==90231==    by 0x49F0714: UnknownInlinedFun (dictobject.c:641)
==90231==    by 0x49F0714: dictresize (dictobject.c:1449)
==90231==    by 0x49EFD72: UnknownInlinedFun (dictobject.c:1194)
==90231==    by 0x49EFD72: insertdict (dictobject.c:1261)
==90231==    by 0x49E6C60: UnknownInlinedFun (dictobject.c:1865)
==90231==    by 0x49E6C60: UnknownInlinedFun (dictobject.c:1883)
==90231==    by 0x49E6C60: UnknownInlinedFun (typeobject.c:10140)
==90231==    by 0x49E6C60: UnknownInlinedFun (typeobject.c:7152)
==90231==    by 0x49E6C60: type_ready (typeobject.c:7501)
==90231==    by 0x4AD652F: PyModule_AddType (modsupport.c:688)
==90231==    by 0x75C51F4: UnknownInlinedFun (_datetimemodule.c:6734)
==90231==    by 0x75C51F4: PyInit__datetime (_datetimemodule.c:6936)
==90231==    by 0x4AFE037: UnknownInlinedFun (importdl.c:169)
==90231==    by 0x4AFE037: UnknownInlinedFun (import.c:3775)
==90231==    by 0x4AFE037: _imp_create_dynamic (import.c.h:506)
==90231==    by 0x4A2E3CA: cfunction_vectorcall_FASTCALL (methodobject.c:422)
==90231==    by 0x4A0B71A: UnknownInlinedFun (call.c:387)
==90231==    by 0x4A0B71A: _PyEval_EvalFrameDefault (bytecodes.c:3262)
==90231==    by 0x4A2C9FA: UnknownInlinedFun (pycore_call.h:92)
==90231==    by 0x4A2C9FA: object_vacall (call.c:850)
==90231==    by 0x4A5DF4A: PyObject_CallMethodObjArgs (call.c:911)
==90231==    by 0x4A5D020: UnknownInlinedFun (import.c:2779)
==90231==    by 0x4A5D020: PyImport_ImportModuleLevelObject (import.c:2862)
==90231== 
==90231== 768 bytes in 1 blocks are still reachable in loss record 12 of 72
==90231==    at 0x4842788: malloc (vg_replace_malloc.c:446)
==90231==    by 0x49E42F6: UnknownInlinedFun (obmalloc.c:45)
==90231==    by 0x49E42F6: UnknownInlinedFun (obmalloc.c:662)
==90231==    by 0x49E42F6: UnknownInlinedFun (obmalloc.c:1569)
==90231==    by 0x49E42F6: PyObject_Malloc (obmalloc.c:801)
==90231==    by 0x4AC4555: new_keys_object (dictobject.c:641)
==90231==    by 0x49E7B62: UnknownInlinedFun (dictobject.c:5321)
==90231==    by 0x49E7B62: UnknownInlinedFun (typeobject.c:7420)
==90231==    by 0x49E7B62: type_ready (typeobject.c:7519)
==90231==    by 0x4AC7DB8: UnknownInlinedFun (typeobject.c:3795)
==90231==    by 0x4AC7DB8: type_new (typeobject.c:3929)
==90231==    by 0x4A5F465: tp_new_wrapper (typeobject.c:8312)
==90231==    by 0x4A2DA86: cfunction_call (methodobject.c:537)
==90231==    by 0x4A3FA59: _PyObject_Call (call.c:367)
==90231==    by 0x4A0B71A: UnknownInlinedFun (call.c:387)
==90231==    by 0x4A0B71A: _PyEval_EvalFrameDefault (bytecodes.c:3262)
==90231==    by 0x4A00845: UnknownInlinedFun (pycore_ceval.h:89)
==90231==    by 0x4A00845: UnknownInlinedFun (ceval.c:1683)
==90231==    by 0x4A00845: UnknownInlinedFun (call.c:419)
==90231==    by 0x4A00845: _PyObject_FastCallDictTstate (call.c:133)
==90231==    by 0x4A5F116: UnknownInlinedFun (call.c:508)
==90231==    by 0x4A5F116: slot_tp_new (typeobject.c:9050)
==90231==    by 0x4AC891D: UnknownInlinedFun (typeobject.c:3864)
==90231==    by 0x4AC891D: type_new (typeobject.c:3917)
==90231== 
==90231== 824 bytes in 1 blocks are still reachable in loss record 13 of 72
==90231==    at 0x4842788: malloc (vg_replace_malloc.c:446)
==90231==    by 0x49FC8A9: UnknownInlinedFun (obmalloc.c:45)
==90231==    by 0x49FC8A9: UnknownInlinedFun (obmalloc.c:662)
==90231==    by 0x49FC8A9: UnknownInlinedFun (obmalloc.c:1569)
==90231==    by 0x49FC8A9: UnknownInlinedFun (obmalloc.c:801)
==90231==    by 0x49FC8A9: UnknownInlinedFun (object.c:332)
==90231==    by 0x49FC8A9: _PyCode_New (codeobject.c:582)
==90231==    by 0x4A04826: r_object (marshal.c:1454)
==90231==    by 0x4A04439: r_object (marshal.c:1223)
==90231==    by 0x4A04688: r_object (marshal.c:1394)
==90231==    by 0x4A04439: r_object (marshal.c:1223)
==90231==    by 0x4A04688: r_object (marshal.c:1394)
==90231==    by 0x4ACABB8: read_object (marshal.c:1525)
==90231==    by 0x4AF1209: UnknownInlinedFun (marshal.c:1832)
==90231==    by 0x4AF1209: marshal_loads (marshal.c.h:154)
==90231==    by 0x4A0697B: _PyEval_EvalFrameDefault (bytecodes.c:2912)
==90231==    by 0x4A2C9FA: UnknownInlinedFun (pycore_call.h:92)
==90231==    by 0x4A2C9FA: object_vacall (call.c:850)
==90231==    by 0x4A5DF4A: PyObject_CallMethodObjArgs (call.c:911)
==90231== 
==90231== 976 bytes in 1 blocks are still reachable in loss record 14 of 72
==90231==    at 0x4842788: malloc (vg_replace_malloc.c:446)
==90231==    by 0x49ED7FD: UnknownInlinedFun (obmalloc.c:45)
==90231==    by 0x49ED7FD: UnknownInlinedFun (obmalloc.c:662)
==90231==    by 0x49ED7FD: UnknownInlinedFun (obmalloc.c:1569)
==90231==    by 0x49ED7FD: UnknownInlinedFun (obmalloc.c:801)
==90231==    by 0x49ED7FD: UnknownInlinedFun (typeobject.c:1701)
==90231==    by 0x49ED7FD: PyType_GenericAlloc (typeobject.c:1725)
==90231==    by 0x4AC4D79: _PyType_FromMetaclass_impl (typeobject.c:4305)
==90231==    by 0x4AF5B21: _abcmodule_exec (_abc.c:915)
==90231==    by 0x4AD1A71: PyModule_ExecDef (moduleobject.c:440)
==90231==    by 0x4AD6353: UnknownInlinedFun (import.c:3818)
==90231==    by 0x4AD6353: _imp_exec_builtin (import.c.h:564)
==90231==    by 0x4A2AF6B: cfunction_vectorcall_O (methodobject.c:509)
==90231==    by 0x4A0B71A: UnknownInlinedFun (call.c:387)
==90231==    by 0x4A0B71A: _PyEval_EvalFrameDefault (bytecodes.c:3262)
==90231==    by 0x4A2C9FA: UnknownInlinedFun (pycore_call.h:92)
==90231==    by 0x4A2C9FA: object_vacall (call.c:850)
==90231==    by 0x4A5DF4A: PyObject_CallMethodObjArgs (call.c:911)
==90231==    by 0x4A5D020: UnknownInlinedFun (import.c:2779)
==90231==    by 0x4A5D020: PyImport_ImportModuleLevelObject (import.c:2862)
==90231==    by 0x4A0BF9F: UnknownInlinedFun (ceval.c:2482)
==90231==    by 0x4A0BF9F: _PyEval_EvalFrameDefault (bytecodes.c:2143)
==90231== 
==90231== 976 bytes in 1 blocks are still reachable in loss record 15 of 72
==90231==    at 0x4842788: malloc (vg_replace_malloc.c:446)
==90231==    by 0x49ED7FD: UnknownInlinedFun (obmalloc.c:45)
==90231==    by 0x49ED7FD: UnknownInlinedFun (obmalloc.c:662)
==90231==    by 0x49ED7FD: UnknownInlinedFun (obmalloc.c:1569)
==90231==    by 0x49ED7FD: UnknownInlinedFun (obmalloc.c:801)
==90231==    by 0x49ED7FD: UnknownInlinedFun (typeobject.c:1701)
==90231==    by 0x49ED7FD: PyType_GenericAlloc (typeobject.c:1725)
==90231==    by 0x4AC84C4: UnknownInlinedFun (typeobject.c:3322)
==90231==    by 0x4AC84C4: UnknownInlinedFun (typeobject.c:3762)
==90231==    by 0x4AC84C4: UnknownInlinedFun (typeobject.c:3785)
==90231==    by 0x4AC84C4: type_new (typeobject.c:3929)
==90231==    by 0x49FD975: UnknownInlinedFun (typeobject.c:1664)
==90231==    by 0x49FD975: _PyObject_MakeTpCall (call.c:240)
==90231==    by 0x4A0093B: _PyObject_FastCallDictTstate (call.c:133)
==90231==    by 0x4ACB65B: builtin___build_class__ (bltinmodule.c:208)
==90231==    by 0x4A21CBD: cfunction_vectorcall_FASTCALL_KEYWORDS (methodobject.c:438)
==90231==    by 0x4A21B6C: UnknownInlinedFun (pycore_call.h:92)
==90231==    by 0x4A21B6C: PyObject_Vectorcall (call.c:325)
==90231==    by 0x4A0631E: _PyEval_EvalFrameDefault (bytecodes.c:2714)
==90231==    by 0x4ACA0F4: PyEval_EvalCode (ceval.c:578)
==90231==    by 0x4AE5705: UnknownInlinedFun (bltinmodule.c:1096)
==90231==    by 0x4AE5705: builtin_exec (bltinmodule.c.h:586)
==90231==    by 0x4A097D8: _PyEval_EvalFrameDefault (bytecodes.c:2974)
==90231== 
==90231== 976 bytes in 1 blocks are still reachable in loss record 16 of 72
==90231==    at 0x4842788: malloc (vg_replace_malloc.c:446)
==90231==    by 0x49ED7FD: UnknownInlinedFun (obmalloc.c:45)
==90231==    by 0x49ED7FD: UnknownInlinedFun (obmalloc.c:662)
==90231==    by 0x49ED7FD: UnknownInlinedFun (obmalloc.c:1569)
==90231==    by 0x49ED7FD: UnknownInlinedFun (obmalloc.c:801)
==90231==    by 0x49ED7FD: UnknownInlinedFun (typeobject.c:1701)
==90231==    by 0x49ED7FD: PyType_GenericAlloc (typeobject.c:1725)
==90231==    by 0x4AC4D79: _PyType_FromMetaclass_impl (typeobject.c:4305)
==90231==    by 0x4AFC602: collections_exec (_collectionsmodule.c:2560)
==90231==    by 0x4AD1A71: PyModule_ExecDef (moduleobject.c:440)
==90231==    by 0x4AD6353: UnknownInlinedFun (import.c:3818)
==90231==    by 0x4AD6353: _imp_exec_builtin (import.c.h:564)
==90231==    by 0x4A2AF6B: cfunction_vectorcall_O (methodobject.c:509)
==90231==    by 0x4A0B71A: UnknownInlinedFun (call.c:387)
==90231==    by 0x4A0B71A: _PyEval_EvalFrameDefault (bytecodes.c:3262)
==90231==    by 0x4A2C9FA: UnknownInlinedFun (pycore_call.h:92)
==90231==    by 0x4A2C9FA: object_vacall (call.c:850)
==90231==    by 0x4A5DF4A: PyObject_CallMethodObjArgs (call.c:911)
==90231==    by 0x4A5D020: UnknownInlinedFun (import.c:2779)
==90231==    by 0x4A5D020: PyImport_ImportModuleLevelObject (import.c:2862)
==90231==    by 0x4A0BF9F: UnknownInlinedFun (ceval.c:2482)
==90231==    by 0x4A0BF9F: _PyEval_EvalFrameDefault (bytecodes.c:2143)
==90231== 
==90231== 976 bytes in 1 blocks are still reachable in loss record 17 of 72
==90231==    at 0x4842788: malloc (vg_replace_malloc.c:446)
==90231==    by 0x49ED7FD: UnknownInlinedFun (obmalloc.c:45)
==90231==    by 0x49ED7FD: UnknownInlinedFun (obmalloc.c:662)
==90231==    by 0x49ED7FD: UnknownInlinedFun (obmalloc.c:1569)
==90231==    by 0x49ED7FD: UnknownInlinedFun (obmalloc.c:801)
==90231==    by 0x49ED7FD: UnknownInlinedFun (typeobject.c:1701)
==90231==    by 0x49ED7FD: PyType_GenericAlloc (typeobject.c:1725)
==90231==    by 0x4AC4D79: _PyType_FromMetaclass_impl (typeobject.c:4305)
==90231==    by 0x4AFC637: collections_exec (_collectionsmodule.c:2561)
==90231==    by 0x4AD1A71: PyModule_ExecDef (moduleobject.c:440)
==90231==    by 0x4AD6353: UnknownInlinedFun (import.c:3818)
==90231==    by 0x4AD6353: _imp_exec_builtin (import.c.h:564)
==90231==    by 0x4A2AF6B: cfunction_vectorcall_O (methodobject.c:509)
==90231==    by 0x4A0B71A: UnknownInlinedFun (call.c:387)
==90231==    by 0x4A0B71A: _PyEval_EvalFrameDefault (bytecodes.c:3262)
==90231==    by 0x4A2C9FA: UnknownInlinedFun (pycore_call.h:92)
==90231==    by 0x4A2C9FA: object_vacall (call.c:850)
==90231==    by 0x4A5DF4A: PyObject_CallMethodObjArgs (call.c:911)
==90231==    by 0x4A5D020: UnknownInlinedFun (import.c:2779)
==90231==    by 0x4A5D020: PyImport_ImportModuleLevelObject (import.c:2862)
==90231==    by 0x4A0BF9F: UnknownInlinedFun (ceval.c:2482)
==90231==    by 0x4A0BF9F: _PyEval_EvalFrameDefault (bytecodes.c:2143)
==90231== 
==90231== 976 bytes in 1 blocks are still reachable in loss record 18 of 72
==90231==    at 0x4842788: malloc (vg_replace_malloc.c:446)
==90231==    by 0x49ED7FD: UnknownInlinedFun (obmalloc.c:45)
==90231==    by 0x49ED7FD: UnknownInlinedFun (obmalloc.c:662)
==90231==    by 0x49ED7FD: UnknownInlinedFun (obmalloc.c:1569)
==90231==    by 0x49ED7FD: UnknownInlinedFun (obmalloc.c:801)
==90231==    by 0x49ED7FD: UnknownInlinedFun (typeobject.c:1701)
==90231==    by 0x49ED7FD: PyType_GenericAlloc (typeobject.c:1725)
==90231==    by 0x4AC79E3: UnknownInlinedFun (typeobject.c:3322)
==90231==    by 0x4AC79E3: UnknownInlinedFun (typeobject.c:3762)
==90231==    by 0x4AC79E3: UnknownInlinedFun (typeobject.c:3785)
==90231==    by 0x4AC79E3: type_new (typeobject.c:3929)
==90231==    by 0x49FD975: UnknownInlinedFun (typeobject.c:1664)
==90231==    by 0x49FD975: _PyObject_MakeTpCall (call.c:240)
==90231==    by 0x4ACB65B: builtin___build_class__ (bltinmodule.c:208)
==90231==    by 0x4A21CBD: cfunction_vectorcall_FASTCALL_KEYWORDS (methodobject.c:438)
==90231==    by 0x4A21B6C: UnknownInlinedFun (pycore_call.h:92)
==90231==    by 0x4A21B6C: PyObject_Vectorcall (call.c:325)
==90231==    by 0x4A0631E: _PyEval_EvalFrameDefault (bytecodes.c:2714)
==90231==    by 0x4ACA0F4: PyEval_EvalCode (ceval.c:578)
==90231==    by 0x4AE5705: UnknownInlinedFun (bltinmodule.c:1096)
==90231==    by 0x4AE5705: builtin_exec (bltinmodule.c.h:586)
==90231==    by 0x4A21CBD: cfunction_vectorcall_FASTCALL_KEYWORDS (methodobject.c:438)
==90231==    by 0x4A0B71A: UnknownInlinedFun (call.c:387)
==90231==    by 0x4A0B71A: _PyEval_EvalFrameDefault (bytecodes.c:3262)
==90231== 
==90231== 976 bytes in 1 blocks are still reachable in loss record 19 of 72
==90231==    at 0x4842788: malloc (vg_replace_malloc.c:446)
==90231==    by 0x49ED7FD: UnknownInlinedFun (obmalloc.c:45)
==90231==    by 0x49ED7FD: UnknownInlinedFun (obmalloc.c:662)
==90231==    by 0x49ED7FD: UnknownInlinedFun (obmalloc.c:1569)
==90231==    by 0x49ED7FD: UnknownInlinedFun (obmalloc.c:801)
==90231==    by 0x49ED7FD: UnknownInlinedFun (typeobject.c:1701)
==90231==    by 0x49ED7FD: PyType_GenericAlloc (typeobject.c:1725)
==90231==    by 0x4AC79E3: UnknownInlinedFun (typeobject.c:3322)
==90231==    by 0x4AC79E3: UnknownInlinedFun (typeobject.c:3762)
==90231==    by 0x4AC79E3: UnknownInlinedFun (typeobject.c:3785)
==90231==    by 0x4AC79E3: type_new (typeobject.c:3929)
==90231==    by 0x49FD975: UnknownInlinedFun (typeobject.c:1664)
==90231==    by 0x49FD975: _PyObject_MakeTpCall (call.c:240)
==90231==    by 0x49F75D9: UnknownInlinedFun (pycore_call.h:92)
==90231==    by 0x49F75D9: UnknownInlinedFun (call.c:562)
==90231==    by 0x49F75D9: PyObject_CallFunction (call.c:584)
==90231==    by 0x4AC77D4: PyErr_NewException (errors.c:1303)
==90231==    by 0x6496B86: UnknownInlinedFun (_ctypes.c:5800)
==90231==    by 0x6496B86: PyInit__ctypes (_ctypes.c:5824)
==90231==    by 0x4AFE037: UnknownInlinedFun (importdl.c:169)
==90231==    by 0x4AFE037: UnknownInlinedFun (import.c:3775)
==90231==    by 0x4AFE037: _imp_create_dynamic (import.c.h:506)
==90231==    by 0x4A2E3CA: cfunction_vectorcall_FASTCALL (methodobject.c:422)
==90231==    by 0x4A0B71A: UnknownInlinedFun (call.c:387)
==90231==    by 0x4A0B71A: _PyEval_EvalFrameDefault (bytecodes.c:3262)
==90231==    by 0x4A2C9FA: UnknownInlinedFun (pycore_call.h:92)
==90231==    by 0x4A2C9FA: object_vacall (call.c:850)
==90231==    by 0x4A5DF4A: PyObject_CallMethodObjArgs (call.c:911)
==90231== 
==90231== 976 bytes in 1 blocks are still reachable in loss record 20 of 72
==90231==    at 0x4842788: malloc (vg_replace_malloc.c:446)
==90231==    by 0x49ED7FD: UnknownInlinedFun (obmalloc.c:45)
==90231==    by 0x49ED7FD: UnknownInlinedFun (obmalloc.c:662)
==90231==    by 0x49ED7FD: UnknownInlinedFun (obmalloc.c:1569)
==90231==    by 0x49ED7FD: UnknownInlinedFun (obmalloc.c:801)
==90231==    by 0x49ED7FD: UnknownInlinedFun (typeobject.c:1701)
==90231==    by 0x49ED7FD: PyType_GenericAlloc (typeobject.c:1725)
==90231==    by 0x4AC4D79: _PyType_FromMetaclass_impl (typeobject.c:4305)
==90231==    by 0x6496BCE: UnknownInlinedFun (_ctypes.c:5676)
==90231==    by 0x6496BCE: UnknownInlinedFun (_ctypes.c:5805)
==90231==    by 0x6496BCE: PyInit__ctypes (_ctypes.c:5824)
==90231==    by 0x4AFE037: UnknownInlinedFun (importdl.c:169)
==90231==    by 0x4AFE037: UnknownInlinedFun (import.c:3775)
==90231==    by 0x4AFE037: _imp_create_dynamic (import.c.h:506)
==90231==    by 0x4A2E3CA: cfunction_vectorcall_FASTCALL (methodobject.c:422)
==90231==    by 0x4A0B71A: UnknownInlinedFun (call.c:387)
==90231==    by 0x4A0B71A: _PyEval_EvalFrameDefault (bytecodes.c:3262)
==90231==    by 0x4A2C9FA: UnknownInlinedFun (pycore_call.h:92)
==90231==    by 0x4A2C9FA: object_vacall (call.c:850)
==90231==    by 0x4A5DF4A: PyObject_CallMethodObjArgs (call.c:911)
==90231==    by 0x4A5D020: UnknownInlinedFun (import.c:2779)
==90231==    by 0x4A5D020: PyImport_ImportModuleLevelObject (import.c:2862)
==90231==    by 0x4A0BF9F: UnknownInlinedFun (ceval.c:2482)
==90231==    by 0x4A0BF9F: _PyEval_EvalFrameDefault (bytecodes.c:2143)
==90231==    by 0x4ACA0F4: PyEval_EvalCode (ceval.c:578)
==90231== 
==90231== 976 bytes in 1 blocks are still reachable in loss record 21 of 72
==90231==    at 0x4842788: malloc (vg_replace_malloc.c:446)
==90231==    by 0x49ED7FD: UnknownInlinedFun (obmalloc.c:45)
==90231==    by 0x49ED7FD: UnknownInlinedFun (obmalloc.c:662)
==90231==    by 0x49ED7FD: UnknownInlinedFun (obmalloc.c:1569)
==90231==    by 0x49ED7FD: UnknownInlinedFun (obmalloc.c:801)
==90231==    by 0x49ED7FD: UnknownInlinedFun (typeobject.c:1701)
==90231==    by 0x49ED7FD: PyType_GenericAlloc (typeobject.c:1725)
==90231==    by 0x4AC4D79: _PyType_FromMetaclass_impl (typeobject.c:4305)
==90231==    by 0x6496DE2: UnknownInlinedFun (_ctypes.c:5709)
==90231==    by 0x6496DE2: UnknownInlinedFun (_ctypes.c:5805)
==90231==    by 0x6496DE2: PyInit__ctypes (_ctypes.c:5824)
==90231==    by 0x4AFE037: UnknownInlinedFun (importdl.c:169)
==90231==    by 0x4AFE037: UnknownInlinedFun (import.c:3775)
==90231==    by 0x4AFE037: _imp_create_dynamic (import.c.h:506)
==90231==    by 0x4A2E3CA: cfunction_vectorcall_FASTCALL (methodobject.c:422)
==90231==    by 0x4A0B71A: UnknownInlinedFun (call.c:387)
==90231==    by 0x4A0B71A: _PyEval_EvalFrameDefault (bytecodes.c:3262)
==90231==    by 0x4A2C9FA: UnknownInlinedFun (pycore_call.h:92)
==90231==    by 0x4A2C9FA: object_vacall (call.c:850)
==90231==    by 0x4A5DF4A: PyObject_CallMethodObjArgs (call.c:911)
==90231==    by 0x4A5D020: UnknownInlinedFun (import.c:2779)
==90231==    by 0x4A5D020: PyImport_ImportModuleLevelObject (import.c:2862)
==90231==    by 0x4A0BF9F: UnknownInlinedFun (ceval.c:2482)
==90231==    by 0x4A0BF9F: _PyEval_EvalFrameDefault (bytecodes.c:2143)
==90231==    by 0x4ACA0F4: PyEval_EvalCode (ceval.c:578)
==90231== 
==90231== 976 bytes in 1 blocks are still reachable in loss record 22 of 72
==90231==    at 0x4842788: malloc (vg_replace_malloc.c:446)
==90231==    by 0x49ED7FD: UnknownInlinedFun (obmalloc.c:45)
==90231==    by 0x49ED7FD: UnknownInlinedFun (obmalloc.c:662)
==90231==    by 0x49ED7FD: UnknownInlinedFun (obmalloc.c:1569)
==90231==    by 0x49ED7FD: UnknownInlinedFun (obmalloc.c:801)
==90231==    by 0x49ED7FD: UnknownInlinedFun (typeobject.c:1701)
==90231==    by 0x49ED7FD: PyType_GenericAlloc (typeobject.c:1725)
==90231==    by 0x4AC4D79: _PyType_FromMetaclass_impl (typeobject.c:4305)
==90231==    by 0x6496E06: UnknownInlinedFun (_ctypes.c:5716)
==90231==    by 0x6496E06: UnknownInlinedFun (_ctypes.c:5805)
==90231==    by 0x6496E06: PyInit__ctypes (_ctypes.c:5824)
==90231==    by 0x4AFE037: UnknownInlinedFun (importdl.c:169)
==90231==    by 0x4AFE037: UnknownInlinedFun (import.c:3775)
==90231==    by 0x4AFE037: _imp_create_dynamic (import.c.h:506)
==90231==    by 0x4A2E3CA: cfunction_vectorcall_FASTCALL (methodobject.c:422)
==90231==    by 0x4A0B71A: UnknownInlinedFun (call.c:387)
==90231==    by 0x4A0B71A: _PyEval_EvalFrameDefault (bytecodes.c:3262)
==90231==    by 0x4A2C9FA: UnknownInlinedFun (pycore_call.h:92)
==90231==    by 0x4A2C9FA: object_vacall (call.c:850)
==90231==    by 0x4A5DF4A: PyObject_CallMethodObjArgs (call.c:911)
==90231==    by 0x4A5D020: UnknownInlinedFun (import.c:2779)
==90231==    by 0x4A5D020: PyImport_ImportModuleLevelObject (import.c:2862)
==90231==    by 0x4A0BF9F: UnknownInlinedFun (ceval.c:2482)
==90231==    by 0x4A0BF9F: _PyEval_EvalFrameDefault (bytecodes.c:2143)
==90231==    by 0x4ACA0F4: PyEval_EvalCode (ceval.c:578)
==90231== 
==90231== 976 bytes in 1 blocks are still reachable in loss record 23 of 72
==90231==    at 0x4842788: malloc (vg_replace_malloc.c:446)
==90231==    by 0x49ED7FD: UnknownInlinedFun (obmalloc.c:45)
==90231==    by 0x49ED7FD: UnknownInlinedFun (obmalloc.c:662)
==90231==    by 0x49ED7FD: UnknownInlinedFun (obmalloc.c:1569)
==90231==    by 0x49ED7FD: UnknownInlinedFun (obmalloc.c:801)
==90231==    by 0x49ED7FD: UnknownInlinedFun (typeobject.c:1701)
==90231==    by 0x49ED7FD: PyType_GenericAlloc (typeobject.c:1725)
==90231==    by 0x4AC4D79: _PyType_FromMetaclass_impl (typeobject.c:4305)
==90231==    by 0x6496E2A: UnknownInlinedFun (_ctypes.c:5717)
==90231==    by 0x6496E2A: UnknownInlinedFun (_ctypes.c:5805)
==90231==    by 0x6496E2A: PyInit__ctypes (_ctypes.c:5824)
==90231==    by 0x4AFE037: UnknownInlinedFun (importdl.c:169)
==90231==    by 0x4AFE037: UnknownInlinedFun (import.c:3775)
==90231==    by 0x4AFE037: _imp_create_dynamic (import.c.h:506)
==90231==    by 0x4A2E3CA: cfunction_vectorcall_FASTCALL (methodobject.c:422)
==90231==    by 0x4A0B71A: UnknownInlinedFun (call.c:387)
==90231==    by 0x4A0B71A: _PyEval_EvalFrameDefault (bytecodes.c:3262)
==90231==    by 0x4A2C9FA: UnknownInlinedFun (pycore_call.h:92)
==90231==    by 0x4A2C9FA: object_vacall (call.c:850)
==90231==    by 0x4A5DF4A: PyObject_CallMethodObjArgs (call.c:911)
==90231==    by 0x4A5D020: UnknownInlinedFun (import.c:2779)
==90231==    by 0x4A5D020: PyImport_ImportModuleLevelObject (import.c:2862)
==90231==    by 0x4A0BF9F: UnknownInlinedFun (ceval.c:2482)
==90231==    by 0x4A0BF9F: _PyEval_EvalFrameDefault (bytecodes.c:2143)
==90231==    by 0x4ACA0F4: PyEval_EvalCode (ceval.c:578)
==90231== 
==90231== 976 bytes in 1 blocks are still reachable in loss record 24 of 72
==90231==    at 0x4842788: malloc (vg_replace_malloc.c:446)
==90231==    by 0x49ED7FD: UnknownInlinedFun (obmalloc.c:45)
==90231==    by 0x49ED7FD: UnknownInlinedFun (obmalloc.c:662)
==90231==    by 0x49ED7FD: UnknownInlinedFun (obmalloc.c:1569)
==90231==    by 0x49ED7FD: UnknownInlinedFun (obmalloc.c:801)
==90231==    by 0x49ED7FD: UnknownInlinedFun (typeobject.c:1701)
==90231==    by 0x49ED7FD: PyType_GenericAlloc (typeobject.c:1725)
==90231==    by 0x4AC79E3: UnknownInlinedFun (typeobject.c:3322)
==90231==    by 0x4AC79E3: UnknownInlinedFun (typeobject.c:3762)
==90231==    by 0x4AC79E3: UnknownInlinedFun (typeobject.c:3785)
==90231==    by 0x4AC79E3: type_new (typeobject.c:3929)
==90231==    by 0x6494078: PyCFuncPtrType_new (_ctypes.c:2553)
==90231==    by 0x49FD975: UnknownInlinedFun (typeobject.c:1664)
==90231==    by 0x49FD975: _PyObject_MakeTpCall (call.c:240)
==90231==    by 0x4ACB65B: builtin___build_class__ (bltinmodule.c:208)
==90231==    by 0x4A21CBD: cfunction_vectorcall_FASTCALL_KEYWORDS (methodobject.c:438)
==90231==    by 0x4A21B6C: UnknownInlinedFun (pycore_call.h:92)
==90231==    by 0x4A21B6C: PyObject_Vectorcall (call.c:325)
==90231==    by 0x4A0631E: _PyEval_EvalFrameDefault (bytecodes.c:2714)
==90231==    by 0x4A00845: UnknownInlinedFun (pycore_ceval.h:89)
==90231==    by 0x4A00845: UnknownInlinedFun (ceval.c:1683)
==90231==    by 0x4A00845: UnknownInlinedFun (call.c:419)
==90231==    by 0x4A00845: _PyObject_FastCallDictTstate (call.c:133)
==90231==    by 0x4A3CAF6: UnknownInlinedFun (call.c:508)
==90231==    by 0x4A3CAF6: slot_tp_init (typeobject.c:9020)
==90231==    by 0x49FDA67: UnknownInlinedFun (typeobject.c:1676)
==90231==    by 0x49FDA67: _PyObject_MakeTpCall (call.c:240)
==90231== 
==90231== 976 bytes in 1 blocks are still reachable in loss record 25 of 72
==90231==    at 0x4842788: malloc (vg_replace_malloc.c:446)
==90231==    by 0x49ED7FD: UnknownInlinedFun (obmalloc.c:45)
==90231==    by 0x49ED7FD: UnknownInlinedFun (obmalloc.c:662)
==90231==    by 0x49ED7FD: UnknownInlinedFun (obmalloc.c:1569)
==90231==    by 0x49ED7FD: UnknownInlinedFun (obmalloc.c:801)
==90231==    by 0x49ED7FD: UnknownInlinedFun (typeobject.c:1701)
==90231==    by 0x49ED7FD: PyType_GenericAlloc (typeobject.c:1725)
==90231==    by 0x4AC79E3: UnknownInlinedFun (typeobject.c:3322)
==90231==    by 0x4AC79E3: UnknownInlinedFun (typeobject.c:3762)
==90231==    by 0x4AC79E3: UnknownInlinedFun (typeobject.c:3785)
==90231==    by 0x4AC79E3: type_new (typeobject.c:3929)
==90231==    by 0x6494078: PyCFuncPtrType_new (_ctypes.c:2553)
==90231==    by 0x49FD975: UnknownInlinedFun (typeobject.c:1664)
==90231==    by 0x49FD975: _PyObject_MakeTpCall (call.c:240)
==90231==    by 0x4ACB65B: builtin___build_class__ (bltinmodule.c:208)
==90231==    by 0x4A097D8: _PyEval_EvalFrameDefault (bytecodes.c:2974)
==90231==    by 0x4ACA0F4: PyEval_EvalCode (ceval.c:578)
==90231==    by 0x4AE5705: UnknownInlinedFun (bltinmodule.c:1096)
==90231==    by 0x4AE5705: builtin_exec (bltinmodule.c.h:586)
==90231==    by 0x4A21CBD: cfunction_vectorcall_FASTCALL_KEYWORDS (methodobject.c:438)
==90231==    by 0x4A0B71A: UnknownInlinedFun (call.c:387)
==90231==    by 0x4A0B71A: _PyEval_EvalFrameDefault (bytecodes.c:3262)
==90231==    by 0x4A2C9FA: UnknownInlinedFun (pycore_call.h:92)
==90231==    by 0x4A2C9FA: object_vacall (call.c:850)
==90231== 
==90231== 976 bytes in 1 blocks are still reachable in loss record 26 of 72
==90231==    at 0x4842788: malloc (vg_replace_malloc.c:446)
==90231==    by 0x49ED7FD: UnknownInlinedFun (obmalloc.c:45)
==90231==    by 0x49ED7FD: UnknownInlinedFun (obmalloc.c:662)
==90231==    by 0x49ED7FD: UnknownInlinedFun (obmalloc.c:1569)
==90231==    by 0x49ED7FD: UnknownInlinedFun (obmalloc.c:801)
==90231==    by 0x49ED7FD: UnknownInlinedFun (typeobject.c:1701)
==90231==    by 0x49ED7FD: PyType_GenericAlloc (typeobject.c:1725)
==90231==    by 0x4AC84C4: UnknownInlinedFun (typeobject.c:3322)
==90231==    by 0x4AC84C4: UnknownInlinedFun (typeobject.c:3762)
==90231==    by 0x4AC84C4: UnknownInlinedFun (typeobject.c:3785)
==90231==    by 0x4AC84C4: type_new (typeobject.c:3929)
==90231==    by 0x49FD975: UnknownInlinedFun (typeobject.c:1664)
==90231==    by 0x49FD975: _PyObject_MakeTpCall (call.c:240)
==90231==    by 0x4A08EAF: _PyEval_EvalFrameDefault (bytecodes.c:2879)
==90231==    by 0x49F7B24: _PyObject_VectorcallTstate.lto_priv.1 (pycore_call.h:92)
==90231==    by 0x4AC6810: _PyObject_CallFunctionVa (call.c:556)
==90231==    by 0x4AD20B1: PyObject_CallMethod (call.c:653)
==90231==    by 0x7CF3FAB: PyInit__decimal (_decimal.c:5804)
==90231==    by 0x4AFE037: UnknownInlinedFun (importdl.c:169)
==90231==    by 0x4AFE037: UnknownInlinedFun (import.c:3775)
==90231==    by 0x4AFE037: _imp_create_dynamic (import.c.h:506)
==90231==    by 0x4A2E3CA: cfunction_vectorcall_FASTCALL (methodobject.c:422)
==90231==    by 0x4A0B71A: UnknownInlinedFun (call.c:387)
==90231==    by 0x4A0B71A: _PyEval_EvalFrameDefault (bytecodes.c:3262)
==90231== 
==90231== 976 bytes in 1 blocks are still reachable in loss record 27 of 72
==90231==    at 0x4842788: malloc (vg_replace_malloc.c:446)
==90231==    by 0x49ED7FD: UnknownInlinedFun (obmalloc.c:45)
==90231==    by 0x49ED7FD: UnknownInlinedFun (obmalloc.c:662)
==90231==    by 0x49ED7FD: UnknownInlinedFun (obmalloc.c:1569)
==90231==    by 0x49ED7FD: UnknownInlinedFun (obmalloc.c:801)
==90231==    by 0x49ED7FD: UnknownInlinedFun (typeobject.c:1701)
==90231==    by 0x49ED7FD: PyType_GenericAlloc (typeobject.c:1725)
==90231==    by 0x4AC79E3: UnknownInlinedFun (typeobject.c:3322)
==90231==    by 0x4AC79E3: UnknownInlinedFun (typeobject.c:3762)
==90231==    by 0x4AC79E3: UnknownInlinedFun (typeobject.c:3785)
==90231==    by 0x4AC79E3: type_new (typeobject.c:3929)
==90231==    by 0x4A5F465: tp_new_wrapper (typeobject.c:8312)
==90231==    by 0x4A2DA86: cfunction_call (methodobject.c:537)
==90231==    by 0x4A3FA59: _PyObject_Call (call.c:367)
==90231==    by 0x4A0B71A: UnknownInlinedFun (call.c:387)
==90231==    by 0x4A0B71A: _PyEval_EvalFrameDefault (bytecodes.c:3262)
==90231==    by 0x4A00845: UnknownInlinedFun (pycore_ceval.h:89)
==90231==    by 0x4A00845: UnknownInlinedFun (ceval.c:1683)
==90231==    by 0x4A00845: UnknownInlinedFun (call.c:419)
==90231==    by 0x4A00845: _PyObject_FastCallDictTstate (call.c:133)
==90231==    by 0x4A5F116: UnknownInlinedFun (call.c:508)
==90231==    by 0x4A5F116: slot_tp_new (typeobject.c:9050)
==90231==    by 0x4AC891D: UnknownInlinedFun (typeobject.c:3864)
==90231==    by 0x4AC891D: type_new (typeobject.c:3917)
==90231==    by 0x49FD975: UnknownInlinedFun (typeobject.c:1664)
==90231==    by 0x49FD975: _PyObject_MakeTpCall (call.c:240)
==90231==    by 0x49F75D9: UnknownInlinedFun (pycore_call.h:92)
==90231==    by 0x49F75D9: UnknownInlinedFun (call.c:562)
==90231==    by 0x49F75D9: PyObject_CallFunction (call.c:584)
==90231== 
==90231== 976 bytes in 1 blocks are still reachable in loss record 28 of 72
==90231==    at 0x4842788: malloc (vg_replace_malloc.c:446)
==90231==    by 0x49ED7FD: UnknownInlinedFun (obmalloc.c:45)
==90231==    by 0x49ED7FD: UnknownInlinedFun (obmalloc.c:662)
==90231==    by 0x49ED7FD: UnknownInlinedFun (obmalloc.c:1569)
==90231==    by 0x49ED7FD: UnknownInlinedFun (obmalloc.c:801)
==90231==    by 0x49ED7FD: UnknownInlinedFun (typeobject.c:1701)
==90231==    by 0x49ED7FD: PyType_GenericAlloc (typeobject.c:1725)
==90231==    by 0x4AC79E3: UnknownInlinedFun (typeobject.c:3322)
==90231==    by 0x4AC79E3: UnknownInlinedFun (typeobject.c:3762)
==90231==    by 0x4AC79E3: UnknownInlinedFun (typeobject.c:3785)
==90231==    by 0x4AC79E3: type_new (typeobject.c:3929)
==90231==    by 0x49FD975: UnknownInlinedFun (typeobject.c:1664)
==90231==    by 0x49FD975: _PyObject_MakeTpCall (call.c:240)
==90231==    by 0x49F75D9: UnknownInlinedFun (pycore_call.h:92)
==90231==    by 0x49F75D9: UnknownInlinedFun (call.c:562)
==90231==    by 0x49F75D9: PyObject_CallFunction (call.c:584)
==90231==    by 0x4AC77D4: PyErr_NewException (errors.c:1303)
==90231==    by 0x7CF4151: PyInit__decimal (_decimal.c:5841)
==90231==    by 0x4AFE037: UnknownInlinedFun (importdl.c:169)
==90231==    by 0x4AFE037: UnknownInlinedFun (import.c:3775)
==90231==    by 0x4AFE037: _imp_create_dynamic (import.c.h:506)
==90231==    by 0x4A2E3CA: cfunction_vectorcall_FASTCALL (methodobject.c:422)
==90231==    by 0x4A0B71A: UnknownInlinedFun (call.c:387)
==90231==    by 0x4A0B71A: _PyEval_EvalFrameDefault (bytecodes.c:3262)
==90231==    by 0x4A2C9FA: UnknownInlinedFun (pycore_call.h:92)
==90231==    by 0x4A2C9FA: object_vacall (call.c:850)
==90231==    by 0x4A5DF4A: PyObject_CallMethodObjArgs (call.c:911)
==90231== 
==90231== 1,016 bytes in 1 blocks are still reachable in loss record 29 of 72
==90231==    at 0x4842788: malloc (vg_replace_malloc.c:446)
==90231==    by 0x49ED7FD: UnknownInlinedFun (obmalloc.c:45)
==90231==    by 0x49ED7FD: UnknownInlinedFun (obmalloc.c:662)
==90231==    by 0x49ED7FD: UnknownInlinedFun (obmalloc.c:1569)
==90231==    by 0x49ED7FD: UnknownInlinedFun (obmalloc.c:801)
==90231==    by 0x49ED7FD: UnknownInlinedFun (typeobject.c:1701)
==90231==    by 0x49ED7FD: PyType_GenericAlloc (typeobject.c:1725)
==90231==    by 0x4AC4D79: _PyType_FromMetaclass_impl (typeobject.c:4305)
==90231==    by 0x4AFC594: collections_exec (_collectionsmodule.c:2558)
==90231==    by 0x4AD1A71: PyModule_ExecDef (moduleobject.c:440)
==90231==    by 0x4AD6353: UnknownInlinedFun (import.c:3818)
==90231==    by 0x4AD6353: _imp_exec_builtin (import.c.h:564)
==90231==    by 0x4A2AF6B: cfunction_vectorcall_O (methodobject.c:509)
==90231==    by 0x4A0B71A: UnknownInlinedFun (call.c:387)
==90231==    by 0x4A0B71A: _PyEval_EvalFrameDefault (bytecodes.c:3262)
==90231==    by 0x4A2C9FA: UnknownInlinedFun (pycore_call.h:92)
==90231==    by 0x4A2C9FA: object_vacall (call.c:850)
==90231==    by 0x4A5DF4A: PyObject_CallMethodObjArgs (call.c:911)
==90231==    by 0x4A5D020: UnknownInlinedFun (import.c:2779)
==90231==    by 0x4A5D020: PyImport_ImportModuleLevelObject (import.c:2862)
==90231==    by 0x4A0BF9F: UnknownInlinedFun (ceval.c:2482)
==90231==    by 0x4A0BF9F: _PyEval_EvalFrameDefault (bytecodes.c:2143)
==90231== 
==90231== 1,016 bytes in 1 blocks are still reachable in loss record 30 of 72
==90231==    at 0x4842788: malloc (vg_replace_malloc.c:446)
==90231==    by 0x49ED7FD: UnknownInlinedFun (obmalloc.c:45)
==90231==    by 0x49ED7FD: UnknownInlinedFun (obmalloc.c:662)
==90231==    by 0x49ED7FD: UnknownInlinedFun (obmalloc.c:1569)
==90231==    by 0x49ED7FD: UnknownInlinedFun (obmalloc.c:801)
==90231==    by 0x49ED7FD: UnknownInlinedFun (typeobject.c:1701)
==90231==    by 0x49ED7FD: PyType_GenericAlloc (typeobject.c:1725)
==90231==    by 0x4AC4D79: _PyType_FromMetaclass_impl (typeobject.c:4305)
==90231==    by 0x4AFC5CD: collections_exec (_collectionsmodule.c:2559)
==90231==    by 0x4AD1A71: PyModule_ExecDef (moduleobject.c:440)
==90231==    by 0x4AD6353: UnknownInlinedFun (import.c:3818)
==90231==    by 0x4AD6353: _imp_exec_builtin (import.c.h:564)
==90231==    by 0x4A2AF6B: cfunction_vectorcall_O (methodobject.c:509)
==90231==    by 0x4A0B71A: UnknownInlinedFun (call.c:387)
==90231==    by 0x4A0B71A: _PyEval_EvalFrameDefault (bytecodes.c:3262)
==90231==    by 0x4A2C9FA: UnknownInlinedFun (pycore_call.h:92)
==90231==    by 0x4A2C9FA: object_vacall (call.c:850)
==90231==    by 0x4A5DF4A: PyObject_CallMethodObjArgs (call.c:911)
==90231==    by 0x4A5D020: UnknownInlinedFun (import.c:2779)
==90231==    by 0x4A5D020: PyImport_ImportModuleLevelObject (import.c:2862)
==90231==    by 0x4A0BF9F: UnknownInlinedFun (ceval.c:2482)
==90231==    by 0x4A0BF9F: _PyEval_EvalFrameDefault (bytecodes.c:2143)
==90231== 
==90231== 1,016 bytes in 1 blocks are still reachable in loss record 31 of 72
==90231==    at 0x4842788: malloc (vg_replace_malloc.c:446)
==90231==    by 0x49ED7FD: UnknownInlinedFun (obmalloc.c:45)
==90231==    by 0x49ED7FD: UnknownInlinedFun (obmalloc.c:662)
==90231==    by 0x49ED7FD: UnknownInlinedFun (obmalloc.c:1569)
==90231==    by 0x49ED7FD: UnknownInlinedFun (obmalloc.c:801)
==90231==    by 0x49ED7FD: UnknownInlinedFun (typeobject.c:1701)
==90231==    by 0x49ED7FD: PyType_GenericAlloc (typeobject.c:1725)
==90231==    by 0x4AC4D79: _PyType_FromMetaclass_impl (typeobject.c:4305)
==90231==    by 0x4AFC66C: collections_exec (_collectionsmodule.c:2562)
==90231==    by 0x4AD1A71: PyModule_ExecDef (moduleobject.c:440)
==90231==    by 0x4AD6353: UnknownInlinedFun (import.c:3818)
==90231==    by 0x4AD6353: _imp_exec_builtin (import.c.h:564)
==90231==    by 0x4A2AF6B: cfunction_vectorcall_O (methodobject.c:509)
==90231==    by 0x4A0B71A: UnknownInlinedFun (call.c:387)
==90231==    by 0x4A0B71A: _PyEval_EvalFrameDefault (bytecodes.c:3262)
==90231==    by 0x4A2C9FA: UnknownInlinedFun (pycore_call.h:92)
==90231==    by 0x4A2C9FA: object_vacall (call.c:850)
==90231==    by 0x4A5DF4A: PyObject_CallMethodObjArgs (call.c:911)
==90231==    by 0x4A5D020: UnknownInlinedFun (import.c:2779)
==90231==    by 0x4A5D020: PyImport_ImportModuleLevelObject (import.c:2862)
==90231==    by 0x4A0BF9F: UnknownInlinedFun (ceval.c:2482)
==90231==    by 0x4A0BF9F: _PyEval_EvalFrameDefault (bytecodes.c:2143)
==90231== 
==90231== 1,016 bytes in 1 blocks are still reachable in loss record 32 of 72
==90231==    at 0x4842788: malloc (vg_replace_malloc.c:446)
==90231==    by 0x49ED7FD: UnknownInlinedFun (obmalloc.c:45)
==90231==    by 0x49ED7FD: UnknownInlinedFun (obmalloc.c:662)
==90231==    by 0x49ED7FD: UnknownInlinedFun (obmalloc.c:1569)
==90231==    by 0x49ED7FD: UnknownInlinedFun (obmalloc.c:801)
==90231==    by 0x49ED7FD: UnknownInlinedFun (typeobject.c:1701)
==90231==    by 0x49ED7FD: PyType_GenericAlloc (typeobject.c:1725)
==90231==    by 0x4AC4D79: _PyType_FromMetaclass_impl (typeobject.c:4305)
==90231==    by 0x6496BAA: UnknownInlinedFun (_ctypes.c:5675)
==90231==    by 0x6496BAA: UnknownInlinedFun (_ctypes.c:5805)
==90231==    by 0x6496BAA: PyInit__ctypes (_ctypes.c:5824)
==90231==    by 0x4AFE037: UnknownInlinedFun (importdl.c:169)
==90231==    by 0x4AFE037: UnknownInlinedFun (import.c:3775)
==90231==    by 0x4AFE037: _imp_create_dynamic (import.c.h:506)
==90231==    by 0x4A2E3CA: cfunction_vectorcall_FASTCALL (methodobject.c:422)
==90231==    by 0x4A0B71A: UnknownInlinedFun (call.c:387)
==90231==    by 0x4A0B71A: _PyEval_EvalFrameDefault (bytecodes.c:3262)
==90231==    by 0x4A2C9FA: UnknownInlinedFun (pycore_call.h:92)
==90231==    by 0x4A2C9FA: object_vacall (call.c:850)
==90231==    by 0x4A5DF4A: PyObject_CallMethodObjArgs (call.c:911)
==90231==    by 0x4A5D020: UnknownInlinedFun (import.c:2779)
==90231==    by 0x4A5D020: PyImport_ImportModuleLevelObject (import.c:2862)
==90231==    by 0x4A0BF9F: UnknownInlinedFun (ceval.c:2482)
==90231==    by 0x4A0BF9F: _PyEval_EvalFrameDefault (bytecodes.c:2143)
==90231==    by 0x4ACA0F4: PyEval_EvalCode (ceval.c:578)
==90231== 
==90231== 1,096 bytes in 1 blocks are still reachable in loss record 33 of 72
==90231==    at 0x4842788: malloc (vg_replace_malloc.c:446)
==90231==    by 0x49ED7FD: UnknownInlinedFun (obmalloc.c:45)
==90231==    by 0x49ED7FD: UnknownInlinedFun (obmalloc.c:662)
==90231==    by 0x49ED7FD: UnknownInlinedFun (obmalloc.c:1569)
==90231==    by 0x49ED7FD: UnknownInlinedFun (obmalloc.c:801)
==90231==    by 0x49ED7FD: UnknownInlinedFun (typeobject.c:1701)
==90231==    by 0x49ED7FD: PyType_GenericAlloc (typeobject.c:1725)
==90231==    by 0x4AC84C4: UnknownInlinedFun (typeobject.c:3322)
==90231==    by 0x4AC84C4: UnknownInlinedFun (typeobject.c:3762)
==90231==    by 0x4AC84C4: UnknownInlinedFun (typeobject.c:3785)
==90231==    by 0x4AC84C4: type_new (typeobject.c:3929)
==90231==    by 0x49FD975: UnknownInlinedFun (typeobject.c:1664)
==90231==    by 0x49FD975: _PyObject_MakeTpCall (call.c:240)
==90231==    by 0x4A008E0: _PyObject_FastCallDictTstate (call.c:144)
==90231==    by 0x4ACB65B: builtin___build_class__ (bltinmodule.c:208)
==90231==    by 0x4A21CBD: cfunction_vectorcall_FASTCALL_KEYWORDS (methodobject.c:438)
==90231==    by 0x4A21B6C: UnknownInlinedFun (pycore_call.h:92)
==90231==    by 0x4A21B6C: PyObject_Vectorcall (call.c:325)
==90231==    by 0x4A0631E: _PyEval_EvalFrameDefault (bytecodes.c:2714)
==90231==    by 0x4ACA0F4: PyEval_EvalCode (ceval.c:578)
==90231==    by 0x4AE5705: UnknownInlinedFun (bltinmodule.c:1096)
==90231==    by 0x4AE5705: builtin_exec (bltinmodule.c.h:586)
==90231==    by 0x4A21CBD: cfunction_vectorcall_FASTCALL_KEYWORDS (methodobject.c:438)
==90231== 
==90231== 1,104 bytes in 1 blocks are still reachable in loss record 34 of 72
==90231==    at 0x4842788: malloc (vg_replace_malloc.c:446)
==90231==    by 0x49F0714: UnknownInlinedFun (obmalloc.c:45)
==90231==    by 0x49F0714: UnknownInlinedFun (obmalloc.c:662)
==90231==    by 0x49F0714: UnknownInlinedFun (obmalloc.c:1569)
==90231==    by 0x49F0714: UnknownInlinedFun (obmalloc.c:801)
==90231==    by 0x49F0714: UnknownInlinedFun (dictobject.c:641)
==90231==    by 0x49F0714: dictresize (dictobject.c:1449)
==90231==    by 0x49EFD72: UnknownInlinedFun (dictobject.c:1194)
==90231==    by 0x49EFD72: insertdict (dictobject.c:1261)
==90231==    by 0x4AC4949: add_subclass (typeobject.c:7618)
==90231==    by 0x49E7029: UnknownInlinedFun (typeobject.c:7352)
==90231==    by 0x49E7029: type_ready (typeobject.c:7515)
==90231==    by 0x4AC7DB8: UnknownInlinedFun (typeobject.c:3795)
==90231==    by 0x4AC7DB8: type_new (typeobject.c:3929)
==90231==    by 0x64937DA: PyCSimpleType_new (_ctypes.c:2045)
==90231==    by 0x49FD975: UnknownInlinedFun (typeobject.c:1664)
==90231==    by 0x49FD975: _PyObject_MakeTpCall (call.c:240)
==90231==    by 0x4ACB65B: builtin___build_class__ (bltinmodule.c:208)
==90231==    by 0x4A21CBD: cfunction_vectorcall_FASTCALL_KEYWORDS (methodobject.c:438)
==90231==    by 0x4A21B6C: UnknownInlinedFun (pycore_call.h:92)
==90231==    by 0x4A21B6C: PyObject_Vectorcall (call.c:325)
==90231==    by 0x4A0631E: _PyEval_EvalFrameDefault (bytecodes.c:2714)
==90231== 
==90231== 1,489 bytes in 1 blocks are still reachable in loss record 35 of 72
==90231==    at 0x4842788: malloc (vg_replace_malloc.c:446)
==90231==    by 0x49E42F6: UnknownInlinedFun (obmalloc.c:45)
==90231==    by 0x49E42F6: UnknownInlinedFun (obmalloc.c:662)
==90231==    by 0x49E42F6: UnknownInlinedFun (obmalloc.c:1569)
==90231==    by 0x49E42F6: PyObject_Malloc (obmalloc.c:801)
==90231==    by 0x4AC823C: UnknownInlinedFun (typeobject.c:3467)
==90231==    by 0x4AC823C: UnknownInlinedFun (typeobject.c:3679)
==90231==    by 0x4AC823C: UnknownInlinedFun (typeobject.c:3790)
==90231==    by 0x4AC823C: type_new (typeobject.c:3929)
==90231==    by 0x49FD975: UnknownInlinedFun (typeobject.c:1664)
==90231==    by 0x49FD975: _PyObject_MakeTpCall (call.c:240)
==90231==    by 0x4A0093B: _PyObject_FastCallDictTstate (call.c:133)
==90231==    by 0x4ACB65B: builtin___build_class__ (bltinmodule.c:208)
==90231==    by 0x4A21CBD: cfunction_vectorcall_FASTCALL_KEYWORDS (methodobject.c:438)
==90231==    by 0x4A21B6C: UnknownInlinedFun (pycore_call.h:92)
==90231==    by 0x4A21B6C: PyObject_Vectorcall (call.c:325)
==90231==    by 0x4A0631E: _PyEval_EvalFrameDefault (bytecodes.c:2714)
==90231==    by 0x4ACA0F4: PyEval_EvalCode (ceval.c:578)
==90231==    by 0x4AC9F97: exec_code_in_module (import.c:1712)
==90231==    by 0x4AC90D5: PyImport_ImportFrozenModuleObject (import.c:2154)
==90231== 
==90231== 1,520 bytes in 1 blocks are still reachable in loss record 36 of 72
==90231==    at 0x4842788: malloc (vg_replace_malloc.c:446)
==90231==    by 0x49F0714: UnknownInlinedFun (obmalloc.c:45)
==90231==    by 0x49F0714: UnknownInlinedFun (obmalloc.c:662)
==90231==    by 0x49F0714: UnknownInlinedFun (obmalloc.c:1569)
==90231==    by 0x49F0714: UnknownInlinedFun (obmalloc.c:801)
==90231==    by 0x49F0714: UnknownInlinedFun (dictobject.c:641)
==90231==    by 0x49F0714: dictresize (dictobject.c:1449)
==90231==    by 0x49EFD72: UnknownInlinedFun (dictobject.c:1194)
==90231==    by 0x49EFD72: insertdict (dictobject.c:1261)
==90231==    by 0x4A0ABD4: _PyEval_EvalFrameDefault (bytecodes.c:1023)
==90231==    by 0x4ACA0F4: PyEval_EvalCode (ceval.c:578)
==90231==    by 0x4AC9F97: exec_code_in_module (import.c:1712)
==90231==    by 0x4AC90D5: PyImport_ImportFrozenModuleObject (import.c:2154)
==90231==    by 0x4AC9015: PyImport_ImportFrozenModule (import.c:2193)
==90231==    by 0x4ABEC7C: UnknownInlinedFun (import.c:2273)
==90231==    by 0x4ABEC7C: UnknownInlinedFun (import.c:3145)
==90231==    by 0x4ABEC7C: pycore_interp_init (pylifecycle.c:868)
==90231==    by 0x4AB76ED: UnknownInlinedFun (pylifecycle.c:897)
==90231==    by 0x4AB76ED: pyinit_core.constprop.0 (pylifecycle.c:1060)
==90231==    by 0x4AB6EF2: Py_InitializeFromConfig (pylifecycle.c:1282)
==90231==    by 0x4AB6C10: pymain_init (main.c:67)
==90231== 
==90231== 1,520 bytes in 1 blocks are still reachable in loss record 37 of 72
==90231==    at 0x4842788: malloc (vg_replace_malloc.c:446)
==90231==    by 0x49F0714: UnknownInlinedFun (obmalloc.c:45)
==90231==    by 0x49F0714: UnknownInlinedFun (obmalloc.c:662)
==90231==    by 0x49F0714: UnknownInlinedFun (obmalloc.c:1569)
==90231==    by 0x49F0714: UnknownInlinedFun (obmalloc.c:801)
==90231==    by 0x49F0714: UnknownInlinedFun (dictobject.c:641)
==90231==    by 0x49F0714: dictresize (dictobject.c:1449)
==90231==    by 0x49EFD72: UnknownInlinedFun (dictobject.c:1194)
==90231==    by 0x49EFD72: insertdict (dictobject.c:1261)
==90231==    by 0x4A0ABD4: _PyEval_EvalFrameDefault (bytecodes.c:1023)
==90231==    by 0x4ACA0F4: PyEval_EvalCode (ceval.c:578)
==90231==    by 0x4AE5705: UnknownInlinedFun (bltinmodule.c:1096)
==90231==    by 0x4AE5705: builtin_exec (bltinmodule.c.h:586)
==90231==    by 0x4A21CBD: cfunction_vectorcall_FASTCALL_KEYWORDS (methodobject.c:438)
==90231==    by 0x4A21B6C: UnknownInlinedFun (pycore_call.h:92)
==90231==    by 0x4A21B6C: PyObject_Vectorcall (call.c:325)
==90231==    by 0x4A0631E: _PyEval_EvalFrameDefault (bytecodes.c:2714)
==90231==    by 0x4A2C9FA: UnknownInlinedFun (pycore_call.h:92)
==90231==    by 0x4A2C9FA: object_vacall (call.c:850)
==90231==    by 0x4A5DF4A: PyObject_CallMethodObjArgs (call.c:911)
==90231==    by 0x4A5D020: UnknownInlinedFun (import.c:2779)
==90231==    by 0x4A5D020: PyImport_ImportModuleLevelObject (import.c:2862)
==90231== 
==90231== 1,520 bytes in 1 blocks are still reachable in loss record 38 of 72
==90231==    at 0x4842788: malloc (vg_replace_malloc.c:446)
==90231==    by 0x49F0714: UnknownInlinedFun (obmalloc.c:45)
==90231==    by 0x49F0714: UnknownInlinedFun (obmalloc.c:662)
==90231==    by 0x49F0714: UnknownInlinedFun (obmalloc.c:1569)
==90231==    by 0x49F0714: UnknownInlinedFun (obmalloc.c:801)
==90231==    by 0x49F0714: UnknownInlinedFun (dictobject.c:641)
==90231==    by 0x49F0714: dictresize (dictobject.c:1449)
==90231==    by 0x49F0ECE: PyDict_SetDefault (dictobject.c:3332)
==90231==    by 0x49E7956: UnknownInlinedFun (typeobject.c:6701)
==90231==    by 0x49E7956: UnknownInlinedFun (typeobject.c:7161)
==90231==    by 0x49E7956: type_ready (typeobject.c:7501)
==90231==    by 0x4AC4F46: _PyType_FromMetaclass_impl (typeobject.c:4411)
==90231==    by 0x4AFC594: collections_exec (_collectionsmodule.c:2558)
==90231==    by 0x4AD1A71: PyModule_ExecDef (moduleobject.c:440)
==90231==    by 0x4AD6353: UnknownInlinedFun (import.c:3818)
==90231==    by 0x4AD6353: _imp_exec_builtin (import.c.h:564)
==90231==    by 0x4A2AF6B: cfunction_vectorcall_O (methodobject.c:509)
==90231==    by 0x4A0B71A: UnknownInlinedFun (call.c:387)
==90231==    by 0x4A0B71A: _PyEval_EvalFrameDefault (bytecodes.c:3262)
==90231==    by 0x4A2C9FA: UnknownInlinedFun (pycore_call.h:92)
==90231==    by 0x4A2C9FA: object_vacall (call.c:850)
==90231==    by 0x4A5DF4A: PyObject_CallMethodObjArgs (call.c:911)
==90231== 
==90231== 1,520 bytes in 1 blocks are still reachable in loss record 39 of 72
==90231==    at 0x4842788: malloc (vg_replace_malloc.c:446)
==90231==    by 0x49F0714: UnknownInlinedFun (obmalloc.c:45)
==90231==    by 0x49F0714: UnknownInlinedFun (obmalloc.c:662)
==90231==    by 0x49F0714: UnknownInlinedFun (obmalloc.c:1569)
==90231==    by 0x49F0714: UnknownInlinedFun (obmalloc.c:801)
==90231==    by 0x49F0714: UnknownInlinedFun (dictobject.c:641)
==90231==    by 0x49F0714: dictresize (dictobject.c:1449)
==90231==    by 0x49EFD72: UnknownInlinedFun (dictobject.c:1194)
==90231==    by 0x49EFD72: insertdict (dictobject.c:1261)
==90231==    by 0x49F290C: UnknownInlinedFun (dictobject.c:1865)
==90231==    by 0x49F290C: UnknownInlinedFun (dictobject.c:1883)
==90231==    by 0x49F290C: PyDict_SetItemString (dictobject.c:3919)
==90231==    by 0x64971B0: UnknownInlinedFun (_ctypes.c:5778)
==90231==    by 0x64971B0: UnknownInlinedFun (_ctypes.c:5809)
==90231==    by 0x64971B0: PyInit__ctypes (_ctypes.c:5824)
==90231==    by 0x4AFE037: UnknownInlinedFun (importdl.c:169)
==90231==    by 0x4AFE037: UnknownInlinedFun (import.c:3775)
==90231==    by 0x4AFE037: _imp_create_dynamic (import.c.h:506)
==90231==    by 0x4A2E3CA: cfunction_vectorcall_FASTCALL (methodobject.c:422)
==90231==    by 0x4A0B71A: UnknownInlinedFun (call.c:387)
==90231==    by 0x4A0B71A: _PyEval_EvalFrameDefault (bytecodes.c:3262)
==90231==    by 0x4A2C9FA: UnknownInlinedFun (pycore_call.h:92)
==90231==    by 0x4A2C9FA: object_vacall (call.c:850)
==90231==    by 0x4A5DF4A: PyObject_CallMethodObjArgs (call.c:911)
==90231==    by 0x4A5D020: UnknownInlinedFun (import.c:2779)
==90231==    by 0x4A5D020: PyImport_ImportModuleLevelObject (import.c:2862)
==90231==    by 0x4A0BF9F: UnknownInlinedFun (ceval.c:2482)
==90231==    by 0x4A0BF9F: _PyEval_EvalFrameDefault (bytecodes.c:2143)
==90231== 
==90231== 1,520 bytes in 1 blocks are still reachable in loss record 40 of 72
==90231==    at 0x4842788: malloc (vg_replace_malloc.c:446)
==90231==    by 0x49F0714: UnknownInlinedFun (obmalloc.c:45)
==90231==    by 0x49F0714: UnknownInlinedFun (obmalloc.c:662)
==90231==    by 0x49F0714: UnknownInlinedFun (obmalloc.c:1569)
==90231==    by 0x49F0714: UnknownInlinedFun (obmalloc.c:801)
==90231==    by 0x49F0714: UnknownInlinedFun (dictobject.c:641)
==90231==    by 0x49F0714: dictresize (dictobject.c:1449)
==90231==    by 0x49F0ECE: PyDict_SetDefault (dictobject.c:3332)
==90231==    by 0x49E7CAC: UnknownInlinedFun (typeobject.c:6628)
==90231==    by 0x49E7CAC: UnknownInlinedFun (typeobject.c:6654)
==90231==    by 0x49E7CAC: UnknownInlinedFun (typeobject.c:7155)
==90231==    by 0x49E7CAC: type_ready (typeobject.c:7501)
==90231==    by 0x7CF3E17: PyInit__decimal (_decimal.c:5778)
==90231==    by 0x4AFE037: UnknownInlinedFun (importdl.c:169)
==90231==    by 0x4AFE037: UnknownInlinedFun (import.c:3775)
==90231==    by 0x4AFE037: _imp_create_dynamic (import.c.h:506)
==90231==    by 0x4A2E3CA: cfunction_vectorcall_FASTCALL (methodobject.c:422)
==90231==    by 0x4A0B71A: UnknownInlinedFun (call.c:387)
==90231==    by 0x4A0B71A: _PyEval_EvalFrameDefault (bytecodes.c:3262)
==90231==    by 0x4A2C9FA: UnknownInlinedFun (pycore_call.h:92)
==90231==    by 0x4A2C9FA: object_vacall (call.c:850)
==90231==    by 0x4A5DF4A: PyObject_CallMethodObjArgs (call.c:911)
==90231==    by 0x4A5D020: UnknownInlinedFun (import.c:2779)
==90231==    by 0x4A5D020: PyImport_ImportModuleLevelObject (import.c:2862)
==90231==    by 0x4A0BF9F: UnknownInlinedFun (ceval.c:2482)
==90231==    by 0x4A0BF9F: _PyEval_EvalFrameDefault (bytecodes.c:2143)
==90231== 
==90231== 1,536 bytes in 2 blocks are still reachable in loss record 41 of 72
==90231==    at 0x4842788: malloc (vg_replace_malloc.c:446)
==90231==    by 0x49E42F6: UnknownInlinedFun (obmalloc.c:45)
==90231==    by 0x49E42F6: UnknownInlinedFun (obmalloc.c:662)
==90231==    by 0x49E42F6: UnknownInlinedFun (obmalloc.c:1569)
==90231==    by 0x49E42F6: PyObject_Malloc (obmalloc.c:801)
==90231==    by 0x4AC4555: new_keys_object (dictobject.c:641)
==90231==    by 0x49E7B62: UnknownInlinedFun (dictobject.c:5321)
==90231==    by 0x49E7B62: UnknownInlinedFun (typeobject.c:7420)
==90231==    by 0x49E7B62: type_ready (typeobject.c:7519)
==90231==    by 0x4AC7DB8: UnknownInlinedFun (typeobject.c:3795)
==90231==    by 0x4AC7DB8: type_new (typeobject.c:3929)
==90231==    by 0x6493AE1: UnknownInlinedFun (_ctypes.c:1973)
==90231==    by 0x6493AE1: PyCSimpleType_new (_ctypes.c:2179)
==90231==    by 0x49FD975: UnknownInlinedFun (typeobject.c:1664)
==90231==    by 0x49FD975: _PyObject_MakeTpCall (call.c:240)
==90231==    by 0x4ACB65B: builtin___build_class__ (bltinmodule.c:208)
==90231==    by 0x4A21CBD: cfunction_vectorcall_FASTCALL_KEYWORDS (methodobject.c:438)
==90231==    by 0x4A21B6C: UnknownInlinedFun (pycore_call.h:92)
==90231==    by 0x4A21B6C: PyObject_Vectorcall (call.c:325)
==90231==    by 0x4A0631E: _PyEval_EvalFrameDefault (bytecodes.c:2714)
==90231==    by 0x4ACA0F4: PyEval_EvalCode (ceval.c:578)
==90231== 
==90231== 1,536 bytes in 2 blocks are still reachable in loss record 42 of 72
==90231==    at 0x4842788: malloc (vg_replace_malloc.c:446)
==90231==    by 0x49E42F6: UnknownInlinedFun (obmalloc.c:45)
==90231==    by 0x49E42F6: UnknownInlinedFun (obmalloc.c:662)
==90231==    by 0x49E42F6: UnknownInlinedFun (obmalloc.c:1569)
==90231==    by 0x49E42F6: PyObject_Malloc (obmalloc.c:801)
==90231==    by 0x4AC4555: new_keys_object (dictobject.c:641)
==90231==    by 0x49E7B62: UnknownInlinedFun (dictobject.c:5321)
==90231==    by 0x49E7B62: UnknownInlinedFun (typeobject.c:7420)
==90231==    by 0x49E7B62: type_ready (typeobject.c:7519)
==90231==    by 0x4AC7DB8: UnknownInlinedFun (typeobject.c:3795)
==90231==    by 0x4AC7DB8: type_new (typeobject.c:3929)
==90231==    by 0x649751A: StructUnionType_new (_ctypes.c:520)
==90231==    by 0x49FD975: UnknownInlinedFun (typeobject.c:1664)
==90231==    by 0x49FD975: _PyObject_MakeTpCall (call.c:240)
==90231==    by 0x4ACB65B: builtin___build_class__ (bltinmodule.c:208)
==90231==    by 0x4A21CBD: cfunction_vectorcall_FASTCALL_KEYWORDS (methodobject.c:438)
==90231==    by 0x4A21B6C: UnknownInlinedFun (pycore_call.h:92)
==90231==    by 0x4A21B6C: PyObject_Vectorcall (call.c:325)
==90231==    by 0x4A0631E: _PyEval_EvalFrameDefault (bytecodes.c:2714)
==90231==    by 0x4ACA0F4: PyEval_EvalCode (ceval.c:578)
==90231== 
==90231== 1,608 bytes in 1 blocks are still reachable in loss record 43 of 72
==90231==    at 0x4842788: malloc (vg_replace_malloc.c:446)
==90231==    by 0x49ED7FD: UnknownInlinedFun (obmalloc.c:45)
==90231==    by 0x49ED7FD: UnknownInlinedFun (obmalloc.c:662)
==90231==    by 0x49ED7FD: UnknownInlinedFun (obmalloc.c:1569)
==90231==    by 0x49ED7FD: UnknownInlinedFun (obmalloc.c:801)
==90231==    by 0x49ED7FD: UnknownInlinedFun (typeobject.c:1701)
==90231==    by 0x49ED7FD: PyType_GenericAlloc (typeobject.c:1725)
==90231==    by 0x486602F: UnknownInlinedFun (awaitable.c:23)
==90231==    by 0x486602F: alloc_awaitable_pool (awaitable.c:203)
==90231==    by 0x48669C7: PyInit__pyawaitable (mod.c:82)
==90231==    by 0x4AFE037: UnknownInlinedFun (importdl.c:169)
==90231==    by 0x4AFE037: UnknownInlinedFun (import.c:3775)
==90231==    by 0x4AFE037: _imp_create_dynamic (import.c.h:506)
==90231==    by 0x4A2E3CA: cfunction_vectorcall_FASTCALL (methodobject.c:422)
==90231==    by 0x4A0B71A: UnknownInlinedFun (call.c:387)
==90231==    by 0x4A0B71A: _PyEval_EvalFrameDefault (bytecodes.c:3262)
==90231==    by 0x4A2C9FA: UnknownInlinedFun (pycore_call.h:92)
==90231==    by 0x4A2C9FA: object_vacall (call.c:850)
==90231==    by 0x4A5DF4A: PyObject_CallMethodObjArgs (call.c:911)
==90231==    by 0x4A5D020: UnknownInlinedFun (import.c:2779)
==90231==    by 0x4A5D020: PyImport_ImportModuleLevelObject (import.c:2862)
==90231==    by 0x4A0BF9F: UnknownInlinedFun (ceval.c:2482)
==90231==    by 0x4A0BF9F: _PyEval_EvalFrameDefault (bytecodes.c:2143)
==90231==    by 0x4ACA0F4: PyEval_EvalCode (ceval.c:578)
==90231== 
==90231== 1,952 bytes in 2 blocks are still reachable in loss record 44 of 72
==90231==    at 0x4842788: malloc (vg_replace_malloc.c:446)
==90231==    by 0x49ED7FD: UnknownInlinedFun (obmalloc.c:45)
==90231==    by 0x49ED7FD: UnknownInlinedFun (obmalloc.c:662)
==90231==    by 0x49ED7FD: UnknownInlinedFun (obmalloc.c:1569)
==90231==    by 0x49ED7FD: UnknownInlinedFun (obmalloc.c:801)
==90231==    by 0x49ED7FD: UnknownInlinedFun (typeobject.c:1701)
==90231==    by 0x49ED7FD: PyType_GenericAlloc (typeobject.c:1725)
==90231==    by 0x4AC79E3: UnknownInlinedFun (typeobject.c:3322)
==90231==    by 0x4AC79E3: UnknownInlinedFun (typeobject.c:3762)
==90231==    by 0x4AC79E3: UnknownInlinedFun (typeobject.c:3785)
==90231==    by 0x4AC79E3: type_new (typeobject.c:3929)
==90231==    by 0x49FD975: UnknownInlinedFun (typeobject.c:1664)
==90231==    by 0x49FD975: _PyObject_MakeTpCall (call.c:240)
==90231==    by 0x4A0093B: _PyObject_FastCallDictTstate (call.c:133)
==90231==    by 0x4ACB65B: builtin___build_class__ (bltinmodule.c:208)
==90231==    by 0x4A21CBD: cfunction_vectorcall_FASTCALL_KEYWORDS (methodobject.c:438)
==90231==    by 0x4A21B6C: UnknownInlinedFun (pycore_call.h:92)
==90231==    by 0x4A21B6C: PyObject_Vectorcall (call.c:325)
==90231==    by 0x4A0631E: _PyEval_EvalFrameDefault (bytecodes.c:2714)
==90231==    by 0x4ACA0F4: PyEval_EvalCode (ceval.c:578)
==90231==    by 0x4AC9F97: exec_code_in_module (import.c:1712)
==90231==    by 0x4AC90D5: PyImport_ImportFrozenModuleObject (import.c:2154)
==90231== 
==90231== 1,952 bytes in 2 blocks are still reachable in loss record 45 of 72
==90231==    at 0x4842788: malloc (vg_replace_malloc.c:446)
==90231==    by 0x49ED7FD: UnknownInlinedFun (obmalloc.c:45)
==90231==    by 0x49ED7FD: UnknownInlinedFun (obmalloc.c:662)
==90231==    by 0x49ED7FD: UnknownInlinedFun (obmalloc.c:1569)
==90231==    by 0x49ED7FD: UnknownInlinedFun (obmalloc.c:801)
==90231==    by 0x49ED7FD: UnknownInlinedFun (typeobject.c:1701)
==90231==    by 0x49ED7FD: PyType_GenericAlloc (typeobject.c:1725)
==90231==    by 0x4AC79E3: UnknownInlinedFun (typeobject.c:3322)
==90231==    by 0x4AC79E3: UnknownInlinedFun (typeobject.c:3762)
==90231==    by 0x4AC79E3: UnknownInlinedFun (typeobject.c:3785)
==90231==    by 0x4AC79E3: type_new (typeobject.c:3929)
==90231==    by 0x49FD975: UnknownInlinedFun (typeobject.c:1664)
==90231==    by 0x49FD975: _PyObject_MakeTpCall (call.c:240)
==90231==    by 0x4A0093B: _PyObject_FastCallDictTstate (call.c:133)
==90231==    by 0x4ACB65B: builtin___build_class__ (bltinmodule.c:208)
==90231==    by 0x4A21CBD: cfunction_vectorcall_FASTCALL_KEYWORDS (methodobject.c:438)
==90231==    by 0x4A21B6C: UnknownInlinedFun (pycore_call.h:92)
==90231==    by 0x4A21B6C: PyObject_Vectorcall (call.c:325)
==90231==    by 0x4A0631E: _PyEval_EvalFrameDefault (bytecodes.c:2714)
==90231==    by 0x4ACA0F4: PyEval_EvalCode (ceval.c:578)
==90231==    by 0x4AE5705: UnknownInlinedFun (bltinmodule.c:1096)
==90231==    by 0x4AE5705: builtin_exec (bltinmodule.c.h:586)
==90231==    by 0x4A097D8: _PyEval_EvalFrameDefault (bytecodes.c:2974)
==90231== 
==90231== 1,952 bytes in 2 blocks are still reachable in loss record 46 of 72
==90231==    at 0x4842788: malloc (vg_replace_malloc.c:446)
==90231==    by 0x49ED7FD: UnknownInlinedFun (obmalloc.c:45)
==90231==    by 0x49ED7FD: UnknownInlinedFun (obmalloc.c:662)
==90231==    by 0x49ED7FD: UnknownInlinedFun (obmalloc.c:1569)
==90231==    by 0x49ED7FD: UnknownInlinedFun (obmalloc.c:801)
==90231==    by 0x49ED7FD: UnknownInlinedFun (typeobject.c:1701)
==90231==    by 0x49ED7FD: PyType_GenericAlloc (typeobject.c:1725)
==90231==    by 0x4AC84C4: UnknownInlinedFun (typeobject.c:3322)
==90231==    by 0x4AC84C4: UnknownInlinedFun (typeobject.c:3762)
==90231==    by 0x4AC84C4: UnknownInlinedFun (typeobject.c:3785)
==90231==    by 0x4AC84C4: type_new (typeobject.c:3929)
==90231==    by 0x49FD975: UnknownInlinedFun (typeobject.c:1664)
==90231==    by 0x49FD975: _PyObject_MakeTpCall (call.c:240)
==90231==    by 0x4A0093B: _PyObject_FastCallDictTstate (call.c:133)
==90231==    by 0x4ACB65B: builtin___build_class__ (bltinmodule.c:208)
==90231==    by 0x4A21CBD: cfunction_vectorcall_FASTCALL_KEYWORDS (methodobject.c:438)
==90231==    by 0x4A21B6C: UnknownInlinedFun (pycore_call.h:92)
==90231==    by 0x4A21B6C: PyObject_Vectorcall (call.c:325)
==90231==    by 0x4A0631E: _PyEval_EvalFrameDefault (bytecodes.c:2714)
==90231==    by 0x4ACA0F4: PyEval_EvalCode (ceval.c:578)
==90231==    by 0x4AE5705: UnknownInlinedFun (bltinmodule.c:1096)
==90231==    by 0x4AE5705: builtin_exec (bltinmodule.c.h:586)
==90231==    by 0x4A21CBD: cfunction_vectorcall_FASTCALL_KEYWORDS (methodobject.c:438)
==90231== 
==90231== 1,952 bytes in 2 blocks are still reachable in loss record 47 of 72
==90231==    at 0x4842788: malloc (vg_replace_malloc.c:446)
==90231==    by 0x49ED7FD: UnknownInlinedFun (obmalloc.c:45)
==90231==    by 0x49ED7FD: UnknownInlinedFun (obmalloc.c:662)
==90231==    by 0x49ED7FD: UnknownInlinedFun (obmalloc.c:1569)
==90231==    by 0x49ED7FD: UnknownInlinedFun (obmalloc.c:801)
==90231==    by 0x49ED7FD: UnknownInlinedFun (typeobject.c:1701)
==90231==    by 0x49ED7FD: PyType_GenericAlloc (typeobject.c:1725)
==90231==    by 0x4AC79E3: UnknownInlinedFun (typeobject.c:3322)
==90231==    by 0x4AC79E3: UnknownInlinedFun (typeobject.c:3762)
==90231==    by 0x4AC79E3: UnknownInlinedFun (typeobject.c:3785)
==90231==    by 0x4AC79E3: type_new (typeobject.c:3929)
==90231==    by 0x6493AE1: UnknownInlinedFun (_ctypes.c:1973)
==90231==    by 0x6493AE1: PyCSimpleType_new (_ctypes.c:2179)
==90231==    by 0x49FD975: UnknownInlinedFun (typeobject.c:1664)
==90231==    by 0x49FD975: _PyObject_MakeTpCall (call.c:240)
==90231==    by 0x4ACB65B: builtin___build_class__ (bltinmodule.c:208)
==90231==    by 0x4A21CBD: cfunction_vectorcall_FASTCALL_KEYWORDS (methodobject.c:438)
==90231==    by 0x4A21B6C: UnknownInlinedFun (pycore_call.h:92)
==90231==    by 0x4A21B6C: PyObject_Vectorcall (call.c:325)
==90231==    by 0x4A0631E: _PyEval_EvalFrameDefault (bytecodes.c:2714)
==90231==    by 0x4ACA0F4: PyEval_EvalCode (ceval.c:578)
==90231==    by 0x4AE5705: UnknownInlinedFun (bltinmodule.c:1096)
==90231==    by 0x4AE5705: builtin_exec (bltinmodule.c.h:586)
==90231==    by 0x4A21CBD: cfunction_vectorcall_FASTCALL_KEYWORDS (methodobject.c:438)
==90231== 
==90231== 1,952 bytes in 2 blocks are still reachable in loss record 48 of 72
==90231==    at 0x4842788: malloc (vg_replace_malloc.c:446)
==90231==    by 0x49ED7FD: UnknownInlinedFun (obmalloc.c:45)
==90231==    by 0x49ED7FD: UnknownInlinedFun (obmalloc.c:662)
==90231==    by 0x49ED7FD: UnknownInlinedFun (obmalloc.c:1569)
==90231==    by 0x49ED7FD: UnknownInlinedFun (obmalloc.c:801)
==90231==    by 0x49ED7FD: UnknownInlinedFun (typeobject.c:1701)
==90231==    by 0x49ED7FD: PyType_GenericAlloc (typeobject.c:1725)
==90231==    by 0x4AC79E3: UnknownInlinedFun (typeobject.c:3322)
==90231==    by 0x4AC79E3: UnknownInlinedFun (typeobject.c:3762)
==90231==    by 0x4AC79E3: UnknownInlinedFun (typeobject.c:3785)
==90231==    by 0x4AC79E3: type_new (typeobject.c:3929)
==90231==    by 0x649751A: StructUnionType_new (_ctypes.c:520)
==90231==    by 0x49FD975: UnknownInlinedFun (typeobject.c:1664)
==90231==    by 0x49FD975: _PyObject_MakeTpCall (call.c:240)
==90231==    by 0x4ACB65B: builtin___build_class__ (bltinmodule.c:208)
==90231==    by 0x4A21CBD: cfunction_vectorcall_FASTCALL_KEYWORDS (methodobject.c:438)
==90231==    by 0x4A21B6C: UnknownInlinedFun (pycore_call.h:92)
==90231==    by 0x4A21B6C: PyObject_Vectorcall (call.c:325)
==90231==    by 0x4A0631E: _PyEval_EvalFrameDefault (bytecodes.c:2714)
==90231==    by 0x4ACA0F4: PyEval_EvalCode (ceval.c:578)
==90231==    by 0x4AE5705: UnknownInlinedFun (bltinmodule.c:1096)
==90231==    by 0x4AE5705: builtin_exec (bltinmodule.c.h:586)
==90231==    by 0x4A21CBD: cfunction_vectorcall_FASTCALL_KEYWORDS (methodobject.c:438)
==90231== 
==90231== 2,095 bytes in 28 blocks are still reachable in loss record 49 of 72
==90231==    at 0x4842788: malloc (vg_replace_malloc.c:446)
==90231==    by 0x402587F: malloc (rtld-malloc.h:56)
==90231==    by 0x402587F: strdup (strdup.c:42)
==90231==    by 0x4008BEC: _dl_map_object (dl-load.c:2182)
==90231==    by 0x400C99B: dl_open_worker_begin (dl-open.c:578)
==90231==    by 0x4001522: _dl_catch_exception (dl-catch.c:237)
==90231==    by 0x400C0DF: dl_open_worker (dl-open.c:803)
==90231==    by 0x4001522: _dl_catch_exception (dl-catch.c:237)
==90231==    by 0x400C533: _dl_open (dl-open.c:905)
==90231==    by 0x4F369E3: dlopen_doit (dlopen.c:56)
==90231==    by 0x4001522: _dl_catch_exception (dl-catch.c:237)
==90231==    by 0x4001678: _dl_catch_error (dl-catch.c:256)
==90231==    by 0x4F364C2: _dlerror_run (dlerror.c:138)
==90231== 
==90231== 2,095 bytes in 28 blocks are still reachable in loss record 50 of 72
==90231==    at 0x4842788: malloc (vg_replace_malloc.c:446)
==90231==    by 0x400BE60: malloc (rtld-malloc.h:56)
==90231==    by 0x400BE60: _dl_new_object (dl-object.c:199)
==90231==    by 0x4007269: _dl_map_object_from_fd (dl-load.c:1053)
==90231==    by 0x4008C97: _dl_map_object (dl-load.c:2249)
==90231==    by 0x400C99B: dl_open_worker_begin (dl-open.c:578)
==90231==    by 0x4001522: _dl_catch_exception (dl-catch.c:237)
==90231==    by 0x400C0DF: dl_open_worker (dl-open.c:803)
==90231==    by 0x4001522: _dl_catch_exception (dl-catch.c:237)
==90231==    by 0x400C533: _dl_open (dl-open.c:905)
==90231==    by 0x4F369E3: dlopen_doit (dlopen.c:56)
==90231==    by 0x4001522: _dl_catch_exception (dl-catch.c:237)
==90231==    by 0x4001678: _dl_catch_error (dl-catch.c:256)
==90231== 
==90231== 2,288 bytes in 2 blocks are still reachable in loss record 51 of 72
==90231==    at 0x4842788: malloc (vg_replace_malloc.c:446)
==90231==    by 0x49F0714: UnknownInlinedFun (obmalloc.c:45)
==90231==    by 0x49F0714: UnknownInlinedFun (obmalloc.c:662)
==90231==    by 0x49F0714: UnknownInlinedFun (obmalloc.c:1569)
==90231==    by 0x49F0714: UnknownInlinedFun (obmalloc.c:801)
==90231==    by 0x49F0714: UnknownInlinedFun (dictobject.c:641)
==90231==    by 0x49F0714: dictresize (dictobject.c:1449)
==90231==    by 0x49EFD72: UnknownInlinedFun (dictobject.c:1194)
==90231==    by 0x49EFD72: insertdict (dictobject.c:1261)
==90231==    by 0x4A0ABD4: _PyEval_EvalFrameDefault (bytecodes.c:1023)
==90231==    by 0x4ACA0F4: PyEval_EvalCode (ceval.c:578)
==90231==    by 0x4AE5705: UnknownInlinedFun (bltinmodule.c:1096)
==90231==    by 0x4AE5705: builtin_exec (bltinmodule.c.h:586)
==90231==    by 0x4A097D8: _PyEval_EvalFrameDefault (bytecodes.c:2974)
==90231==    by 0x4A2C9FA: UnknownInlinedFun (pycore_call.h:92)
==90231==    by 0x4A2C9FA: object_vacall (call.c:850)
==90231==    by 0x4A5DF4A: PyObject_CallMethodObjArgs (call.c:911)
==90231==    by 0x4A5D020: UnknownInlinedFun (import.c:2779)
==90231==    by 0x4A5D020: PyImport_ImportModuleLevelObject (import.c:2862)
==90231==    by 0x4A0BF9F: UnknownInlinedFun (ceval.c:2482)
==90231==    by 0x4A0BF9F: _PyEval_EvalFrameDefault (bytecodes.c:2143)
==90231==    by 0x4ACA0F4: PyEval_EvalCode (ceval.c:578)
==90231== 
==90231== 2,288 bytes in 2 blocks are still reachable in loss record 52 of 72
==90231==    at 0x4842788: malloc (vg_replace_malloc.c:446)
==90231==    by 0x49F0714: UnknownInlinedFun (obmalloc.c:45)
==90231==    by 0x49F0714: UnknownInlinedFun (obmalloc.c:662)
==90231==    by 0x49F0714: UnknownInlinedFun (obmalloc.c:1569)
==90231==    by 0x49F0714: UnknownInlinedFun (obmalloc.c:801)
==90231==    by 0x49F0714: UnknownInlinedFun (dictobject.c:641)
==90231==    by 0x49F0714: dictresize (dictobject.c:1449)
==90231==    by 0x49F0ECE: PyDict_SetDefault (dictobject.c:3332)
==90231==    by 0x49E7956: UnknownInlinedFun (typeobject.c:6701)
==90231==    by 0x49E7956: UnknownInlinedFun (typeobject.c:7161)
==90231==    by 0x49E7956: type_ready (typeobject.c:7501)
==90231==    by 0x4AD652F: PyModule_AddType (modsupport.c:688)
==90231==    by 0x75C51F4: UnknownInlinedFun (_datetimemodule.c:6734)
==90231==    by 0x75C51F4: PyInit__datetime (_datetimemodule.c:6936)
==90231==    by 0x4AFE037: UnknownInlinedFun (importdl.c:169)
==90231==    by 0x4AFE037: UnknownInlinedFun (import.c:3775)
==90231==    by 0x4AFE037: _imp_create_dynamic (import.c.h:506)
==90231==    by 0x4A2E3CA: cfunction_vectorcall_FASTCALL (methodobject.c:422)
==90231==    by 0x4A0B71A: UnknownInlinedFun (call.c:387)
==90231==    by 0x4A0B71A: _PyEval_EvalFrameDefault (bytecodes.c:3262)
==90231==    by 0x4A2C9FA: UnknownInlinedFun (pycore_call.h:92)
==90231==    by 0x4A2C9FA: object_vacall (call.c:850)
==90231==    by 0x4A5DF4A: PyObject_CallMethodObjArgs (call.c:911)
==90231==    by 0x4A5D020: UnknownInlinedFun (import.c:2779)
==90231==    by 0x4A5D020: PyImport_ImportModuleLevelObject (import.c:2862)
==90231== 
==90231== 2,304 bytes in 3 blocks are still reachable in loss record 53 of 72
==90231==    at 0x4842788: malloc (vg_replace_malloc.c:446)
==90231==    by 0x49F0714: UnknownInlinedFun (obmalloc.c:45)
==90231==    by 0x49F0714: UnknownInlinedFun (obmalloc.c:662)
==90231==    by 0x49F0714: UnknownInlinedFun (obmalloc.c:1569)
==90231==    by 0x49F0714: UnknownInlinedFun (obmalloc.c:801)
==90231==    by 0x49F0714: UnknownInlinedFun (dictobject.c:641)
==90231==    by 0x49F0714: dictresize (dictobject.c:1449)
==90231==    by 0x49EFD72: UnknownInlinedFun (dictobject.c:1194)
==90231==    by 0x49EFD72: insertdict (dictobject.c:1261)
==90231==    by 0x4AF64DD: type_set_abstractmethods (typeobject.c:1136)
==90231==    by 0x49F3BE5: _PyObject_GenericSetAttrWithDict (object.c:1552)
==90231==    by 0x493529D: type_setattro.cold (typeobject.c:4933)
==90231==    by 0x49F332B: PyObject_SetAttr (object.c:1175)
==90231==    by 0x4AF5E86: UnknownInlinedFun (_abc.c:406)
==90231==    by 0x4AF5E86: _abc__abc_init (_abc.c:436)
==90231==    by 0x4A0697B: _PyEval_EvalFrameDefault (bytecodes.c:2912)
==90231==    by 0x4A00845: UnknownInlinedFun (pycore_ceval.h:89)
==90231==    by 0x4A00845: UnknownInlinedFun (ceval.c:1683)
==90231==    by 0x4A00845: UnknownInlinedFun (call.c:419)
==90231==    by 0x4A00845: _PyObject_FastCallDictTstate (call.c:133)
==90231==    by 0x4A5F116: UnknownInlinedFun (call.c:508)
==90231==    by 0x4A5F116: slot_tp_new (typeobject.c:9050)
==90231==    by 0x49FD975: UnknownInlinedFun (typeobject.c:1664)
==90231==    by 0x49FD975: _PyObject_MakeTpCall (call.c:240)
==90231== 
==90231== 2,304 bytes in 3 blocks are still reachable in loss record 54 of 72
==90231==    at 0x4842788: malloc (vg_replace_malloc.c:446)
==90231==    by 0x49E42F6: UnknownInlinedFun (obmalloc.c:45)
==90231==    by 0x49E42F6: UnknownInlinedFun (obmalloc.c:662)
==90231==    by 0x49E42F6: UnknownInlinedFun (obmalloc.c:1569)
==90231==    by 0x49E42F6: PyObject_Malloc (obmalloc.c:801)
==90231==    by 0x4AC4555: new_keys_object (dictobject.c:641)
==90231==    by 0x49E7B62: UnknownInlinedFun (dictobject.c:5321)
==90231==    by 0x49E7B62: UnknownInlinedFun (typeobject.c:7420)
==90231==    by 0x49E7B62: type_ready (typeobject.c:7519)
==90231==    by 0x4AC7DB8: UnknownInlinedFun (typeobject.c:3795)
==90231==    by 0x4AC7DB8: type_new (typeobject.c:3929)
==90231==    by 0x64949EF: PyCPointerType_new (_ctypes.c:1138)
==90231==    by 0x49FD975: UnknownInlinedFun (typeobject.c:1664)
==90231==    by 0x49FD975: _PyObject_MakeTpCall (call.c:240)
==90231==    by 0x49F7712: UnknownInlinedFun (pycore_call.h:90)
==90231==    by 0x49F7712: UnknownInlinedFun (pycore_call.h:77)
==90231==    by 0x49F7712: UnknownInlinedFun (call.c:562)
==90231==    by 0x49F7712: PyObject_CallFunction (call.c:584)
==90231==    by 0x6494606: POINTER (callproc.c:1926)
==90231==    by 0x4A2AF6B: cfunction_vectorcall_O (methodobject.c:509)
==90231==    by 0x4A21B6C: UnknownInlinedFun (pycore_call.h:92)
==90231==    by 0x4A21B6C: PyObject_Vectorcall (call.c:325)
==90231==    by 0x4A0631E: _PyEval_EvalFrameDefault (bytecodes.c:2714)
==90231== 
==90231== 2,928 bytes in 3 blocks are still reachable in loss record 55 of 72
==90231==    at 0x4842788: malloc (vg_replace_malloc.c:446)
==90231==    by 0x49ED7FD: UnknownInlinedFun (obmalloc.c:45)
==90231==    by 0x49ED7FD: UnknownInlinedFun (obmalloc.c:662)
==90231==    by 0x49ED7FD: UnknownInlinedFun (obmalloc.c:1569)
==90231==    by 0x49ED7FD: UnknownInlinedFun (obmalloc.c:801)
==90231==    by 0x49ED7FD: UnknownInlinedFun (typeobject.c:1701)
==90231==    by 0x49ED7FD: PyType_GenericAlloc (typeobject.c:1725)
==90231==    by 0x4AC79E3: UnknownInlinedFun (typeobject.c:3322)
==90231==    by 0x4AC79E3: UnknownInlinedFun (typeobject.c:3762)
==90231==    by 0x4AC79E3: UnknownInlinedFun (typeobject.c:3785)
==90231==    by 0x4AC79E3: type_new (typeobject.c:3929)
==90231==    by 0x64949EF: PyCPointerType_new (_ctypes.c:1138)
==90231==    by 0x49FD975: UnknownInlinedFun (typeobject.c:1664)
==90231==    by 0x49FD975: _PyObject_MakeTpCall (call.c:240)
==90231==    by 0x49F7712: UnknownInlinedFun (pycore_call.h:90)
==90231==    by 0x49F7712: UnknownInlinedFun (pycore_call.h:77)
==90231==    by 0x49F7712: UnknownInlinedFun (call.c:562)
==90231==    by 0x49F7712: PyObject_CallFunction (call.c:584)
==90231==    by 0x6494606: POINTER (callproc.c:1926)
==90231==    by 0x4A2AF6B: cfunction_vectorcall_O (methodobject.c:509)
==90231==    by 0x4A21B6C: UnknownInlinedFun (pycore_call.h:92)
==90231==    by 0x4A21B6C: PyObject_Vectorcall (call.c:325)
==90231==    by 0x4A0631E: _PyEval_EvalFrameDefault (bytecodes.c:2714)
==90231==    by 0x4ACA0F4: PyEval_EvalCode (ceval.c:578)
==90231==    by 0x4AE5705: UnknownInlinedFun (bltinmodule.c:1096)
==90231==    by 0x4AE5705: builtin_exec (bltinmodule.c.h:586)
==90231== 
==90231== 3,264 bytes in 1 blocks are still reachable in loss record 56 of 72
==90231==    at 0x4842788: malloc (vg_replace_malloc.c:446)
==90231==    by 0x49F0714: UnknownInlinedFun (obmalloc.c:45)
==90231==    by 0x49F0714: UnknownInlinedFun (obmalloc.c:662)
==90231==    by 0x49F0714: UnknownInlinedFun (obmalloc.c:1569)
==90231==    by 0x49F0714: UnknownInlinedFun (obmalloc.c:801)
==90231==    by 0x49F0714: UnknownInlinedFun (dictobject.c:641)
==90231==    by 0x49F0714: dictresize (dictobject.c:1449)
==90231==    by 0x49F0ECE: PyDict_SetDefault (dictobject.c:3332)
==90231==    by 0x49E7CAC: UnknownInlinedFun (typeobject.c:6628)
==90231==    by 0x49E7CAC: UnknownInlinedFun (typeobject.c:6654)
==90231==    by 0x49E7CAC: UnknownInlinedFun (typeobject.c:7155)
==90231==    by 0x49E7CAC: type_ready (typeobject.c:7501)
==90231==    by 0x7CF3E06: PyInit__decimal (_decimal.c:5777)
==90231==    by 0x4AFE037: UnknownInlinedFun (importdl.c:169)
==90231==    by 0x4AFE037: UnknownInlinedFun (import.c:3775)
==90231==    by 0x4AFE037: _imp_create_dynamic (import.c.h:506)
==90231==    by 0x4A2E3CA: cfunction_vectorcall_FASTCALL (methodobject.c:422)
==90231==    by 0x4A0B71A: UnknownInlinedFun (call.c:387)
==90231==    by 0x4A0B71A: _PyEval_EvalFrameDefault (bytecodes.c:3262)
==90231==    by 0x4A2C9FA: UnknownInlinedFun (pycore_call.h:92)
==90231==    by 0x4A2C9FA: object_vacall (call.c:850)
==90231==    by 0x4A5DF4A: PyObject_CallMethodObjArgs (call.c:911)
==90231==    by 0x4A5D020: UnknownInlinedFun (import.c:2779)
==90231==    by 0x4A5D020: PyImport_ImportModuleLevelObject (import.c:2862)
==90231==    by 0x4A0BF9F: UnknownInlinedFun (ceval.c:2482)
==90231==    by 0x4A0BF9F: _PyEval_EvalFrameDefault (bytecodes.c:2143)
==90231== 
==90231== 3,904 bytes in 4 blocks are still reachable in loss record 57 of 72
==90231==    at 0x4842788: malloc (vg_replace_malloc.c:446)
==90231==    by 0x49ED7FD: UnknownInlinedFun (obmalloc.c:45)
==90231==    by 0x49ED7FD: UnknownInlinedFun (obmalloc.c:662)
==90231==    by 0x49ED7FD: UnknownInlinedFun (obmalloc.c:1569)
==90231==    by 0x49ED7FD: UnknownInlinedFun (obmalloc.c:801)
==90231==    by 0x49ED7FD: UnknownInlinedFun (typeobject.c:1701)
==90231==    by 0x49ED7FD: PyType_GenericAlloc (typeobject.c:1725)
==90231==    by 0x4AC79E3: UnknownInlinedFun (typeobject.c:3322)
==90231==    by 0x4AC79E3: UnknownInlinedFun (typeobject.c:3762)
==90231==    by 0x4AC79E3: UnknownInlinedFun (typeobject.c:3785)
==90231==    by 0x4AC79E3: type_new (typeobject.c:3929)
==90231==    by 0x49FD975: UnknownInlinedFun (typeobject.c:1664)
==90231==    by 0x49FD975: _PyObject_MakeTpCall (call.c:240)
==90231==    by 0x49F75D9: UnknownInlinedFun (pycore_call.h:92)
==90231==    by 0x49F75D9: UnknownInlinedFun (call.c:562)
==90231==    by 0x49F75D9: PyObject_CallFunction (call.c:584)
==90231==    by 0x4AC77D4: PyErr_NewException (errors.c:1303)
==90231==    by 0x7CF4354: PyInit__decimal (_decimal.c:5910)
==90231==    by 0x4AFE037: UnknownInlinedFun (importdl.c:169)
==90231==    by 0x4AFE037: UnknownInlinedFun (import.c:3775)
==90231==    by 0x4AFE037: _imp_create_dynamic (import.c.h:506)
==90231==    by 0x4A2E3CA: cfunction_vectorcall_FASTCALL (methodobject.c:422)
==90231==    by 0x4A0B71A: UnknownInlinedFun (call.c:387)
==90231==    by 0x4A0B71A: _PyEval_EvalFrameDefault (bytecodes.c:3262)
==90231==    by 0x4A2C9FA: UnknownInlinedFun (pycore_call.h:92)
==90231==    by 0x4A2C9FA: object_vacall (call.c:850)
==90231==    by 0x4A5DF4A: PyObject_CallMethodObjArgs (call.c:911)
==90231== 
==90231== 6,144 bytes in 3 blocks are still reachable in loss record 58 of 72
==90231==    at 0x4842788: malloc (vg_replace_malloc.c:446)
==90231==    by 0x49F9B23: UnknownInlinedFun (obmalloc.c:45)
==90231==    by 0x49F9B23: UnknownInlinedFun (obmalloc.c:662)
==90231==    by 0x49F9B23: UnknownInlinedFun (obmalloc.c:1569)
==90231==    by 0x49F9B23: UnknownInlinedFun (obmalloc.c:703)
==90231==    by 0x49F9B23: set_table_resize (setobject.c:274)
==90231==    by 0x4AF5FAE: UnknownInlinedFun (_abc.c:392)
==90231==    by 0x4AF5FAE: _abc__abc_init (_abc.c:436)
==90231==    by 0x4A0697B: _PyEval_EvalFrameDefault (bytecodes.c:2912)
==90231==    by 0x4A00845: UnknownInlinedFun (pycore_ceval.h:89)
==90231==    by 0x4A00845: UnknownInlinedFun (ceval.c:1683)
==90231==    by 0x4A00845: UnknownInlinedFun (call.c:419)
==90231==    by 0x4A00845: _PyObject_FastCallDictTstate (call.c:133)
==90231==    by 0x4A5F116: UnknownInlinedFun (call.c:508)
==90231==    by 0x4A5F116: slot_tp_new (typeobject.c:9050)
==90231==    by 0x49FD975: UnknownInlinedFun (typeobject.c:1664)
==90231==    by 0x49FD975: _PyObject_MakeTpCall (call.c:240)
==90231==    by 0x4ACB65B: builtin___build_class__ (bltinmodule.c:208)
==90231==    by 0x4A21CBD: cfunction_vectorcall_FASTCALL_KEYWORDS (methodobject.c:438)
==90231==    by 0x4A21B6C: UnknownInlinedFun (pycore_call.h:92)
==90231==    by 0x4A21B6C: PyObject_Vectorcall (call.c:325)
==90231==    by 0x4A0631E: _PyEval_EvalFrameDefault (bytecodes.c:2714)
==90231==    by 0x4ACA0F4: PyEval_EvalCode (ceval.c:578)
==90231== 
==90231== 6,144 bytes in 8 blocks are still reachable in loss record 59 of 72
==90231==    at 0x4842788: malloc (vg_replace_malloc.c:446)
==90231==    by 0x49E42F6: UnknownInlinedFun (obmalloc.c:45)
==90231==    by 0x49E42F6: UnknownInlinedFun (obmalloc.c:662)
==90231==    by 0x49E42F6: UnknownInlinedFun (obmalloc.c:1569)
==90231==    by 0x49E42F6: PyObject_Malloc (obmalloc.c:801)
==90231==    by 0x4AC4555: new_keys_object (dictobject.c:641)
==90231==    by 0x49E7B62: UnknownInlinedFun (dictobject.c:5321)
==90231==    by 0x49E7B62: UnknownInlinedFun (typeobject.c:7420)
==90231==    by 0x49E7B62: type_ready (typeobject.c:7519)
==90231==    by 0x4AC7DB8: UnknownInlinedFun (typeobject.c:3795)
==90231==    by 0x4AC7DB8: type_new (typeobject.c:3929)
==90231==    by 0x49FD975: UnknownInlinedFun (typeobject.c:1664)
==90231==    by 0x49FD975: _PyObject_MakeTpCall (call.c:240)
==90231==    by 0x4A0093B: _PyObject_FastCallDictTstate (call.c:133)
==90231==    by 0x4ACB65B: builtin___build_class__ (bltinmodule.c:208)
==90231==    by 0x4A21CBD: cfunction_vectorcall_FASTCALL_KEYWORDS (methodobject.c:438)
==90231==    by 0x4A21B6C: UnknownInlinedFun (pycore_call.h:92)
==90231==    by 0x4A21B6C: PyObject_Vectorcall (call.c:325)
==90231==    by 0x4A0631E: _PyEval_EvalFrameDefault (bytecodes.c:2714)
==90231==    by 0x4ACA0F4: PyEval_EvalCode (ceval.c:578)
==90231== 
==90231== 6,144 bytes in 8 blocks are still reachable in loss record 60 of 72
==90231==    at 0x4842788: malloc (vg_replace_malloc.c:446)
==90231==    by 0x49E42F6: UnknownInlinedFun (obmalloc.c:45)
==90231==    by 0x49E42F6: UnknownInlinedFun (obmalloc.c:662)
==90231==    by 0x49E42F6: UnknownInlinedFun (obmalloc.c:1569)
==90231==    by 0x49E42F6: PyObject_Malloc (obmalloc.c:801)
==90231==    by 0x4AC4555: new_keys_object (dictobject.c:641)
==90231==    by 0x49E7B62: UnknownInlinedFun (dictobject.c:5321)
==90231==    by 0x49E7B62: UnknownInlinedFun (typeobject.c:7420)
==90231==    by 0x49E7B62: type_ready (typeobject.c:7519)
==90231==    by 0x4AC7DB8: UnknownInlinedFun (typeobject.c:3795)
==90231==    by 0x4AC7DB8: type_new (typeobject.c:3929)
==90231==    by 0x64937DA: PyCSimpleType_new (_ctypes.c:2045)
==90231==    by 0x49FD975: UnknownInlinedFun (typeobject.c:1664)
==90231==    by 0x49FD975: _PyObject_MakeTpCall (call.c:240)
==90231==    by 0x4ACB65B: builtin___build_class__ (bltinmodule.c:208)
==90231==    by 0x4A21CBD: cfunction_vectorcall_FASTCALL_KEYWORDS (methodobject.c:438)
==90231==    by 0x4A21B6C: UnknownInlinedFun (pycore_call.h:92)
==90231==    by 0x4A21B6C: PyObject_Vectorcall (call.c:325)
==90231==    by 0x4A0631E: _PyEval_EvalFrameDefault (bytecodes.c:2714)
==90231==    by 0x4ACA0F4: PyEval_EvalCode (ceval.c:578)
==90231== 
==90231== 6,832 bytes in 7 blocks are still reachable in loss record 61 of 72
==90231==    at 0x4842788: malloc (vg_replace_malloc.c:446)
==90231==    by 0x49ED7FD: UnknownInlinedFun (obmalloc.c:45)
==90231==    by 0x49ED7FD: UnknownInlinedFun (obmalloc.c:662)
==90231==    by 0x49ED7FD: UnknownInlinedFun (obmalloc.c:1569)
==90231==    by 0x49ED7FD: UnknownInlinedFun (obmalloc.c:801)
==90231==    by 0x49ED7FD: UnknownInlinedFun (typeobject.c:1701)
==90231==    by 0x49ED7FD: PyType_GenericAlloc (typeobject.c:1725)
==90231==    by 0x4AC79E3: UnknownInlinedFun (typeobject.c:3322)
==90231==    by 0x4AC79E3: UnknownInlinedFun (typeobject.c:3762)
==90231==    by 0x4AC79E3: UnknownInlinedFun (typeobject.c:3785)
==90231==    by 0x4AC79E3: type_new (typeobject.c:3929)
==90231==    by 0x49FD975: UnknownInlinedFun (typeobject.c:1664)
==90231==    by 0x49FD975: _PyObject_MakeTpCall (call.c:240)
==90231==    by 0x4A0093B: _PyObject_FastCallDictTstate (call.c:133)
==90231==    by 0x4ACB65B: builtin___build_class__ (bltinmodule.c:208)
==90231==    by 0x4A21CBD: cfunction_vectorcall_FASTCALL_KEYWORDS (methodobject.c:438)
==90231==    by 0x4A21B6C: UnknownInlinedFun (pycore_call.h:92)
==90231==    by 0x4A21B6C: PyObject_Vectorcall (call.c:325)
==90231==    by 0x4A0631E: _PyEval_EvalFrameDefault (bytecodes.c:2714)
==90231==    by 0x4ACA0F4: PyEval_EvalCode (ceval.c:578)
==90231==    by 0x4AE5705: UnknownInlinedFun (bltinmodule.c:1096)
==90231==    by 0x4AE5705: builtin_exec (bltinmodule.c.h:586)
==90231==    by 0x4A21CBD: cfunction_vectorcall_FASTCALL_KEYWORDS (methodobject.c:438)
==90231== 
==90231== 6,912 bytes in 9 blocks are still reachable in loss record 62 of 72
==90231==    at 0x4842788: malloc (vg_replace_malloc.c:446)
==90231==    by 0x49E42F6: UnknownInlinedFun (obmalloc.c:45)
==90231==    by 0x49E42F6: UnknownInlinedFun (obmalloc.c:662)
==90231==    by 0x49E42F6: UnknownInlinedFun (obmalloc.c:1569)
==90231==    by 0x49E42F6: PyObject_Malloc (obmalloc.c:801)
==90231==    by 0x4AC4555: new_keys_object (dictobject.c:641)
==90231==    by 0x49E7B62: UnknownInlinedFun (dictobject.c:5321)
==90231==    by 0x49E7B62: UnknownInlinedFun (typeobject.c:7420)
==90231==    by 0x49E7B62: type_ready (typeobject.c:7519)
==90231==    by 0x4AC7DB8: UnknownInlinedFun (typeobject.c:3795)
==90231==    by 0x4AC7DB8: type_new (typeobject.c:3929)
==90231==    by 0x6494078: PyCFuncPtrType_new (_ctypes.c:2553)
==90231==    by 0x49FD975: UnknownInlinedFun (typeobject.c:1664)
==90231==    by 0x49FD975: _PyObject_MakeTpCall (call.c:240)
==90231==    by 0x4ACB65B: builtin___build_class__ (bltinmodule.c:208)
==90231==    by 0x4A097D8: _PyEval_EvalFrameDefault (bytecodes.c:2974)
==90231==    by 0x4ACB621: builtin___build_class__ (bltinmodule.c:200)
==90231==    by 0x4A21CBD: cfunction_vectorcall_FASTCALL_KEYWORDS (methodobject.c:438)
==90231==    by 0x4A21B6C: UnknownInlinedFun (pycore_call.h:92)
==90231==    by 0x4A21B6C: PyObject_Vectorcall (call.c:325)
==90231== 
==90231== 6,936 bytes in 33 blocks are still reachable in loss record 63 of 72
==90231==    at 0x4849BF3: calloc (vg_replace_malloc.c:1675)
==90231==    by 0x4013D77: calloc (rtld-malloc.h:44)
==90231==    by 0x4013D77: _dl_check_map_versions (dl-version.c:280)
==90231==    by 0x400CA4A: dl_open_worker_begin (dl-open.c:646)
==90231==    by 0x4001522: _dl_catch_exception (dl-catch.c:237)
==90231==    by 0x400C0DF: dl_open_worker (dl-open.c:803)
==90231==    by 0x4001522: _dl_catch_exception (dl-catch.c:237)
==90231==    by 0x400C533: _dl_open (dl-open.c:905)
==90231==    by 0x4F369E3: dlopen_doit (dlopen.c:56)
==90231==    by 0x4001522: _dl_catch_exception (dl-catch.c:237)
==90231==    by 0x4001678: _dl_catch_error (dl-catch.c:256)
==90231==    by 0x4F364C2: _dlerror_run (dlerror.c:138)
==90231==    by 0x4F36A9E: dlopen_implementation (dlopen.c:71)
==90231==    by 0x4F36A9E: dlopen@@GLIBC_2.34 (dlopen.c:81)
==90231== 
==90231== 7,808 bytes in 8 blocks are still reachable in loss record 64 of 72
==90231==    at 0x4842788: malloc (vg_replace_malloc.c:446)
==90231==    by 0x49ED7FD: UnknownInlinedFun (obmalloc.c:45)
==90231==    by 0x49ED7FD: UnknownInlinedFun (obmalloc.c:662)
==90231==    by 0x49ED7FD: UnknownInlinedFun (obmalloc.c:1569)
==90231==    by 0x49ED7FD: UnknownInlinedFun (obmalloc.c:801)
==90231==    by 0x49ED7FD: UnknownInlinedFun (typeobject.c:1701)
==90231==    by 0x49ED7FD: PyType_GenericAlloc (typeobject.c:1725)
==90231==    by 0x4AC79E3: UnknownInlinedFun (typeobject.c:3322)
==90231==    by 0x4AC79E3: UnknownInlinedFun (typeobject.c:3762)
==90231==    by 0x4AC79E3: UnknownInlinedFun (typeobject.c:3785)
==90231==    by 0x4AC79E3: type_new (typeobject.c:3929)
==90231==    by 0x64937DA: PyCSimpleType_new (_ctypes.c:2045)
==90231==    by 0x49FD975: UnknownInlinedFun (typeobject.c:1664)
==90231==    by 0x49FD975: _PyObject_MakeTpCall (call.c:240)
==90231==    by 0x4ACB65B: builtin___build_class__ (bltinmodule.c:208)
==90231==    by 0x4A21CBD: cfunction_vectorcall_FASTCALL_KEYWORDS (methodobject.c:438)
==90231==    by 0x4A21B6C: UnknownInlinedFun (pycore_call.h:92)
==90231==    by 0x4A21B6C: PyObject_Vectorcall (call.c:325)
==90231==    by 0x4A0631E: _PyEval_EvalFrameDefault (bytecodes.c:2714)
==90231==    by 0x4ACA0F4: PyEval_EvalCode (ceval.c:578)
==90231==    by 0x4AE5705: UnknownInlinedFun (bltinmodule.c:1096)
==90231==    by 0x4AE5705: builtin_exec (bltinmodule.c.h:586)
==90231==    by 0x4A21CBD: cfunction_vectorcall_FASTCALL_KEYWORDS (methodobject.c:438)
==90231== 
==90231== 8,784 bytes in 9 blocks are still reachable in loss record 65 of 72
==90231==    at 0x4842788: malloc (vg_replace_malloc.c:446)
==90231==    by 0x49ED7FD: UnknownInlinedFun (obmalloc.c:45)
==90231==    by 0x49ED7FD: UnknownInlinedFun (obmalloc.c:662)
==90231==    by 0x49ED7FD: UnknownInlinedFun (obmalloc.c:1569)
==90231==    by 0x49ED7FD: UnknownInlinedFun (obmalloc.c:801)
==90231==    by 0x49ED7FD: UnknownInlinedFun (typeobject.c:1701)
==90231==    by 0x49ED7FD: PyType_GenericAlloc (typeobject.c:1725)
==90231==    by 0x4AC79E3: UnknownInlinedFun (typeobject.c:3322)
==90231==    by 0x4AC79E3: UnknownInlinedFun (typeobject.c:3762)
==90231==    by 0x4AC79E3: UnknownInlinedFun (typeobject.c:3785)
==90231==    by 0x4AC79E3: type_new (typeobject.c:3929)
==90231==    by 0x6494078: PyCFuncPtrType_new (_ctypes.c:2553)
==90231==    by 0x49FD975: UnknownInlinedFun (typeobject.c:1664)
==90231==    by 0x49FD975: _PyObject_MakeTpCall (call.c:240)
==90231==    by 0x4ACB65B: builtin___build_class__ (bltinmodule.c:208)
==90231==    by 0x4A097D8: _PyEval_EvalFrameDefault (bytecodes.c:2974)
==90231==    by 0x4ACB621: builtin___build_class__ (bltinmodule.c:200)
==90231==    by 0x4A21CBD: cfunction_vectorcall_FASTCALL_KEYWORDS (methodobject.c:438)
==90231==    by 0x4A21B6C: UnknownInlinedFun (pycore_call.h:92)
==90231==    by 0x4A21B6C: PyObject_Vectorcall (call.c:325)
==90231==    by 0x4A0631E: _PyEval_EvalFrameDefault (bytecodes.c:2714)
==90231==    by 0x4ACA0F4: PyEval_EvalCode (ceval.c:578)
==90231== 
==90231== 8,784 bytes in 9 blocks are still reachable in loss record 66 of 72
==90231==    at 0x4842788: malloc (vg_replace_malloc.c:446)
==90231==    by 0x49ED7FD: UnknownInlinedFun (obmalloc.c:45)
==90231==    by 0x49ED7FD: UnknownInlinedFun (obmalloc.c:662)
==90231==    by 0x49ED7FD: UnknownInlinedFun (obmalloc.c:1569)
==90231==    by 0x49ED7FD: UnknownInlinedFun (obmalloc.c:801)
==90231==    by 0x49ED7FD: UnknownInlinedFun (typeobject.c:1701)
==90231==    by 0x49ED7FD: PyType_GenericAlloc (typeobject.c:1725)
==90231==    by 0x4AC79E3: UnknownInlinedFun (typeobject.c:3322)
==90231==    by 0x4AC79E3: UnknownInlinedFun (typeobject.c:3762)
==90231==    by 0x4AC79E3: UnknownInlinedFun (typeobject.c:3785)
==90231==    by 0x4AC79E3: type_new (typeobject.c:3929)
==90231==    by 0x49FD975: UnknownInlinedFun (typeobject.c:1664)
==90231==    by 0x49FD975: _PyObject_MakeTpCall (call.c:240)
==90231==    by 0x49F75D9: UnknownInlinedFun (pycore_call.h:92)
==90231==    by 0x49F75D9: UnknownInlinedFun (call.c:562)
==90231==    by 0x49F75D9: PyObject_CallFunction (call.c:584)
==90231==    by 0x4AC77D4: PyErr_NewException (errors.c:1303)
==90231==    by 0x7CF41EF: PyInit__decimal (_decimal.c:5880)
==90231==    by 0x4AFE037: UnknownInlinedFun (importdl.c:169)
==90231==    by 0x4AFE037: UnknownInlinedFun (import.c:3775)
==90231==    by 0x4AFE037: _imp_create_dynamic (import.c.h:506)
==90231==    by 0x4A2E3CA: cfunction_vectorcall_FASTCALL (methodobject.c:422)
==90231==    by 0x4A0B71A: UnknownInlinedFun (call.c:387)
==90231==    by 0x4A0B71A: _PyEval_EvalFrameDefault (bytecodes.c:3262)
==90231==    by 0x4A2C9FA: UnknownInlinedFun (pycore_call.h:92)
==90231==    by 0x4A2C9FA: object_vacall (call.c:850)
==90231==    by 0x4A5DF4A: PyObject_CallMethodObjArgs (call.c:911)
==90231== 
==90231== 10,023 bytes in 8 blocks are still reachable in loss record 67 of 72
==90231==    at 0x4849BF3: calloc (vg_replace_malloc.c:1675)
==90231==    by 0x400BB7D: calloc (rtld-malloc.h:44)
==90231==    by 0x400BB7D: _dl_new_object (dl-object.c:92)
==90231==    by 0x4007269: _dl_map_object_from_fd (dl-load.c:1053)
==90231==    by 0x4008C97: _dl_map_object (dl-load.c:2249)
==90231==    by 0x400287C: openaux (dl-deps.c:64)
==90231==    by 0x4001522: _dl_catch_exception (dl-catch.c:237)
==90231==    by 0x4002D04: _dl_map_object_deps (dl-deps.c:232)
==90231==    by 0x400CA04: dl_open_worker_begin (dl-open.c:638)
==90231==    by 0x4001522: _dl_catch_exception (dl-catch.c:237)
==90231==    by 0x400C0DF: dl_open_worker (dl-open.c:803)
==90231==    by 0x4001522: _dl_catch_exception (dl-catch.c:237)
==90231==    by 0x400C533: _dl_open (dl-open.c:905)
==90231== 
==90231== 10,544 bytes in 3 blocks are still reachable in loss record 68 of 72
==90231==    at 0x4842788: malloc (vg_replace_malloc.c:446)
==90231==    by 0x49F0714: UnknownInlinedFun (obmalloc.c:45)
==90231==    by 0x49F0714: UnknownInlinedFun (obmalloc.c:662)
==90231==    by 0x49F0714: UnknownInlinedFun (obmalloc.c:1569)
==90231==    by 0x49F0714: UnknownInlinedFun (obmalloc.c:801)
==90231==    by 0x49F0714: UnknownInlinedFun (dictobject.c:641)
==90231==    by 0x49F0714: dictresize (dictobject.c:1449)
==90231==    by 0x49EFD72: UnknownInlinedFun (dictobject.c:1194)
==90231==    by 0x49EFD72: insertdict (dictobject.c:1261)
==90231==    by 0x4A0ABD4: _PyEval_EvalFrameDefault (bytecodes.c:1023)
==90231==    by 0x4ACA0F4: PyEval_EvalCode (ceval.c:578)
==90231==    by 0x4AE5705: UnknownInlinedFun (bltinmodule.c:1096)
==90231==    by 0x4AE5705: builtin_exec (bltinmodule.c.h:586)
==90231==    by 0x4A21CBD: cfunction_vectorcall_FASTCALL_KEYWORDS (methodobject.c:438)
==90231==    by 0x4A0B71A: UnknownInlinedFun (call.c:387)
==90231==    by 0x4A0B71A: _PyEval_EvalFrameDefault (bytecodes.c:3262)
==90231==    by 0x4A2C9FA: UnknownInlinedFun (pycore_call.h:92)
==90231==    by 0x4A2C9FA: object_vacall (call.c:850)
==90231==    by 0x4A5DF4A: PyObject_CallMethodObjArgs (call.c:911)
==90231==    by 0x4A5D020: UnknownInlinedFun (import.c:2779)
==90231==    by 0x4A5D020: PyImport_ImportModuleLevelObject (import.c:2862)
==90231==    by 0x4A0BF9F: UnknownInlinedFun (ceval.c:2482)
==90231==    by 0x4A0BF9F: _PyEval_EvalFrameDefault (bytecodes.c:2143)
==90231== 
==90231== 30,296 bytes in 31 blocks are still reachable in loss record 69 of 72
==90231==    at 0x4842788: malloc (vg_replace_malloc.c:446)
==90231==    by 0x49ED7FD: UnknownInlinedFun (obmalloc.c:45)
==90231==    by 0x49ED7FD: UnknownInlinedFun (obmalloc.c:662)
==90231==    by 0x49ED7FD: UnknownInlinedFun (obmalloc.c:1569)
==90231==    by 0x49ED7FD: UnknownInlinedFun (obmalloc.c:801)
==90231==    by 0x49ED7FD: UnknownInlinedFun (typeobject.c:1701)
==90231==    by 0x49ED7FD: PyType_GenericAlloc (typeobject.c:1725)
==90231==    by 0x4AC84C4: UnknownInlinedFun (typeobject.c:3322)
==90231==    by 0x4AC84C4: UnknownInlinedFun (typeobject.c:3762)
==90231==    by 0x4AC84C4: UnknownInlinedFun (typeobject.c:3785)
==90231==    by 0x4AC84C4: type_new (typeobject.c:3929)
==90231==    by 0x4A5F465: tp_new_wrapper (typeobject.c:8312)
==90231==    by 0x4A2DA86: cfunction_call (methodobject.c:537)
==90231==    by 0x4A3FA59: _PyObject_Call (call.c:367)
==90231==    by 0x4A0B71A: UnknownInlinedFun (call.c:387)
==90231==    by 0x4A0B71A: _PyEval_EvalFrameDefault (bytecodes.c:3262)
==90231==    by 0x4A00845: UnknownInlinedFun (pycore_ceval.h:89)
==90231==    by 0x4A00845: UnknownInlinedFun (ceval.c:1683)
==90231==    by 0x4A00845: UnknownInlinedFun (call.c:419)
==90231==    by 0x4A00845: _PyObject_FastCallDictTstate (call.c:133)
==90231==    by 0x4A5F116: UnknownInlinedFun (call.c:508)
==90231==    by 0x4A5F116: slot_tp_new (typeobject.c:9050)
==90231==    by 0x49FD975: UnknownInlinedFun (typeobject.c:1664)
==90231==    by 0x49FD975: _PyObject_MakeTpCall (call.c:240)
==90231==    by 0x4ACB65B: builtin___build_class__ (bltinmodule.c:208)
==90231==    by 0x4A21CBD: cfunction_vectorcall_FASTCALL_KEYWORDS (methodobject.c:438)
==90231== 
==90231== 36,815 bytes in 28 blocks are still reachable in loss record 70 of 72
==90231==    at 0x4849BF3: calloc (vg_replace_malloc.c:1675)
==90231==    by 0x400BB7D: calloc (rtld-malloc.h:44)
==90231==    by 0x400BB7D: _dl_new_object (dl-object.c:92)
==90231==    by 0x4007269: _dl_map_object_from_fd (dl-load.c:1053)
==90231==    by 0x4008C97: _dl_map_object (dl-load.c:2249)
==90231==    by 0x400C99B: dl_open_worker_begin (dl-open.c:578)
==90231==    by 0x4001522: _dl_catch_exception (dl-catch.c:237)
==90231==    by 0x400C0DF: dl_open_worker (dl-open.c:803)
==90231==    by 0x4001522: _dl_catch_exception (dl-catch.c:237)
==90231==    by 0x400C533: _dl_open (dl-open.c:905)
==90231==    by 0x4F369E3: dlopen_doit (dlopen.c:56)
==90231==    by 0x4001522: _dl_catch_exception (dl-catch.c:237)
==90231==    by 0x4001678: _dl_catch_error (dl-catch.c:256)
==90231== 
==90231== 131,072 bytes in 1 blocks are still reachable in loss record 71 of 72
==90231==    at 0x4849BF3: calloc (vg_replace_malloc.c:1675)
==90231==    by 0x4ABF734: UnknownInlinedFun (obmalloc.c:671)
==90231==    by 0x4ABF734: UnknownInlinedFun (obmalloc.c:1033)
==90231==    by 0x4ABF734: arena_map_mark_used (obmalloc.c:1076)
==90231==    by 0x4ABF37C: UnknownInlinedFun (obmalloc.c:1209)
==90231==    by 0x4ABF37C: allocate_from_new_pool (obmalloc.c:1389)
==90231==    by 0x49E40D8: UnknownInlinedFun (obmalloc.c:1553)
==90231==    by 0x49E40D8: UnknownInlinedFun (obmalloc.c:1564)
==90231==    by 0x49E40D8: UnknownInlinedFun (obmalloc.c:801)
==90231==    by 0x49E40D8: UnknownInlinedFun (gcmodule.c:2307)
==90231==    by 0x49E40D8: _PyObject_GC_New (gcmodule.c:2322)
==90231==    by 0x49E3DE3: UnknownInlinedFun (dictobject.c:748)
==90231==    by 0x49E3DE3: PyDict_New (dictobject.c:851)
==90231==    by 0x4ABCBC2: UnknownInlinedFun (unicodeobject.c:287)
==90231==    by 0x4ABCBC2: UnknownInlinedFun (unicodeobject.c:14708)
==90231==    by 0x4ABCBC2: UnknownInlinedFun (pylifecycle.c:678)
==90231==    by 0x4ABCBC2: pycore_interp_init (pylifecycle.c:826)
==90231==    by 0x4AB76ED: UnknownInlinedFun (pylifecycle.c:897)
==90231==    by 0x4AB76ED: pyinit_core.constprop.0 (pylifecycle.c:1060)
==90231==    by 0x4AB6EF2: Py_InitializeFromConfig (pylifecycle.c:1282)
==90231==    by 0x4AB6C10: pymain_init (main.c:67)
==90231==    by 0x4AB5AB0: pymain_main (main.c:730)
==90231==    by 0x4AB560B: Py_BytesMain (main.c:763)
==90231==    by 0x4ECDC87: (below main) (libc_start_call_main.h:58)
==90231== 
==90231== 262,144 bytes in 1 blocks are still reachable in loss record 72 of 72
==90231==    at 0x4849BF3: calloc (vg_replace_malloc.c:1675)
==90231==    by 0x4ABF69B: UnknownInlinedFun (obmalloc.c:671)
==90231==    by 0x4ABF69B: UnknownInlinedFun (obmalloc.c:1021)
==90231==    by 0x4ABF69B: arena_map_mark_used (obmalloc.c:1076)
==90231==    by 0x4ABF37C: UnknownInlinedFun (obmalloc.c:1209)
==90231==    by 0x4ABF37C: allocate_from_new_pool (obmalloc.c:1389)
==90231==    by 0x49E40D8: UnknownInlinedFun (obmalloc.c:1553)
==90231==    by 0x49E40D8: UnknownInlinedFun (obmalloc.c:1564)
==90231==    by 0x49E40D8: UnknownInlinedFun (obmalloc.c:801)
==90231==    by 0x49E40D8: UnknownInlinedFun (gcmodule.c:2307)
==90231==    by 0x49E40D8: _PyObject_GC_New (gcmodule.c:2322)
==90231==    by 0x49E3DE3: UnknownInlinedFun (dictobject.c:748)
==90231==    by 0x49E3DE3: PyDict_New (dictobject.c:851)
==90231==    by 0x4ABCBC2: UnknownInlinedFun (unicodeobject.c:287)
==90231==    by 0x4ABCBC2: UnknownInlinedFun (unicodeobject.c:14708)
==90231==    by 0x4ABCBC2: UnknownInlinedFun (pylifecycle.c:678)
==90231==    by 0x4ABCBC2: pycore_interp_init (pylifecycle.c:826)
==90231==    by 0x4AB76ED: UnknownInlinedFun (pylifecycle.c:897)
==90231==    by 0x4AB76ED: pyinit_core.constprop.0 (pylifecycle.c:1060)
==90231==    by 0x4AB6EF2: Py_InitializeFromConfig (pylifecycle.c:1282)
==90231==    by 0x4AB6C10: pymain_init (main.c:67)
==90231==    by 0x4AB5AB0: pymain_main (main.c:730)
==90231==    by 0x4AB560B: Py_BytesMain (main.c:763)
==90231==    by 0x4ECDC87: (below main) (libc_start_call_main.h:58)
==90231== 
==90231== LEAK SUMMARY:
==90231==    definitely lost: 0 bytes in 0 blocks
==90231==    indirectly lost: 0 bytes in 0 blocks
==90231==      possibly lost: 0 bytes in 0 blocks
==90231==    still reachable: 621,828 bytes in 309 blocks
==90231==         suppressed: 0 bytes in 0 blocks
==90231== 
==90231== For lists of detected and suppressed errors, rerun with: -s
==90231== ERROR SUMMARY: 0 errors from 0 contexts (suppressed: 0 from 0)
