==50552== Memcheck, a memory error detector
==50552== Copyright (C) 2002-2024, and GNU GPL'd, by Julian Seward et al.
==50552== Using Valgrind-3.23.0 and LibVEX; rerun with -h for copyright info
==50552== Command: python3 test.py
==50552== Parent PID: 50145
==50552== 
==50552== 
==50552== HEAP SUMMARY:
==50552==     in use at exit: 569,430 bytes in 210 blocks
==50552==   total heap usage: 6,103 allocs, 5,893 frees, 16,682,354 bytes allocated
==50552== 
==50552== 85 bytes in 4 blocks are still reachable in loss record 1 of 65
==50552==    at 0x4842788: malloc (vg_replace_malloc.c:446)
==50552==    by 0x402587F: malloc (rtld-malloc.h:56)
==50552==    by 0x402587F: strdup (strdup.c:42)
==50552==    by 0x4014B49: _dl_load_cache_lookup (dl-cache.c:515)
==50552==    by 0x4008EFF: _dl_map_object (dl-load.c:2116)
==50552==    by 0x400287C: openaux (dl-deps.c:64)
==50552==    by 0x4001522: _dl_catch_exception (dl-catch.c:237)
==50552==    by 0x4002D04: _dl_map_object_deps (dl-deps.c:232)
==50552==    by 0x400CA04: dl_open_worker_begin (dl-open.c:638)
==50552==    by 0x4001522: _dl_catch_exception (dl-catch.c:237)
==50552==    by 0x400C0DF: dl_open_worker (dl-open.c:803)
==50552==    by 0x4001522: _dl_catch_exception (dl-catch.c:237)
==50552==    by 0x400C533: _dl_open (dl-open.c:905)
==50552== 
==50552== 85 bytes in 4 blocks are still reachable in loss record 2 of 65
==50552==    at 0x4842788: malloc (vg_replace_malloc.c:446)
==50552==    by 0x400BE60: malloc (rtld-malloc.h:56)
==50552==    by 0x400BE60: _dl_new_object (dl-object.c:199)
==50552==    by 0x4007269: _dl_map_object_from_fd (dl-load.c:1053)
==50552==    by 0x4008C97: _dl_map_object (dl-load.c:2249)
==50552==    by 0x400287C: openaux (dl-deps.c:64)
==50552==    by 0x4001522: _dl_catch_exception (dl-catch.c:237)
==50552==    by 0x4002D04: _dl_map_object_deps (dl-deps.c:232)
==50552==    by 0x400CA04: dl_open_worker_begin (dl-open.c:638)
==50552==    by 0x4001522: _dl_catch_exception (dl-catch.c:237)
==50552==    by 0x400C0DF: dl_open_worker (dl-open.c:803)
==50552==    by 0x4001522: _dl_catch_exception (dl-catch.c:237)
==50552==    by 0x400C533: _dl_open (dl-open.c:905)
==50552== 
==50552== 560 bytes in 1 blocks are still reachable in loss record 3 of 65
==50552==    at 0x4842788: malloc (vg_replace_malloc.c:446)
==50552==    by 0x4917F1C: UnknownInlinedFun (obmalloc.c:586)
==50552==    by 0x4917F1C: UnknownInlinedFun (obmalloc.c:2003)
==50552==    by 0x4917F1C: _PyObject_Malloc (obmalloc.c:1996)
==50552==    by 0x497CFF6: UnknownInlinedFun (obmalloc.c:712)
==50552==    by 0x497CFF6: _PyObject_NewVar (object.c:189)
==50552==    by 0x4A4DC1D: _PyCode_New (codeobject.c:481)
==50552==    by 0x4A837CA: r_object (marshal.c:1463)
==50552==    by 0x4A84081: r_object (marshal.c:1228)
==50552==    by 0x4A8346E: r_object (marshal.c:1403)
==50552==    by 0x4A84E1A: read_object (marshal.c:1535)
==50552==    by 0x4A851BC: UnknownInlinedFun (marshal.c:1842)
==50552==    by 0x4A851BC: marshal_loads (marshal.c.h:148)
==50552==    by 0x4952E11: cfunction_vectorcall_O (methodobject.c:514)
==50552==    by 0x4943727: UnknownInlinedFun (pycore_call.h:92)
==50552==    by 0x4943727: PyObject_Vectorcall (call.c:299)
==50552==    by 0x4AE6016: _PyEval_EvalFrameDefault (ceval.c:4769)
==50552== 
==50552== 568 bytes in 1 blocks are still reachable in loss record 4 of 65
==50552==    at 0x4842788: malloc (vg_replace_malloc.c:446)
==50552==    by 0x4917F1C: UnknownInlinedFun (obmalloc.c:586)
==50552==    by 0x4917F1C: UnknownInlinedFun (obmalloc.c:2003)
==50552==    by 0x4917F1C: _PyObject_Malloc (obmalloc.c:1996)
==50552==    by 0x49A7496: UnknownInlinedFun (obmalloc.c:712)
==50552==    by 0x49A7496: new_keys_object (dictobject.c:632)
==50552==    by 0x49A7820: dictresize (dictobject.c:1429)
==50552==    by 0x49A7FEA: UnknownInlinedFun (dictobject.c:1183)
==50552==    by 0x49A7FEA: insertdict (dictobject.c:1248)
==50552==    by 0x49DB52D: UnknownInlinedFun (dictobject.c:1906)
==50552==    by 0x49DB52D: add_subclass (typeobject.c:6546)
==50552==    by 0x4928B8A: UnknownInlinedFun (typeobject.c:6346)
==50552==    by 0x4928B8A: type_ready (typeobject.c:6477)
==50552==    by 0x492C56D: PyType_Ready (typeobject.c:6507)
==50552==    by 0x4AFD1CC: UnknownInlinedFun (exceptions.c:3601)
==50552==    by 0x4AFD1CC: UnknownInlinedFun (pylifecycle.c:734)
==50552==    by 0x4AFD1CC: pycore_interp_init (pylifecycle.c:845)
==50552==    by 0x4AFF44C: UnknownInlinedFun (pylifecycle.c:901)
==50552==    by 0x4AFF44C: pyinit_core.constprop.0 (pylifecycle.c:1064)
==50552==    by 0x4B11454: Py_InitializeFromConfig.part.0 (pylifecycle.c:1254)
==50552==    by 0x4B118B8: UnknownInlinedFun (pylifecycle.c:1239)
==50552==    by 0x4B118B8: pymain_init (main.c:67)
==50552== 
==50552== 568 bytes in 1 blocks are still reachable in loss record 5 of 65
==50552==    at 0x4842788: malloc (vg_replace_malloc.c:446)
==50552==    by 0x4917F1C: UnknownInlinedFun (obmalloc.c:586)
==50552==    by 0x4917F1C: UnknownInlinedFun (obmalloc.c:2003)
==50552==    by 0x4917F1C: _PyObject_Malloc (obmalloc.c:1996)
==50552==    by 0x49A7496: UnknownInlinedFun (obmalloc.c:712)
==50552==    by 0x49A7496: new_keys_object (dictobject.c:632)
==50552==    by 0x49A7820: dictresize (dictobject.c:1429)
==50552==    by 0x49A7FEA: UnknownInlinedFun (dictobject.c:1183)
==50552==    by 0x49A7FEA: insertdict (dictobject.c:1248)
==50552==    by 0x49DB52D: UnknownInlinedFun (dictobject.c:1906)
==50552==    by 0x49DB52D: add_subclass (typeobject.c:6546)
==50552==    by 0x4928B8A: UnknownInlinedFun (typeobject.c:6346)
==50552==    by 0x4928B8A: type_ready (typeobject.c:6477)
==50552==    by 0x492C56D: PyType_Ready (typeobject.c:6507)
==50552==    by 0x4AF883E: UnknownInlinedFun (typeobject.c:3189)
==50552==    by 0x4AF883E: type_new (typeobject.c:3323)
==50552==    by 0x63A0F79: PyCFuncPtrType_new (_ctypes.c:2567)
==50552==    by 0x494F8FD: type_call (typeobject.c:1091)
==50552==    by 0x49433BC: _PyObject_MakeTpCall (call.c:214)
==50552== 
==50552== 568 bytes in 1 blocks are still reachable in loss record 6 of 65
==50552==    at 0x4842788: malloc (vg_replace_malloc.c:446)
==50552==    by 0x4917F1C: UnknownInlinedFun (obmalloc.c:586)
==50552==    by 0x4917F1C: UnknownInlinedFun (obmalloc.c:2003)
==50552==    by 0x4917F1C: _PyObject_Malloc (obmalloc.c:1996)
==50552==    by 0x49A7496: UnknownInlinedFun (obmalloc.c:712)
==50552==    by 0x49A7496: new_keys_object (dictobject.c:632)
==50552==    by 0x49A7820: dictresize (dictobject.c:1429)
==50552==    by 0x49A7FEA: UnknownInlinedFun (dictobject.c:1183)
==50552==    by 0x49A7FEA: insertdict (dictobject.c:1248)
==50552==    by 0x49D95EE: bounded_lru_cache_wrapper (_functoolsmodule.c:1068)
==50552==    by 0x49D8713: _PyObject_Call (call.c:343)
==50552==    by 0x4AE8B1A: _PyEval_EvalFrameDefault (ceval.c:5376)
==50552==    by 0x4AEE2A5: UnknownInlinedFun (pycore_ceval.h:73)
==50552==    by 0x4AEE2A5: _PyEval_Vector (ceval.c:6434)
==50552==    by 0x49D6E8D: UnknownInlinedFun (pycore_call.h:92)
==50552==    by 0x49D6E8D: UnknownInlinedFun (typeobject.c:1641)
==50552==    by 0x49D6E8D: vectorcall_method (typeobject.c:1672)
==50552==    by 0x49D72AE: slot_mp_subscript (typeobject.c:7396)
==50552==    by 0x4AE92B2: _PyEval_EvalFrameDefault (ceval.c:2131)
==50552== 
==50552== 744 bytes in 1 blocks are still reachable in loss record 7 of 65
==50552==    at 0x4842788: malloc (vg_replace_malloc.c:446)
==50552==    by 0x4917F1C: UnknownInlinedFun (obmalloc.c:586)
==50552==    by 0x4917F1C: UnknownInlinedFun (obmalloc.c:2003)
==50552==    by 0x4917F1C: _PyObject_Malloc (obmalloc.c:1996)
==50552==    by 0x497CFF6: UnknownInlinedFun (obmalloc.c:712)
==50552==    by 0x497CFF6: _PyObject_NewVar (object.c:189)
==50552==    by 0x4A4DC1D: _PyCode_New (codeobject.c:481)
==50552==    by 0x4A837CA: r_object (marshal.c:1463)
==50552==    by 0x4A84081: r_object (marshal.c:1228)
==50552==    by 0x4A8346E: r_object (marshal.c:1403)
==50552==    by 0x4A84081: r_object (marshal.c:1228)
==50552==    by 0x4A8346E: r_object (marshal.c:1403)
==50552==    by 0x4A84E1A: read_object (marshal.c:1535)
==50552==    by 0x4A851BC: UnknownInlinedFun (marshal.c:1842)
==50552==    by 0x4A851BC: marshal_loads (marshal.c.h:148)
==50552==    by 0x4AE83DA: _PyEval_EvalFrameDefault (ceval.c:5020)
==50552== 
==50552== 768 bytes in 1 blocks are still reachable in loss record 8 of 65
==50552==    at 0x4849E20: realloc (vg_replace_malloc.c:1800)
==50552==    by 0x4917CCE: UnknownInlinedFun (obmalloc.c:604)
==50552==    by 0x4917CCE: UnknownInlinedFun (obmalloc.c:1610)
==50552==    by 0x4917CCE: allocate_from_new_pool (obmalloc.c:1824)
==50552==    by 0x4917F34: UnknownInlinedFun (obmalloc.c:1988)
==50552==    by 0x4917F34: _PyObject_Malloc (obmalloc.c:1998)
==50552==    by 0x49736AE: UnknownInlinedFun (obmalloc.c:712)
==50552==    by 0x49736AE: gc_alloc (gcmodule.c:2283)
==50552==    by 0x4973765: _PyObject_GC_New (gcmodule.c:2298)
==50552==    by 0x49A6074: PyList_New (listobject.c:179)
==50552==    by 0x4AFBED2: UnknownInlinedFun (gcmodule.c:164)
==50552==    by 0x4AFBED2: pycore_interp_init (pylifecycle.c:835)
==50552==    by 0x4AFF44C: UnknownInlinedFun (pylifecycle.c:901)
==50552==    by 0x4AFF44C: pyinit_core.constprop.0 (pylifecycle.c:1064)
==50552==    by 0x4B11454: Py_InitializeFromConfig.part.0 (pylifecycle.c:1254)
==50552==    by 0x4B118B8: UnknownInlinedFun (pylifecycle.c:1239)
==50552==    by 0x4B118B8: pymain_init (main.c:67)
==50552==    by 0x4B13D72: UnknownInlinedFun (main.c:701)
==50552==    by 0x4B13D72: Py_BytesMain (main.c:734)
==50552==    by 0x4DE0C87: ??? (in /usr/lib/libc.so.6)
==50552== 
==50552== 768 bytes in 1 blocks are still reachable in loss record 9 of 65
==50552==    at 0x4842788: malloc (vg_replace_malloc.c:446)
==50552==    by 0x4917F1C: UnknownInlinedFun (obmalloc.c:586)
==50552==    by 0x4917F1C: UnknownInlinedFun (obmalloc.c:2003)
==50552==    by 0x4917F1C: _PyObject_Malloc (obmalloc.c:1996)
==50552==    by 0x49A7496: UnknownInlinedFun (obmalloc.c:712)
==50552==    by 0x49A7496: new_keys_object (dictobject.c:632)
==50552==    by 0x49A7820: dictresize (dictobject.c:1429)
==50552==    by 0x49A7FEA: UnknownInlinedFun (dictobject.c:1183)
==50552==    by 0x49A7FEA: insertdict (dictobject.c:1248)
==50552==    by 0x492846C: UnknownInlinedFun (dictobject.c:1906)
==50552==    by 0x492846C: UnknownInlinedFun (typeobject.c:6167)
==50552==    by 0x492846C: UnknownInlinedFun (typeobject.c:6198)
==50552==    by 0x492846C: type_ready (typeobject.c:6468)
==50552==    by 0x492C56D: PyType_Ready (typeobject.c:6507)
==50552==    by 0x4AFCBCC: UnknownInlinedFun (object.c:1986)
==50552==    by 0x4AFCBCC: UnknownInlinedFun (pylifecycle.c:704)
==50552==    by 0x4AFCBCC: pycore_interp_init (pylifecycle.c:845)
==50552==    by 0x4AFF44C: UnknownInlinedFun (pylifecycle.c:901)
==50552==    by 0x4AFF44C: pyinit_core.constprop.0 (pylifecycle.c:1064)
==50552==    by 0x4B11454: Py_InitializeFromConfig.part.0 (pylifecycle.c:1254)
==50552==    by 0x4B118B8: UnknownInlinedFun (pylifecycle.c:1239)
==50552==    by 0x4B118B8: pymain_init (main.c:67)
==50552==    by 0x4B13D72: UnknownInlinedFun (main.c:701)
==50552==    by 0x4B13D72: Py_BytesMain (main.c:734)
==50552== 
==50552== 768 bytes in 1 blocks are still reachable in loss record 10 of 65
==50552==    at 0x4842788: malloc (vg_replace_malloc.c:446)
==50552==    by 0x4917F1C: UnknownInlinedFun (obmalloc.c:586)
==50552==    by 0x4917F1C: UnknownInlinedFun (obmalloc.c:2003)
==50552==    by 0x4917F1C: _PyObject_Malloc (obmalloc.c:1996)
==50552==    by 0x49A7496: UnknownInlinedFun (obmalloc.c:712)
==50552==    by 0x49A7496: new_keys_object (dictobject.c:632)
==50552==    by 0x492B7D2: UnknownInlinedFun (dictobject.c:5333)
==50552==    by 0x492B7D2: UnknownInlinedFun (typeobject.c:6412)
==50552==    by 0x492B7D2: type_ready (typeobject.c:6480)
==50552==    by 0x492C56D: PyType_Ready (typeobject.c:6507)
==50552==    by 0x4AF883E: UnknownInlinedFun (typeobject.c:3189)
==50552==    by 0x4AF883E: type_new (typeobject.c:3323)
==50552==    by 0x494F8FD: type_call (typeobject.c:1091)
==50552==    by 0x49433BC: _PyObject_MakeTpCall (call.c:214)
==50552==    by 0x4AF3815: UnknownInlinedFun (call.c:165)
==50552==    by 0x4AF3815: builtin___build_class__ (bltinmodule.c:209)
==50552==    by 0x494F28C: cfunction_vectorcall_FASTCALL_KEYWORDS (methodobject.c:443)
==50552==    by 0x4943727: UnknownInlinedFun (pycore_call.h:92)
==50552==    by 0x4943727: PyObject_Vectorcall (call.c:299)
==50552==    by 0x4AE6016: _PyEval_EvalFrameDefault (ceval.c:4769)
==50552== 
==50552== 768 bytes in 1 blocks are still reachable in loss record 11 of 65
==50552==    at 0x4842788: malloc (vg_replace_malloc.c:446)
==50552==    by 0x4917F1C: UnknownInlinedFun (obmalloc.c:586)
==50552==    by 0x4917F1C: UnknownInlinedFun (obmalloc.c:2003)
==50552==    by 0x4917F1C: _PyObject_Malloc (obmalloc.c:1996)
==50552==    by 0x49A7496: UnknownInlinedFun (obmalloc.c:712)
==50552==    by 0x49A7496: new_keys_object (dictobject.c:632)
==50552==    by 0x49A7820: dictresize (dictobject.c:1429)
==50552==    by 0x49DE22F: UnknownInlinedFun (dictobject.c:1183)
==50552==    by 0x49DE22F: PyDict_SetDefault (dictobject.c:3338)
==50552==    by 0x49280CE: UnknownInlinedFun (typeobject.c:5687)
==50552==    by 0x49280CE: UnknownInlinedFun (typeobject.c:5713)
==50552==    by 0x49280CE: UnknownInlinedFun (typeobject.c:6189)
==50552==    by 0x49280CE: type_ready (typeobject.c:6468)
==50552==    by 0x492C56D: PyType_Ready (typeobject.c:6507)
==50552==    by 0x4949A97: best_base (typeobject.c:2185)
==50552==    by 0x4AF800E: UnknownInlinedFun (typeobject.c:3269)
==50552==    by 0x4AF800E: type_new (typeobject.c:3311)
==50552==    by 0x494F8FD: type_call (typeobject.c:1091)
==50552==    by 0x49433BC: _PyObject_MakeTpCall (call.c:214)
==50552==    by 0x49D9799: _PyObject_FastCallDictTstate (call.c:141)
==50552== 
==50552== 768 bytes in 1 blocks are still reachable in loss record 12 of 65
==50552==    at 0x4842788: malloc (vg_replace_malloc.c:446)
==50552==    by 0x4917F1C: UnknownInlinedFun (obmalloc.c:586)
==50552==    by 0x4917F1C: UnknownInlinedFun (obmalloc.c:2003)
==50552==    by 0x4917F1C: _PyObject_Malloc (obmalloc.c:1996)
==50552==    by 0x49A7496: UnknownInlinedFun (obmalloc.c:712)
==50552==    by 0x49A7496: new_keys_object (dictobject.c:632)
==50552==    by 0x49A7820: dictresize (dictobject.c:1429)
==50552==    by 0x49DE22F: UnknownInlinedFun (dictobject.c:1183)
==50552==    by 0x49DE22F: PyDict_SetDefault (dictobject.c:3338)
==50552==    by 0x492837E: UnknownInlinedFun (typeobject.c:5760)
==50552==    by 0x492837E: UnknownInlinedFun (typeobject.c:6195)
==50552==    by 0x492837E: type_ready (typeobject.c:6468)
==50552==    by 0x492C56D: PyType_Ready (typeobject.c:6507)
==50552==    by 0x4A3DB0E: PyModule_AddType (modsupport.c:697)
==50552==    by 0x7005735: PyInit__asyncio (_asynciomodule.c:3491)
==50552==    by 0x4AFA4DE: UnknownInlinedFun (importdl.c:169)
==50552==    by 0x4AFA4DE: UnknownInlinedFun (import.c:2397)
==50552==    by 0x4AFA4DE: _imp_create_dynamic (import.c.h:446)
==50552==    by 0x4952F62: cfunction_vectorcall_FASTCALL (methodobject.c:427)
==50552==    by 0x4AE8B1A: _PyEval_EvalFrameDefault (ceval.c:5376)
==50552== 
==50552== 768 bytes in 1 blocks are still reachable in loss record 13 of 65
==50552==    at 0x4842788: malloc (vg_replace_malloc.c:446)
==50552==    by 0x4917F1C: UnknownInlinedFun (obmalloc.c:586)
==50552==    by 0x4917F1C: UnknownInlinedFun (obmalloc.c:2003)
==50552==    by 0x4917F1C: _PyObject_Malloc (obmalloc.c:1996)
==50552==    by 0x49A7496: UnknownInlinedFun (obmalloc.c:712)
==50552==    by 0x49A7496: new_keys_object (dictobject.c:632)
==50552==    by 0x49A7820: dictresize (dictobject.c:1429)
==50552==    by 0x49DE22F: UnknownInlinedFun (dictobject.c:1183)
==50552==    by 0x49DE22F: PyDict_SetDefault (dictobject.c:3338)
==50552==    by 0x49280CE: UnknownInlinedFun (typeobject.c:5687)
==50552==    by 0x49280CE: UnknownInlinedFun (typeobject.c:5713)
==50552==    by 0x49280CE: UnknownInlinedFun (typeobject.c:6189)
==50552==    by 0x49280CE: type_ready (typeobject.c:6468)
==50552==    by 0x492C56D: PyType_Ready (typeobject.c:6507)
==50552==    by 0x4A3DB0E: PyModule_AddType (modsupport.c:697)
==50552==    by 0x700574D: PyInit__asyncio (_asynciomodule.c:3496)
==50552==    by 0x4AFA4DE: UnknownInlinedFun (importdl.c:169)
==50552==    by 0x4AFA4DE: UnknownInlinedFun (import.c:2397)
==50552==    by 0x4AFA4DE: _imp_create_dynamic (import.c.h:446)
==50552==    by 0x4952F62: cfunction_vectorcall_FASTCALL (methodobject.c:427)
==50552==    by 0x4AE8B1A: _PyEval_EvalFrameDefault (ceval.c:5376)
==50552== 
==50552== 960 bytes in 1 blocks are still reachable in loss record 14 of 65
==50552==    at 0x4842788: malloc (vg_replace_malloc.c:446)
==50552==    by 0x4917F1C: UnknownInlinedFun (obmalloc.c:586)
==50552==    by 0x4917F1C: UnknownInlinedFun (obmalloc.c:2003)
==50552==    by 0x4917F1C: _PyObject_Malloc (obmalloc.c:1996)
==50552==    by 0x4927BA8: UnknownInlinedFun (obmalloc.c:712)
==50552==    by 0x4927BA8: _PyType_AllocNoTrack (typeobject.c:1124)
==50552==    by 0x4927C94: PyType_GenericAlloc (typeobject.c:1148)
==50552==    by 0x4AC241D: PyType_FromModuleAndSpec (typeobject.c:3408)
==50552==    by 0x4AC2B26: _abcmodule_exec (_abc.c:920)
==50552==    by 0x4A3F7F9: PyModule_ExecDef (moduleobject.c:419)
==50552==    by 0x4A3FA9F: UnknownInlinedFun (import.c:2438)
==50552==    by 0x4A3FA9F: _imp_exec_builtin (import.c.h:504)
==50552==    by 0x4952E11: cfunction_vectorcall_O (methodobject.c:514)
==50552==    by 0x4AE8B1A: _PyEval_EvalFrameDefault (ceval.c:5376)
==50552==    by 0x4AEE2A5: UnknownInlinedFun (pycore_ceval.h:73)
==50552==    by 0x4AEE2A5: _PyEval_Vector (ceval.c:6434)
==50552==    by 0x49C2545: UnknownInlinedFun (pycore_call.h:92)
==50552==    by 0x49C2545: object_vacall (call.c:819)
==50552== 
==50552== 960 bytes in 1 blocks are still reachable in loss record 15 of 65
==50552==    at 0x4842788: malloc (vg_replace_malloc.c:446)
==50552==    by 0x4917F1C: UnknownInlinedFun (obmalloc.c:586)
==50552==    by 0x4917F1C: UnknownInlinedFun (obmalloc.c:2003)
==50552==    by 0x4917F1C: _PyObject_Malloc (obmalloc.c:1996)
==50552==    by 0x4927BA8: UnknownInlinedFun (obmalloc.c:712)
==50552==    by 0x4927BA8: _PyType_AllocNoTrack (typeobject.c:1124)
==50552==    by 0x4927C94: PyType_GenericAlloc (typeobject.c:1148)
==50552==    by 0x4AF8632: UnknownInlinedFun (typeobject.c:2744)
==50552==    by 0x4AF8632: UnknownInlinedFun (typeobject.c:3156)
==50552==    by 0x4AF8632: UnknownInlinedFun (typeobject.c:3179)
==50552==    by 0x4AF8632: type_new (typeobject.c:3323)
==50552==    by 0x498C43C: tp_new_wrapper (typeobject.c:7160)
==50552==    by 0x49D8662: cfunction_call (methodobject.c:542)
==50552==    by 0x49D8713: _PyObject_Call (call.c:343)
==50552==    by 0x4AE8B1A: _PyEval_EvalFrameDefault (ceval.c:5376)
==50552==    by 0x4AEE2A5: UnknownInlinedFun (pycore_ceval.h:73)
==50552==    by 0x4AEE2A5: _PyEval_Vector (ceval.c:6434)
==50552==    by 0x49D9799: _PyObject_FastCallDictTstate (call.c:141)
==50552==    by 0x49D998F: _PyObject_Call_Prepend (call.c:482)
==50552== 
==50552== 960 bytes in 1 blocks are still reachable in loss record 16 of 65
==50552==    at 0x4842788: malloc (vg_replace_malloc.c:446)
==50552==    by 0x4917F1C: UnknownInlinedFun (obmalloc.c:586)
==50552==    by 0x4917F1C: UnknownInlinedFun (obmalloc.c:2003)
==50552==    by 0x4917F1C: _PyObject_Malloc (obmalloc.c:1996)
==50552==    by 0x4927BA8: UnknownInlinedFun (obmalloc.c:712)
==50552==    by 0x4927BA8: _PyType_AllocNoTrack (typeobject.c:1124)
==50552==    by 0x4927C94: PyType_GenericAlloc (typeobject.c:1148)
==50552==    by 0x4AC241D: PyType_FromModuleAndSpec (typeobject.c:3408)
==50552==    by 0x4AF6AEB: _functools_exec (_functoolsmodule.c:1477)
==50552==    by 0x4A3F7F9: PyModule_ExecDef (moduleobject.c:419)
==50552==    by 0x4A3FA9F: UnknownInlinedFun (import.c:2438)
==50552==    by 0x4A3FA9F: _imp_exec_builtin (import.c.h:504)
==50552==    by 0x4952E11: cfunction_vectorcall_O (methodobject.c:514)
==50552==    by 0x4AE8B1A: _PyEval_EvalFrameDefault (ceval.c:5376)
==50552==    by 0x4AEE2A5: UnknownInlinedFun (pycore_ceval.h:73)
==50552==    by 0x4AEE2A5: _PyEval_Vector (ceval.c:6434)
==50552==    by 0x49C2545: UnknownInlinedFun (pycore_call.h:92)
==50552==    by 0x49C2545: object_vacall (call.c:819)
==50552== 
==50552== 960 bytes in 1 blocks are still reachable in loss record 17 of 65
==50552==    at 0x4842788: malloc (vg_replace_malloc.c:446)
==50552==    by 0x4917F1C: UnknownInlinedFun (obmalloc.c:586)
==50552==    by 0x4917F1C: UnknownInlinedFun (obmalloc.c:2003)
==50552==    by 0x4917F1C: _PyObject_Malloc (obmalloc.c:1996)
==50552==    by 0x4927BA8: UnknownInlinedFun (obmalloc.c:712)
==50552==    by 0x4927BA8: _PyType_AllocNoTrack (typeobject.c:1124)
==50552==    by 0x4927C94: PyType_GenericAlloc (typeobject.c:1148)
==50552==    by 0x4AF8632: UnknownInlinedFun (typeobject.c:2744)
==50552==    by 0x4AF8632: UnknownInlinedFun (typeobject.c:3156)
==50552==    by 0x4AF8632: UnknownInlinedFun (typeobject.c:3179)
==50552==    by 0x4AF8632: type_new (typeobject.c:3323)
==50552==    by 0x494F8FD: type_call (typeobject.c:1091)
==50552==    by 0x49433BC: _PyObject_MakeTpCall (call.c:214)
==50552==    by 0x4AE74B3: _PyEval_EvalFrameDefault (ceval.c:4984)
==50552==    by 0x4AEE2A5: UnknownInlinedFun (pycore_ceval.h:73)
==50552==    by 0x4AEE2A5: _PyEval_Vector (ceval.c:6434)
==50552==    by 0x4AEE359: PyEval_EvalCode (ceval.c:1148)
==50552==    by 0x4AF30AA: UnknownInlinedFun (bltinmodule.c:1077)
==50552==    by 0x4AF30AA: builtin_exec (bltinmodule.c.h:465)
==50552==    by 0x494F28C: cfunction_vectorcall_FASTCALL_KEYWORDS (methodobject.c:443)
==50552== 
==50552== 960 bytes in 1 blocks are still reachable in loss record 18 of 65
==50552==    at 0x4842788: malloc (vg_replace_malloc.c:446)
==50552==    by 0x4917F1C: UnknownInlinedFun (obmalloc.c:586)
==50552==    by 0x4917F1C: UnknownInlinedFun (obmalloc.c:2003)
==50552==    by 0x4917F1C: _PyObject_Malloc (obmalloc.c:1996)
==50552==    by 0x4927BA8: UnknownInlinedFun (obmalloc.c:712)
==50552==    by 0x4927BA8: _PyType_AllocNoTrack (typeobject.c:1124)
==50552==    by 0x4927C94: PyType_GenericAlloc (typeobject.c:1148)
==50552==    by 0x4AF80AA: UnknownInlinedFun (typeobject.c:2744)
==50552==    by 0x4AF80AA: UnknownInlinedFun (typeobject.c:3156)
==50552==    by 0x4AF80AA: UnknownInlinedFun (typeobject.c:3179)
==50552==    by 0x4AF80AA: type_new (typeobject.c:3323)
==50552==    by 0x494F8FD: type_call (typeobject.c:1091)
==50552==    by 0x49433BC: _PyObject_MakeTpCall (call.c:214)
==50552==    by 0x4AF3815: UnknownInlinedFun (call.c:165)
==50552==    by 0x4AF3815: builtin___build_class__ (bltinmodule.c:209)
==50552==    by 0x494F28C: cfunction_vectorcall_FASTCALL_KEYWORDS (methodobject.c:443)
==50552==    by 0x4943727: UnknownInlinedFun (pycore_call.h:92)
==50552==    by 0x4943727: PyObject_Vectorcall (call.c:299)
==50552==    by 0x4AE6016: _PyEval_EvalFrameDefault (ceval.c:4769)
==50552==    by 0x4AEE2A5: UnknownInlinedFun (pycore_ceval.h:73)
==50552==    by 0x4AEE2A5: _PyEval_Vector (ceval.c:6434)
==50552== 
==50552== 960 bytes in 1 blocks are still reachable in loss record 19 of 65
==50552==    at 0x4842788: malloc (vg_replace_malloc.c:446)
==50552==    by 0x4917F1C: UnknownInlinedFun (obmalloc.c:586)
==50552==    by 0x4917F1C: UnknownInlinedFun (obmalloc.c:2003)
==50552==    by 0x4917F1C: _PyObject_Malloc (obmalloc.c:1996)
==50552==    by 0x4927BA8: UnknownInlinedFun (obmalloc.c:712)
==50552==    by 0x4927BA8: _PyType_AllocNoTrack (typeobject.c:1124)
==50552==    by 0x4927C94: PyType_GenericAlloc (typeobject.c:1148)
==50552==    by 0x4AF80AA: UnknownInlinedFun (typeobject.c:2744)
==50552==    by 0x4AF80AA: UnknownInlinedFun (typeobject.c:3156)
==50552==    by 0x4AF80AA: UnknownInlinedFun (typeobject.c:3179)
==50552==    by 0x4AF80AA: type_new (typeobject.c:3323)
==50552==    by 0x494F8FD: type_call (typeobject.c:1091)
==50552==    by 0x49433BC: _PyObject_MakeTpCall (call.c:214)
==50552==    by 0x49369FB: UnknownInlinedFun (pycore_call.h:92)
==50552==    by 0x49369FB: _PyObject_CallFunctionVa (call.c:536)
==50552==    by 0x4936C91: PyObject_CallFunction (call.c:558)
==50552==    by 0x4AC16F4: PyErr_NewException (errors.c:1201)
==50552==    by 0x638A932: PyInit__socket (socketmodule.c:7268)
==50552==    by 0x4AFA4DE: UnknownInlinedFun (importdl.c:169)
==50552==    by 0x4AFA4DE: UnknownInlinedFun (import.c:2397)
==50552==    by 0x4AFA4DE: _imp_create_dynamic (import.c.h:446)
==50552== 
==50552== 960 bytes in 1 blocks are still reachable in loss record 20 of 65
==50552==    at 0x4842788: malloc (vg_replace_malloc.c:446)
==50552==    by 0x4917F1C: UnknownInlinedFun (obmalloc.c:586)
==50552==    by 0x4917F1C: UnknownInlinedFun (obmalloc.c:2003)
==50552==    by 0x4917F1C: _PyObject_Malloc (obmalloc.c:1996)
==50552==    by 0x4927BA8: UnknownInlinedFun (obmalloc.c:712)
==50552==    by 0x4927BA8: _PyType_AllocNoTrack (typeobject.c:1124)
==50552==    by 0x4927C94: PyType_GenericAlloc (typeobject.c:1148)
==50552==    by 0x4AF80AA: UnknownInlinedFun (typeobject.c:2744)
==50552==    by 0x4AF80AA: UnknownInlinedFun (typeobject.c:3156)
==50552==    by 0x4AF80AA: UnknownInlinedFun (typeobject.c:3179)
==50552==    by 0x4AF80AA: type_new (typeobject.c:3323)
==50552==    by 0x494F8FD: type_call (typeobject.c:1091)
==50552==    by 0x49433BC: _PyObject_MakeTpCall (call.c:214)
==50552==    by 0x49369FB: UnknownInlinedFun (pycore_call.h:92)
==50552==    by 0x49369FB: _PyObject_CallFunctionVa (call.c:536)
==50552==    by 0x4936C91: PyObject_CallFunction (call.c:558)
==50552==    by 0x4AC16F4: PyErr_NewException (errors.c:1201)
==50552==    by 0x638A96C: PyInit__socket (socketmodule.c:7274)
==50552==    by 0x4AFA4DE: UnknownInlinedFun (importdl.c:169)
==50552==    by 0x4AFA4DE: UnknownInlinedFun (import.c:2397)
==50552==    by 0x4AFA4DE: _imp_create_dynamic (import.c.h:446)
==50552== 
==50552== 960 bytes in 1 blocks are still reachable in loss record 21 of 65
==50552==    at 0x4842788: malloc (vg_replace_malloc.c:446)
==50552==    by 0x4917F1C: UnknownInlinedFun (obmalloc.c:586)
==50552==    by 0x4917F1C: UnknownInlinedFun (obmalloc.c:2003)
==50552==    by 0x4917F1C: _PyObject_Malloc (obmalloc.c:1996)
==50552==    by 0x4927BA8: UnknownInlinedFun (obmalloc.c:712)
==50552==    by 0x4927BA8: _PyType_AllocNoTrack (typeobject.c:1124)
==50552==    by 0x4927C94: PyType_GenericAlloc (typeobject.c:1148)
==50552==    by 0x4AF80AA: UnknownInlinedFun (typeobject.c:2744)
==50552==    by 0x4AF80AA: UnknownInlinedFun (typeobject.c:3156)
==50552==    by 0x4AF80AA: UnknownInlinedFun (typeobject.c:3179)
==50552==    by 0x4AF80AA: type_new (typeobject.c:3323)
==50552==    by 0x494F8FD: type_call (typeobject.c:1091)
==50552==    by 0x49433BC: _PyObject_MakeTpCall (call.c:214)
==50552==    by 0x49369FB: UnknownInlinedFun (pycore_call.h:92)
==50552==    by 0x49369FB: _PyObject_CallFunctionVa (call.c:536)
==50552==    by 0x4936C91: PyObject_CallFunction (call.c:558)
==50552==    by 0x4AC16F4: PyErr_NewException (errors.c:1201)
==50552==    by 0x63AA919: UnknownInlinedFun (_ctypes.c:5825)
==50552==    by 0x63AA919: PyInit__ctypes (_ctypes.c:5852)
==50552==    by 0x4AFA4DE: UnknownInlinedFun (importdl.c:169)
==50552==    by 0x4AFA4DE: UnknownInlinedFun (import.c:2397)
==50552==    by 0x4AFA4DE: _imp_create_dynamic (import.c.h:446)
==50552== 
==50552== 1,000 bytes in 1 blocks are still reachable in loss record 22 of 65
==50552==    at 0x4842788: malloc (vg_replace_malloc.c:446)
==50552==    by 0x4917F1C: UnknownInlinedFun (obmalloc.c:586)
==50552==    by 0x4917F1C: UnknownInlinedFun (obmalloc.c:2003)
==50552==    by 0x4917F1C: _PyObject_Malloc (obmalloc.c:1996)
==50552==    by 0x4927BA8: UnknownInlinedFun (obmalloc.c:712)
==50552==    by 0x4927BA8: _PyType_AllocNoTrack (typeobject.c:1124)
==50552==    by 0x4927C94: PyType_GenericAlloc (typeobject.c:1148)
==50552==    by 0x4AC241D: PyType_FromModuleAndSpec (typeobject.c:3408)
==50552==    by 0x4AF6AD1: _functools_exec (_functoolsmodule.c:1469)
==50552==    by 0x4A3F7F9: PyModule_ExecDef (moduleobject.c:419)
==50552==    by 0x4A3FA9F: UnknownInlinedFun (import.c:2438)
==50552==    by 0x4A3FA9F: _imp_exec_builtin (import.c.h:504)
==50552==    by 0x4952E11: cfunction_vectorcall_O (methodobject.c:514)
==50552==    by 0x4AE8B1A: _PyEval_EvalFrameDefault (ceval.c:5376)
==50552==    by 0x4AEE2A5: UnknownInlinedFun (pycore_ceval.h:73)
==50552==    by 0x4AEE2A5: _PyEval_Vector (ceval.c:6434)
==50552==    by 0x49C2545: UnknownInlinedFun (pycore_call.h:92)
==50552==    by 0x49C2545: object_vacall (call.c:819)
==50552== 
==50552== 1,036 bytes in 1 blocks are still reachable in loss record 23 of 65
==50552==    at 0x4842788: malloc (vg_replace_malloc.c:446)
==50552==    by 0x4917F1C: UnknownInlinedFun (obmalloc.c:586)
==50552==    by 0x4917F1C: UnknownInlinedFun (obmalloc.c:2003)
==50552==    by 0x4917F1C: _PyObject_Malloc (obmalloc.c:1996)
==50552==    by 0x49969DD: UnknownInlinedFun (obmalloc.c:712)
==50552==    by 0x49969DD: PyUnicode_New.part.0 (unicodeobject.c:1425)
==50552==    by 0x49997AC: UnknownInlinedFun (unicodeobject.c:1366)
==50552==    by 0x49997AC: UnknownInlinedFun (unicodeobject.c:2409)
==50552==    by 0x49997AC: _PyUnicode_FromUCS1 (unicodeobject.c:2395)
==50552==    by 0x4A83DCC: UnknownInlinedFun (unicodeobject.c:2480)
==50552==    by 0x4A83DCC: r_object (marshal.c:1163)
==50552==    by 0x4A84081: r_object (marshal.c:1228)
==50552==    by 0x4A8346E: r_object (marshal.c:1403)
==50552==    by 0x4A84081: r_object (marshal.c:1228)
==50552==    by 0x4A8346E: r_object (marshal.c:1403)
==50552==    by 0x4A84E1A: read_object (marshal.c:1535)
==50552==    by 0x4A851BC: UnknownInlinedFun (marshal.c:1842)
==50552==    by 0x4A851BC: marshal_loads (marshal.c.h:148)
==50552==    by 0x4952E11: cfunction_vectorcall_O (methodobject.c:514)
==50552== 
==50552== 1,040 bytes in 1 blocks are still reachable in loss record 24 of 65
==50552==    at 0x4842788: malloc (vg_replace_malloc.c:446)
==50552==    by 0x4917F1C: UnknownInlinedFun (obmalloc.c:586)
==50552==    by 0x4917F1C: UnknownInlinedFun (obmalloc.c:2003)
==50552==    by 0x4917F1C: _PyObject_Malloc (obmalloc.c:1996)
==50552==    by 0x4927BA8: UnknownInlinedFun (obmalloc.c:712)
==50552==    by 0x4927BA8: _PyType_AllocNoTrack (typeobject.c:1124)
==50552==    by 0x4927C94: PyType_GenericAlloc (typeobject.c:1148)
==50552==    by 0x4AC241D: PyType_FromModuleAndSpec (typeobject.c:3408)
==50552==    by 0x4AF6A5C: _functools_exec (_functoolsmodule.c:1458)
==50552==    by 0x4A3F7F9: PyModule_ExecDef (moduleobject.c:419)
==50552==    by 0x4A3FA9F: UnknownInlinedFun (import.c:2438)
==50552==    by 0x4A3FA9F: _imp_exec_builtin (import.c.h:504)
==50552==    by 0x4952E11: cfunction_vectorcall_O (methodobject.c:514)
==50552==    by 0x4AE8B1A: _PyEval_EvalFrameDefault (ceval.c:5376)
==50552==    by 0x4AEE2A5: UnknownInlinedFun (pycore_ceval.h:73)
==50552==    by 0x4AEE2A5: _PyEval_Vector (ceval.c:6434)
==50552==    by 0x49C2545: UnknownInlinedFun (pycore_call.h:92)
==50552==    by 0x49C2545: object_vacall (call.c:819)
==50552== 
==50552== 1,080 bytes in 1 blocks are still reachable in loss record 25 of 65
==50552==    at 0x4842788: malloc (vg_replace_malloc.c:446)
==50552==    by 0x4917F1C: UnknownInlinedFun (obmalloc.c:586)
==50552==    by 0x4917F1C: UnknownInlinedFun (obmalloc.c:2003)
==50552==    by 0x4917F1C: _PyObject_Malloc (obmalloc.c:1996)
==50552==    by 0x4927BA8: UnknownInlinedFun (obmalloc.c:712)
==50552==    by 0x4927BA8: _PyType_AllocNoTrack (typeobject.c:1124)
==50552==    by 0x4927C94: PyType_GenericAlloc (typeobject.c:1148)
==50552==    by 0x4AF8632: UnknownInlinedFun (typeobject.c:2744)
==50552==    by 0x4AF8632: UnknownInlinedFun (typeobject.c:3156)
==50552==    by 0x4AF8632: UnknownInlinedFun (typeobject.c:3179)
==50552==    by 0x4AF8632: type_new (typeobject.c:3323)
==50552==    by 0x494F8FD: type_call (typeobject.c:1091)
==50552==    by 0x49433BC: _PyObject_MakeTpCall (call.c:214)
==50552==    by 0x49D9835: _PyObject_FastCallDictTstate (call.c:152)
==50552==    by 0x4AF3815: UnknownInlinedFun (call.c:165)
==50552==    by 0x4AF3815: builtin___build_class__ (bltinmodule.c:209)
==50552==    by 0x494F28C: cfunction_vectorcall_FASTCALL_KEYWORDS (methodobject.c:443)
==50552==    by 0x4943727: UnknownInlinedFun (pycore_call.h:92)
==50552==    by 0x4943727: PyObject_Vectorcall (call.c:299)
==50552==    by 0x4AE6016: _PyEval_EvalFrameDefault (ceval.c:4769)
==50552== 
==50552== 1,104 bytes in 1 blocks are still reachable in loss record 26 of 65
==50552==    at 0x4842788: malloc (vg_replace_malloc.c:446)
==50552==    by 0x4917F1C: UnknownInlinedFun (obmalloc.c:586)
==50552==    by 0x4917F1C: UnknownInlinedFun (obmalloc.c:2003)
==50552==    by 0x4917F1C: _PyObject_Malloc (obmalloc.c:1996)
==50552==    by 0x49A7496: UnknownInlinedFun (obmalloc.c:712)
==50552==    by 0x49A7496: new_keys_object (dictobject.c:632)
==50552==    by 0x49A7820: dictresize (dictobject.c:1429)
==50552==    by 0x49A7FEA: UnknownInlinedFun (dictobject.c:1183)
==50552==    by 0x49A7FEA: insertdict (dictobject.c:1248)
==50552==    by 0x49DB52D: UnknownInlinedFun (dictobject.c:1906)
==50552==    by 0x49DB52D: add_subclass (typeobject.c:6546)
==50552==    by 0x4928B8A: UnknownInlinedFun (typeobject.c:6346)
==50552==    by 0x4928B8A: type_ready (typeobject.c:6477)
==50552==    by 0x492C56D: PyType_Ready (typeobject.c:6507)
==50552==    by 0x4AF883E: UnknownInlinedFun (typeobject.c:3189)
==50552==    by 0x4AF883E: type_new (typeobject.c:3323)
==50552==    by 0x494F8FD: type_call (typeobject.c:1091)
==50552==    by 0x49433BC: _PyObject_MakeTpCall (call.c:214)
==50552==    by 0x4AE74B3: _PyEval_EvalFrameDefault (ceval.c:4984)
==50552== 
==50552== 1,104 bytes in 1 blocks are still reachable in loss record 27 of 65
==50552==    at 0x4842788: malloc (vg_replace_malloc.c:446)
==50552==    by 0x4917F1C: UnknownInlinedFun (obmalloc.c:586)
==50552==    by 0x4917F1C: UnknownInlinedFun (obmalloc.c:2003)
==50552==    by 0x4917F1C: _PyObject_Malloc (obmalloc.c:1996)
==50552==    by 0x49A7496: UnknownInlinedFun (obmalloc.c:712)
==50552==    by 0x49A7496: new_keys_object (dictobject.c:632)
==50552==    by 0x49A7820: dictresize (dictobject.c:1429)
==50552==    by 0x49A7FEA: UnknownInlinedFun (dictobject.c:1183)
==50552==    by 0x49A7FEA: insertdict (dictobject.c:1248)
==50552==    by 0x49DB52D: UnknownInlinedFun (dictobject.c:1906)
==50552==    by 0x49DB52D: add_subclass (typeobject.c:6546)
==50552==    by 0x4928B8A: UnknownInlinedFun (typeobject.c:6346)
==50552==    by 0x4928B8A: type_ready (typeobject.c:6477)
==50552==    by 0x492C56D: PyType_Ready (typeobject.c:6507)
==50552==    by 0x4AF883E: UnknownInlinedFun (typeobject.c:3189)
==50552==    by 0x4AF883E: type_new (typeobject.c:3323)
==50552==    by 0x63A741A: PyCSimpleType_new (_ctypes.c:2055)
==50552==    by 0x494F8FD: type_call (typeobject.c:1091)
==50552==    by 0x49433BC: _PyObject_MakeTpCall (call.c:214)
==50552== 
==50552== 1,196 bytes in 16 blocks are still reachable in loss record 28 of 65
==50552==    at 0x4842788: malloc (vg_replace_malloc.c:446)
==50552==    by 0x402587F: malloc (rtld-malloc.h:56)
==50552==    by 0x402587F: strdup (strdup.c:42)
==50552==    by 0x4008BEC: _dl_map_object (dl-load.c:2182)
==50552==    by 0x400C99B: dl_open_worker_begin (dl-open.c:578)
==50552==    by 0x4001522: _dl_catch_exception (dl-catch.c:237)
==50552==    by 0x400C0DF: dl_open_worker (dl-open.c:803)
==50552==    by 0x4001522: _dl_catch_exception (dl-catch.c:237)
==50552==    by 0x400C533: _dl_open (dl-open.c:905)
==50552==    by 0x4E499E3: ??? (in /usr/lib/libc.so.6)
==50552==    by 0x4001522: _dl_catch_exception (dl-catch.c:237)
==50552==    by 0x4001678: _dl_catch_error (dl-catch.c:256)
==50552==    by 0x4E494C2: ??? (in /usr/lib/libc.so.6)
==50552== 
==50552== 1,196 bytes in 16 blocks are still reachable in loss record 29 of 65
==50552==    at 0x4842788: malloc (vg_replace_malloc.c:446)
==50552==    by 0x400BE60: malloc (rtld-malloc.h:56)
==50552==    by 0x400BE60: _dl_new_object (dl-object.c:199)
==50552==    by 0x4007269: _dl_map_object_from_fd (dl-load.c:1053)
==50552==    by 0x4008C97: _dl_map_object (dl-load.c:2249)
==50552==    by 0x400C99B: dl_open_worker_begin (dl-open.c:578)
==50552==    by 0x4001522: _dl_catch_exception (dl-catch.c:237)
==50552==    by 0x400C0DF: dl_open_worker (dl-open.c:803)
==50552==    by 0x4001522: _dl_catch_exception (dl-catch.c:237)
==50552==    by 0x400C533: _dl_open (dl-open.c:905)
==50552==    by 0x4E499E3: ??? (in /usr/lib/libc.so.6)
==50552==    by 0x4001522: _dl_catch_exception (dl-catch.c:237)
==50552==    by 0x4001678: _dl_catch_error (dl-catch.c:256)
==50552== 
==50552== 1,200 bytes in 1 blocks are still reachable in loss record 30 of 65
==50552==    at 0x4842788: malloc (vg_replace_malloc.c:446)
==50552==    by 0x4917F1C: UnknownInlinedFun (obmalloc.c:586)
==50552==    by 0x4917F1C: UnknownInlinedFun (obmalloc.c:2003)
==50552==    by 0x4917F1C: _PyObject_Malloc (obmalloc.c:1996)
==50552==    by 0x4927BA8: UnknownInlinedFun (obmalloc.c:712)
==50552==    by 0x4927BA8: _PyType_AllocNoTrack (typeobject.c:1124)
==50552==    by 0x4927C94: PyType_GenericAlloc (typeobject.c:1148)
==50552==    by 0x4AC241D: PyType_FromModuleAndSpec (typeobject.c:3408)
==50552==    by 0x4AF69F6: _functools_exec (_functoolsmodule.c:1449)
==50552==    by 0x4A3F7F9: PyModule_ExecDef (moduleobject.c:419)
==50552==    by 0x4A3FA9F: UnknownInlinedFun (import.c:2438)
==50552==    by 0x4A3FA9F: _imp_exec_builtin (import.c.h:504)
==50552==    by 0x4952E11: cfunction_vectorcall_O (methodobject.c:514)
==50552==    by 0x4AE8B1A: _PyEval_EvalFrameDefault (ceval.c:5376)
==50552==    by 0x4AEE2A5: UnknownInlinedFun (pycore_ceval.h:73)
==50552==    by 0x4AEE2A5: _PyEval_Vector (ceval.c:6434)
==50552==    by 0x49C2545: UnknownInlinedFun (pycore_call.h:92)
==50552==    by 0x49C2545: object_vacall (call.c:819)
==50552== 
==50552== 1,332 bytes in 2 blocks are still reachable in loss record 31 of 65
==50552==    at 0x4842788: malloc (vg_replace_malloc.c:446)
==50552==    by 0x4917F1C: UnknownInlinedFun (obmalloc.c:586)
==50552==    by 0x4917F1C: UnknownInlinedFun (obmalloc.c:2003)
==50552==    by 0x4917F1C: _PyObject_Malloc (obmalloc.c:1996)
==50552==    by 0x49969DD: UnknownInlinedFun (obmalloc.c:712)
==50552==    by 0x49969DD: PyUnicode_New.part.0 (unicodeobject.c:1425)
==50552==    by 0x493A642: UnknownInlinedFun (unicodeobject.c:1369)
==50552==    by 0x493A642: unicode_decode_utf8 (unicodeobject.c:5117)
==50552==    by 0x492842C: UnknownInlinedFun (unicodeobject.c:5250)
==50552==    by 0x492842C: UnknownInlinedFun (unicodeobject.c:2277)
==50552==    by 0x492842C: UnknownInlinedFun (typeobject.c:6162)
==50552==    by 0x492842C: UnknownInlinedFun (typeobject.c:6198)
==50552==    by 0x492842C: type_ready (typeobject.c:6468)
==50552==    by 0x492C56D: PyType_Ready (typeobject.c:6507)
==50552==    by 0x4AF645B: UnknownInlinedFun (modsupport.c:697)
==50552==    by 0x4AF645B: itertoolsmodule_exec (itertoolsmodule.c:4879)
==50552==    by 0x4A3F7F9: PyModule_ExecDef (moduleobject.c:419)
==50552==    by 0x4A3FA9F: UnknownInlinedFun (import.c:2438)
==50552==    by 0x4A3FA9F: _imp_exec_builtin (import.c.h:504)
==50552==    by 0x4952E11: cfunction_vectorcall_O (methodobject.c:514)
==50552==    by 0x4AE8B1A: _PyEval_EvalFrameDefault (ceval.c:5376)
==50552==    by 0x4AEE2A5: UnknownInlinedFun (pycore_ceval.h:73)
==50552==    by 0x4AEE2A5: _PyEval_Vector (ceval.c:6434)
==50552== 
==50552== 1,520 bytes in 1 blocks are still reachable in loss record 32 of 65
==50552==    at 0x4842788: malloc (vg_replace_malloc.c:446)
==50552==    by 0x4917F1C: UnknownInlinedFun (obmalloc.c:586)
==50552==    by 0x4917F1C: UnknownInlinedFun (obmalloc.c:2003)
==50552==    by 0x4917F1C: _PyObject_Malloc (obmalloc.c:1996)
==50552==    by 0x49A7496: UnknownInlinedFun (obmalloc.c:712)
==50552==    by 0x49A7496: new_keys_object (dictobject.c:632)
==50552==    by 0x49A7820: dictresize (dictobject.c:1429)
==50552==    by 0x49A7FEA: UnknownInlinedFun (dictobject.c:1183)
==50552==    by 0x49A7FEA: insertdict (dictobject.c:1248)
==50552==    by 0x4AEC1CC: _PyEval_EvalFrameDefault (ceval.c:2762)
==50552==    by 0x4AEE2A5: UnknownInlinedFun (pycore_ceval.h:73)
==50552==    by 0x4AEE2A5: _PyEval_Vector (ceval.c:6434)
==50552==    by 0x4AEE359: PyEval_EvalCode (ceval.c:1148)
==50552==    by 0x4AF2327: exec_code_in_module (import.c:764)
==50552==    by 0x4AFB7E5: PyImport_ImportFrozenModuleObject (import.c:1407)
==50552==    by 0x4AFE921: UnknownInlinedFun (import.c:1447)
==50552==    by 0x4AFE921: UnknownInlinedFun (pylifecycle.c:187)
==50552==    by 0x4AFE921: pycore_interp_init (pylifecycle.c:872)
==50552==    by 0x4AFF44C: UnknownInlinedFun (pylifecycle.c:901)
==50552==    by 0x4AFF44C: pyinit_core.constprop.0 (pylifecycle.c:1064)
==50552== 
==50552== 1,520 bytes in 1 blocks are still reachable in loss record 33 of 65
==50552==    at 0x4842788: malloc (vg_replace_malloc.c:446)
==50552==    by 0x4917F1C: UnknownInlinedFun (obmalloc.c:586)
==50552==    by 0x4917F1C: UnknownInlinedFun (obmalloc.c:2003)
==50552==    by 0x4917F1C: _PyObject_Malloc (obmalloc.c:1996)
==50552==    by 0x49A7496: UnknownInlinedFun (obmalloc.c:712)
==50552==    by 0x49A7496: new_keys_object (dictobject.c:632)
==50552==    by 0x49A7820: dictresize (dictobject.c:1429)
==50552==    by 0x49A7FEA: UnknownInlinedFun (dictobject.c:1183)
==50552==    by 0x49A7FEA: insertdict (dictobject.c:1248)
==50552==    by 0x4AEC1CC: _PyEval_EvalFrameDefault (ceval.c:2762)
==50552==    by 0x4AEE2A5: UnknownInlinedFun (pycore_ceval.h:73)
==50552==    by 0x4AEE2A5: _PyEval_Vector (ceval.c:6434)
==50552==    by 0x4AEE359: PyEval_EvalCode (ceval.c:1148)
==50552==    by 0x4AF30AA: UnknownInlinedFun (bltinmodule.c:1077)
==50552==    by 0x4AF30AA: builtin_exec (bltinmodule.c.h:465)
==50552==    by 0x4AE8257: _PyEval_EvalFrameDefault (ceval.c:5091)
==50552==    by 0x4AEE2A5: UnknownInlinedFun (pycore_ceval.h:73)
==50552==    by 0x4AEE2A5: _PyEval_Vector (ceval.c:6434)
==50552==    by 0x49C2545: UnknownInlinedFun (pycore_call.h:92)
==50552==    by 0x49C2545: object_vacall (call.c:819)
==50552== 
==50552== 1,520 bytes in 1 blocks are still reachable in loss record 34 of 65
==50552==    at 0x4842788: malloc (vg_replace_malloc.c:446)
==50552==    by 0x4917F1C: UnknownInlinedFun (obmalloc.c:586)
==50552==    by 0x4917F1C: UnknownInlinedFun (obmalloc.c:2003)
==50552==    by 0x4917F1C: _PyObject_Malloc (obmalloc.c:1996)
==50552==    by 0x49A7496: UnknownInlinedFun (obmalloc.c:712)
==50552==    by 0x49A7496: new_keys_object (dictobject.c:632)
==50552==    by 0x49A7820: dictresize (dictobject.c:1429)
==50552==    by 0x49A7FEA: UnknownInlinedFun (dictobject.c:1183)
==50552==    by 0x49A7FEA: insertdict (dictobject.c:1248)
==50552==    by 0x492846C: UnknownInlinedFun (dictobject.c:1906)
==50552==    by 0x492846C: UnknownInlinedFun (typeobject.c:6167)
==50552==    by 0x492846C: UnknownInlinedFun (typeobject.c:6198)
==50552==    by 0x492846C: type_ready (typeobject.c:6468)
==50552==    by 0x492C56D: PyType_Ready (typeobject.c:6507)
==50552==    by 0x4AF656A: UnknownInlinedFun (modsupport.c:697)
==50552==    by 0x4AF656A: collections_exec (_collectionsmodule.c:2587)
==50552==    by 0x4A3F7F9: PyModule_ExecDef (moduleobject.c:419)
==50552==    by 0x4A3FA9F: UnknownInlinedFun (import.c:2438)
==50552==    by 0x4A3FA9F: _imp_exec_builtin (import.c.h:504)
==50552==    by 0x4952E11: cfunction_vectorcall_O (methodobject.c:514)
==50552==    by 0x4AE8B1A: _PyEval_EvalFrameDefault (ceval.c:5376)
==50552== 
==50552== 1,520 bytes in 1 blocks are still reachable in loss record 35 of 65
==50552==    at 0x4842788: malloc (vg_replace_malloc.c:446)
==50552==    by 0x4917F1C: UnknownInlinedFun (obmalloc.c:586)
==50552==    by 0x4917F1C: UnknownInlinedFun (obmalloc.c:2003)
==50552==    by 0x4917F1C: _PyObject_Malloc (obmalloc.c:1996)
==50552==    by 0x49A7496: UnknownInlinedFun (obmalloc.c:712)
==50552==    by 0x49A7496: new_keys_object (dictobject.c:632)
==50552==    by 0x49A7820: dictresize (dictobject.c:1429)
==50552==    by 0x49A7FEA: UnknownInlinedFun (dictobject.c:1183)
==50552==    by 0x49A7FEA: insertdict (dictobject.c:1248)
==50552==    by 0x49EA19F: UnknownInlinedFun (dictobject.c:1906)
==50552==    by 0x49EA19F: PyDict_SetItemString (dictobject.c:3920)
==50552==    by 0x63AAF24: UnknownInlinedFun (_ctypes.c:5804)
==50552==    by 0x63AAF24: UnknownInlinedFun (_ctypes.c:5837)
==50552==    by 0x63AAF24: PyInit__ctypes (_ctypes.c:5852)
==50552==    by 0x4AFA4DE: UnknownInlinedFun (importdl.c:169)
==50552==    by 0x4AFA4DE: UnknownInlinedFun (import.c:2397)
==50552==    by 0x4AFA4DE: _imp_create_dynamic (import.c.h:446)
==50552==    by 0x4952F62: cfunction_vectorcall_FASTCALL (methodobject.c:427)
==50552==    by 0x4AE8B1A: _PyEval_EvalFrameDefault (ceval.c:5376)
==50552==    by 0x4AEE2A5: UnknownInlinedFun (pycore_ceval.h:73)
==50552==    by 0x4AEE2A5: _PyEval_Vector (ceval.c:6434)
==50552==    by 0x49C2545: UnknownInlinedFun (pycore_call.h:92)
==50552==    by 0x49C2545: object_vacall (call.c:819)
==50552== 
==50552== 1,536 bytes in 2 blocks are still reachable in loss record 36 of 65
==50552==    at 0x4842788: malloc (vg_replace_malloc.c:446)
==50552==    by 0x4917F1C: UnknownInlinedFun (obmalloc.c:586)
==50552==    by 0x4917F1C: UnknownInlinedFun (obmalloc.c:2003)
==50552==    by 0x4917F1C: _PyObject_Malloc (obmalloc.c:1996)
==50552==    by 0x49A7496: UnknownInlinedFun (obmalloc.c:712)
==50552==    by 0x49A7496: new_keys_object (dictobject.c:632)
==50552==    by 0x49A7820: dictresize (dictobject.c:1429)
==50552==    by 0x49DE22F: UnknownInlinedFun (dictobject.c:1183)
==50552==    by 0x49DE22F: PyDict_SetDefault (dictobject.c:3338)
==50552==    by 0x49280CE: UnknownInlinedFun (typeobject.c:5687)
==50552==    by 0x49280CE: UnknownInlinedFun (typeobject.c:5713)
==50552==    by 0x49280CE: UnknownInlinedFun (typeobject.c:6189)
==50552==    by 0x49280CE: type_ready (typeobject.c:6468)
==50552==    by 0x492C56D: PyType_Ready (typeobject.c:6507)
==50552==    by 0x4AFCBCC: UnknownInlinedFun (object.c:1986)
==50552==    by 0x4AFCBCC: UnknownInlinedFun (pylifecycle.c:704)
==50552==    by 0x4AFCBCC: pycore_interp_init (pylifecycle.c:845)
==50552==    by 0x4AFF44C: UnknownInlinedFun (pylifecycle.c:901)
==50552==    by 0x4AFF44C: pyinit_core.constprop.0 (pylifecycle.c:1064)
==50552==    by 0x4B11454: Py_InitializeFromConfig.part.0 (pylifecycle.c:1254)
==50552==    by 0x4B118B8: UnknownInlinedFun (pylifecycle.c:1239)
==50552==    by 0x4B118B8: pymain_init (main.c:67)
==50552==    by 0x4B13D72: UnknownInlinedFun (main.c:701)
==50552==    by 0x4B13D72: Py_BytesMain (main.c:734)
==50552== 
==50552== 1,536 bytes in 2 blocks are still reachable in loss record 37 of 65
==50552==    at 0x4842788: malloc (vg_replace_malloc.c:446)
==50552==    by 0x4917F1C: UnknownInlinedFun (obmalloc.c:586)
==50552==    by 0x4917F1C: UnknownInlinedFun (obmalloc.c:2003)
==50552==    by 0x4917F1C: _PyObject_Malloc (obmalloc.c:1996)
==50552==    by 0x49A7496: UnknownInlinedFun (obmalloc.c:712)
==50552==    by 0x49A7496: new_keys_object (dictobject.c:632)
==50552==    by 0x49A7820: dictresize (dictobject.c:1429)
==50552==    by 0x49DE22F: UnknownInlinedFun (dictobject.c:1183)
==50552==    by 0x49DE22F: PyDict_SetDefault (dictobject.c:3338)
==50552==    by 0x49282E6: UnknownInlinedFun (typeobject.c:5735)
==50552==    by 0x49282E6: UnknownInlinedFun (typeobject.c:6192)
==50552==    by 0x49282E6: type_ready (typeobject.c:6468)
==50552==    by 0x492C56D: PyType_Ready (typeobject.c:6507)
==50552==    by 0x4AFCBCC: UnknownInlinedFun (object.c:1986)
==50552==    by 0x4AFCBCC: UnknownInlinedFun (pylifecycle.c:704)
==50552==    by 0x4AFCBCC: pycore_interp_init (pylifecycle.c:845)
==50552==    by 0x4AFF44C: UnknownInlinedFun (pylifecycle.c:901)
==50552==    by 0x4AFF44C: pyinit_core.constprop.0 (pylifecycle.c:1064)
==50552==    by 0x4B11454: Py_InitializeFromConfig.part.0 (pylifecycle.c:1254)
==50552==    by 0x4B118B8: UnknownInlinedFun (pylifecycle.c:1239)
==50552==    by 0x4B118B8: pymain_init (main.c:67)
==50552==    by 0x4B13D72: UnknownInlinedFun (main.c:701)
==50552==    by 0x4B13D72: Py_BytesMain (main.c:734)
==50552== 
==50552== 1,536 bytes in 2 blocks are still reachable in loss record 38 of 65
==50552==    at 0x4842788: malloc (vg_replace_malloc.c:446)
==50552==    by 0x4917F1C: UnknownInlinedFun (obmalloc.c:586)
==50552==    by 0x4917F1C: UnknownInlinedFun (obmalloc.c:2003)
==50552==    by 0x4917F1C: _PyObject_Malloc (obmalloc.c:1996)
==50552==    by 0x49A7496: UnknownInlinedFun (obmalloc.c:712)
==50552==    by 0x49A7496: new_keys_object (dictobject.c:632)
==50552==    by 0x492B7D2: UnknownInlinedFun (dictobject.c:5333)
==50552==    by 0x492B7D2: UnknownInlinedFun (typeobject.c:6412)
==50552==    by 0x492B7D2: type_ready (typeobject.c:6480)
==50552==    by 0x492C56D: PyType_Ready (typeobject.c:6507)
==50552==    by 0x4AF883E: UnknownInlinedFun (typeobject.c:3189)
==50552==    by 0x4AF883E: type_new (typeobject.c:3323)
==50552==    by 0x63A7701: UnknownInlinedFun (_ctypes.c:1980)
==50552==    by 0x63A7701: PyCSimpleType_new (_ctypes.c:2189)
==50552==    by 0x494F8FD: type_call (typeobject.c:1091)
==50552==    by 0x49433BC: _PyObject_MakeTpCall (call.c:214)
==50552==    by 0x4AF3815: UnknownInlinedFun (call.c:165)
==50552==    by 0x4AF3815: builtin___build_class__ (bltinmodule.c:209)
==50552==    by 0x494F28C: cfunction_vectorcall_FASTCALL_KEYWORDS (methodobject.c:443)
==50552==    by 0x4943727: UnknownInlinedFun (pycore_call.h:92)
==50552==    by 0x4943727: PyObject_Vectorcall (call.c:299)
==50552== 
==50552== 1,536 bytes in 2 blocks are still reachable in loss record 39 of 65
==50552==    at 0x4842788: malloc (vg_replace_malloc.c:446)
==50552==    by 0x4917F1C: UnknownInlinedFun (obmalloc.c:586)
==50552==    by 0x4917F1C: UnknownInlinedFun (obmalloc.c:2003)
==50552==    by 0x4917F1C: _PyObject_Malloc (obmalloc.c:1996)
==50552==    by 0x49A7496: UnknownInlinedFun (obmalloc.c:712)
==50552==    by 0x49A7496: new_keys_object (dictobject.c:632)
==50552==    by 0x492B7D2: UnknownInlinedFun (dictobject.c:5333)
==50552==    by 0x492B7D2: UnknownInlinedFun (typeobject.c:6412)
==50552==    by 0x492B7D2: type_ready (typeobject.c:6480)
==50552==    by 0x492C56D: PyType_Ready (typeobject.c:6507)
==50552==    by 0x4AF883E: UnknownInlinedFun (typeobject.c:3189)
==50552==    by 0x4AF883E: type_new (typeobject.c:3323)
==50552==    by 0x63A5A2A: StructUnionType_new (_ctypes.c:509)
==50552==    by 0x494F8FD: type_call (typeobject.c:1091)
==50552==    by 0x49433BC: _PyObject_MakeTpCall (call.c:214)
==50552==    by 0x4AF3815: UnknownInlinedFun (call.c:165)
==50552==    by 0x4AF3815: builtin___build_class__ (bltinmodule.c:209)
==50552==    by 0x494F28C: cfunction_vectorcall_FASTCALL_KEYWORDS (methodobject.c:443)
==50552==    by 0x4943727: UnknownInlinedFun (pycore_call.h:92)
==50552==    by 0x4943727: PyObject_Vectorcall (call.c:299)
==50552== 
==50552== 1,920 bytes in 2 blocks are still reachable in loss record 40 of 65
==50552==    at 0x4842788: malloc (vg_replace_malloc.c:446)
==50552==    by 0x4917F1C: UnknownInlinedFun (obmalloc.c:586)
==50552==    by 0x4917F1C: UnknownInlinedFun (obmalloc.c:2003)
==50552==    by 0x4917F1C: _PyObject_Malloc (obmalloc.c:1996)
==50552==    by 0x4927BA8: UnknownInlinedFun (obmalloc.c:712)
==50552==    by 0x4927BA8: _PyType_AllocNoTrack (typeobject.c:1124)
==50552==    by 0x4927C94: PyType_GenericAlloc (typeobject.c:1148)
==50552==    by 0x4AF80AA: UnknownInlinedFun (typeobject.c:2744)
==50552==    by 0x4AF80AA: UnknownInlinedFun (typeobject.c:3156)
==50552==    by 0x4AF80AA: UnknownInlinedFun (typeobject.c:3179)
==50552==    by 0x4AF80AA: type_new (typeobject.c:3323)
==50552==    by 0x63A7701: UnknownInlinedFun (_ctypes.c:1980)
==50552==    by 0x63A7701: PyCSimpleType_new (_ctypes.c:2189)
==50552==    by 0x494F8FD: type_call (typeobject.c:1091)
==50552==    by 0x49433BC: _PyObject_MakeTpCall (call.c:214)
==50552==    by 0x4AF3815: UnknownInlinedFun (call.c:165)
==50552==    by 0x4AF3815: builtin___build_class__ (bltinmodule.c:209)
==50552==    by 0x494F28C: cfunction_vectorcall_FASTCALL_KEYWORDS (methodobject.c:443)
==50552==    by 0x4943727: UnknownInlinedFun (pycore_call.h:92)
==50552==    by 0x4943727: PyObject_Vectorcall (call.c:299)
==50552==    by 0x4AE6016: _PyEval_EvalFrameDefault (ceval.c:4769)
==50552== 
==50552== 1,920 bytes in 2 blocks are still reachable in loss record 41 of 65
==50552==    at 0x4842788: malloc (vg_replace_malloc.c:446)
==50552==    by 0x4917F1C: UnknownInlinedFun (obmalloc.c:586)
==50552==    by 0x4917F1C: UnknownInlinedFun (obmalloc.c:2003)
==50552==    by 0x4917F1C: _PyObject_Malloc (obmalloc.c:1996)
==50552==    by 0x4927BA8: UnknownInlinedFun (obmalloc.c:712)
==50552==    by 0x4927BA8: _PyType_AllocNoTrack (typeobject.c:1124)
==50552==    by 0x4927C94: PyType_GenericAlloc (typeobject.c:1148)
==50552==    by 0x4AF80AA: UnknownInlinedFun (typeobject.c:2744)
==50552==    by 0x4AF80AA: UnknownInlinedFun (typeobject.c:3156)
==50552==    by 0x4AF80AA: UnknownInlinedFun (typeobject.c:3179)
==50552==    by 0x4AF80AA: type_new (typeobject.c:3323)
==50552==    by 0x63A5A2A: StructUnionType_new (_ctypes.c:509)
==50552==    by 0x494F8FD: type_call (typeobject.c:1091)
==50552==    by 0x49433BC: _PyObject_MakeTpCall (call.c:214)
==50552==    by 0x4AF3815: UnknownInlinedFun (call.c:165)
==50552==    by 0x4AF3815: builtin___build_class__ (bltinmodule.c:209)
==50552==    by 0x494F28C: cfunction_vectorcall_FASTCALL_KEYWORDS (methodobject.c:443)
==50552==    by 0x4943727: UnknownInlinedFun (pycore_call.h:92)
==50552==    by 0x4943727: PyObject_Vectorcall (call.c:299)
==50552==    by 0x4AE6016: _PyEval_EvalFrameDefault (ceval.c:4769)
==50552== 
==50552== 2,146 bytes in 2 blocks are still reachable in loss record 42 of 65
==50552==    at 0x4842788: malloc (vg_replace_malloc.c:446)
==50552==    by 0x4917F1C: UnknownInlinedFun (obmalloc.c:586)
==50552==    by 0x4917F1C: UnknownInlinedFun (obmalloc.c:2003)
==50552==    by 0x4917F1C: _PyObject_Malloc (obmalloc.c:1996)
==50552==    by 0x4AF839D: UnknownInlinedFun (obmalloc.c:712)
==50552==    by 0x4AF839D: UnknownInlinedFun (typeobject.c:2887)
==50552==    by 0x4AF839D: UnknownInlinedFun (typeobject.c:3076)
==50552==    by 0x4AF839D: UnknownInlinedFun (typeobject.c:3184)
==50552==    by 0x4AF839D: type_new (typeobject.c:3323)
==50552==    by 0x494F8FD: type_call (typeobject.c:1091)
==50552==    by 0x49433BC: _PyObject_MakeTpCall (call.c:214)
==50552==    by 0x49D9799: _PyObject_FastCallDictTstate (call.c:141)
==50552==    by 0x4AF3815: UnknownInlinedFun (call.c:165)
==50552==    by 0x4AF3815: builtin___build_class__ (bltinmodule.c:209)
==50552==    by 0x494F28C: cfunction_vectorcall_FASTCALL_KEYWORDS (methodobject.c:443)
==50552==    by 0x4943727: UnknownInlinedFun (pycore_call.h:92)
==50552==    by 0x4943727: PyObject_Vectorcall (call.c:299)
==50552==    by 0x4AE6016: _PyEval_EvalFrameDefault (ceval.c:4769)
==50552==    by 0x4AEE2A5: UnknownInlinedFun (pycore_ceval.h:73)
==50552==    by 0x4AEE2A5: _PyEval_Vector (ceval.c:6434)
==50552==    by 0x4AEE359: PyEval_EvalCode (ceval.c:1148)
==50552== 
==50552== 2,181 bytes in 1 blocks are still reachable in loss record 43 of 65
==50552==    at 0x4842788: malloc (vg_replace_malloc.c:446)
==50552==    by 0x4917F1C: UnknownInlinedFun (obmalloc.c:586)
==50552==    by 0x4917F1C: UnknownInlinedFun (obmalloc.c:2003)
==50552==    by 0x4917F1C: _PyObject_Malloc (obmalloc.c:1996)
==50552==    by 0x49969DD: UnknownInlinedFun (obmalloc.c:712)
==50552==    by 0x49969DD: PyUnicode_New.part.0 (unicodeobject.c:1425)
==50552==    by 0x493A642: UnknownInlinedFun (unicodeobject.c:1369)
==50552==    by 0x493A642: unicode_decode_utf8 (unicodeobject.c:5117)
==50552==    by 0x492842C: UnknownInlinedFun (unicodeobject.c:5250)
==50552==    by 0x492842C: UnknownInlinedFun (unicodeobject.c:2277)
==50552==    by 0x492842C: UnknownInlinedFun (typeobject.c:6162)
==50552==    by 0x492842C: UnknownInlinedFun (typeobject.c:6198)
==50552==    by 0x492842C: type_ready (typeobject.c:6468)
==50552==    by 0x492C56D: PyType_Ready (typeobject.c:6507)
==50552==    by 0x4949A97: best_base (typeobject.c:2185)
==50552==    by 0x4AF800E: UnknownInlinedFun (typeobject.c:3269)
==50552==    by 0x4AF800E: type_new (typeobject.c:3311)
==50552==    by 0x494F8FD: type_call (typeobject.c:1091)
==50552==    by 0x49433BC: _PyObject_MakeTpCall (call.c:214)
==50552==    by 0x49D9799: _PyObject_FastCallDictTstate (call.c:141)
==50552==    by 0x4AF3815: UnknownInlinedFun (call.c:165)
==50552==    by 0x4AF3815: builtin___build_class__ (bltinmodule.c:209)
==50552== 
==50552== 2,288 bytes in 2 blocks are still reachable in loss record 44 of 65
==50552==    at 0x4842788: malloc (vg_replace_malloc.c:446)
==50552==    by 0x4917F1C: UnknownInlinedFun (obmalloc.c:586)
==50552==    by 0x4917F1C: UnknownInlinedFun (obmalloc.c:2003)
==50552==    by 0x4917F1C: _PyObject_Malloc (obmalloc.c:1996)
==50552==    by 0x49A7496: UnknownInlinedFun (obmalloc.c:712)
==50552==    by 0x49A7496: new_keys_object (dictobject.c:632)
==50552==    by 0x49A7820: dictresize (dictobject.c:1429)
==50552==    by 0x49A7FEA: UnknownInlinedFun (dictobject.c:1183)
==50552==    by 0x49A7FEA: insertdict (dictobject.c:1248)
==50552==    by 0x4AEC1CC: _PyEval_EvalFrameDefault (ceval.c:2762)
==50552==    by 0x4AEE2A5: UnknownInlinedFun (pycore_ceval.h:73)
==50552==    by 0x4AEE2A5: _PyEval_Vector (ceval.c:6434)
==50552==    by 0x4AEE359: PyEval_EvalCode (ceval.c:1148)
==50552==    by 0x4AF30AA: UnknownInlinedFun (bltinmodule.c:1077)
==50552==    by 0x4AF30AA: builtin_exec (bltinmodule.c.h:465)
==50552==    by 0x494F28C: cfunction_vectorcall_FASTCALL_KEYWORDS (methodobject.c:443)
==50552==    by 0x4943727: UnknownInlinedFun (pycore_call.h:92)
==50552==    by 0x4943727: PyObject_Vectorcall (call.c:299)
==50552==    by 0x4AE6016: _PyEval_EvalFrameDefault (ceval.c:4769)
==50552== 
==50552== 2,304 bytes in 3 blocks are still reachable in loss record 45 of 65
==50552==    at 0x4842788: malloc (vg_replace_malloc.c:446)
==50552==    by 0x4917F1C: UnknownInlinedFun (obmalloc.c:586)
==50552==    by 0x4917F1C: UnknownInlinedFun (obmalloc.c:2003)
==50552==    by 0x4917F1C: _PyObject_Malloc (obmalloc.c:1996)
==50552==    by 0x49A7496: UnknownInlinedFun (obmalloc.c:712)
==50552==    by 0x49A7496: new_keys_object (dictobject.c:632)
==50552==    by 0x492B7D2: UnknownInlinedFun (dictobject.c:5333)
==50552==    by 0x492B7D2: UnknownInlinedFun (typeobject.c:6412)
==50552==    by 0x492B7D2: type_ready (typeobject.c:6480)
==50552==    by 0x492C56D: PyType_Ready (typeobject.c:6507)
==50552==    by 0x4AF883E: UnknownInlinedFun (typeobject.c:3189)
==50552==    by 0x4AF883E: type_new (typeobject.c:3323)
==50552==    by 0x63A1A33: PyCPointerType_new (_ctypes.c:1130)
==50552==    by 0x494F8FD: type_call (typeobject.c:1091)
==50552==    by 0x49433BC: _PyObject_MakeTpCall (call.c:214)
==50552==    by 0x4936B60: UnknownInlinedFun (pycore_call.h:90)
==50552==    by 0x4936B60: UnknownInlinedFun (pycore_call.h:77)
==50552==    by 0x4936B60: _PyObject_CallFunctionVa (call.c:536)
==50552==    by 0x4936C91: PyObject_CallFunction (call.c:558)
==50552==    by 0x63A39C8: POINTER.part.0 (callproc.c:1931)
==50552== 
==50552== 2,672 bytes in 4 blocks are still reachable in loss record 46 of 65
==50552==    at 0x4842788: malloc (vg_replace_malloc.c:446)
==50552==    by 0x4917F1C: UnknownInlinedFun (obmalloc.c:586)
==50552==    by 0x4917F1C: UnknownInlinedFun (obmalloc.c:2003)
==50552==    by 0x4917F1C: _PyObject_Malloc (obmalloc.c:1996)
==50552==    by 0x497CFF6: UnknownInlinedFun (obmalloc.c:712)
==50552==    by 0x497CFF6: _PyObject_NewVar (object.c:189)
==50552==    by 0x4A4DC1D: _PyCode_New (codeobject.c:481)
==50552==    by 0x4A837CA: r_object (marshal.c:1463)
==50552==    by 0x4A84081: r_object (marshal.c:1228)
==50552==    by 0x4A8346E: r_object (marshal.c:1403)
==50552==    by 0x4A84081: r_object (marshal.c:1228)
==50552==    by 0x4A8346E: r_object (marshal.c:1403)
==50552==    by 0x4A84E1A: read_object (marshal.c:1535)
==50552==    by 0x4A851BC: UnknownInlinedFun (marshal.c:1842)
==50552==    by 0x4A851BC: marshal_loads (marshal.c.h:148)
==50552==    by 0x4952E11: cfunction_vectorcall_O (methodobject.c:514)
==50552== 
==50552== 2,880 bytes in 3 blocks are still reachable in loss record 47 of 65
==50552==    at 0x4842788: malloc (vg_replace_malloc.c:446)
==50552==    by 0x4917F1C: UnknownInlinedFun (obmalloc.c:586)
==50552==    by 0x4917F1C: UnknownInlinedFun (obmalloc.c:2003)
==50552==    by 0x4917F1C: _PyObject_Malloc (obmalloc.c:1996)
==50552==    by 0x4927BA8: UnknownInlinedFun (obmalloc.c:712)
==50552==    by 0x4927BA8: _PyType_AllocNoTrack (typeobject.c:1124)
==50552==    by 0x4927C94: PyType_GenericAlloc (typeobject.c:1148)
==50552==    by 0x4AF8632: UnknownInlinedFun (typeobject.c:2744)
==50552==    by 0x4AF8632: UnknownInlinedFun (typeobject.c:3156)
==50552==    by 0x4AF8632: UnknownInlinedFun (typeobject.c:3179)
==50552==    by 0x4AF8632: type_new (typeobject.c:3323)
==50552==    by 0x494F8FD: type_call (typeobject.c:1091)
==50552==    by 0x49433BC: _PyObject_MakeTpCall (call.c:214)
==50552==    by 0x49D9799: _PyObject_FastCallDictTstate (call.c:141)
==50552==    by 0x4AF3815: UnknownInlinedFun (call.c:165)
==50552==    by 0x4AF3815: builtin___build_class__ (bltinmodule.c:209)
==50552==    by 0x494F28C: cfunction_vectorcall_FASTCALL_KEYWORDS (methodobject.c:443)
==50552==    by 0x4943727: UnknownInlinedFun (pycore_call.h:92)
==50552==    by 0x4943727: PyObject_Vectorcall (call.c:299)
==50552==    by 0x4AE6016: _PyEval_EvalFrameDefault (ceval.c:4769)
==50552== 
==50552== 2,880 bytes in 3 blocks are still reachable in loss record 48 of 65
==50552==    at 0x4842788: malloc (vg_replace_malloc.c:446)
==50552==    by 0x4917F1C: UnknownInlinedFun (obmalloc.c:586)
==50552==    by 0x4917F1C: UnknownInlinedFun (obmalloc.c:2003)
==50552==    by 0x4917F1C: _PyObject_Malloc (obmalloc.c:1996)
==50552==    by 0x4927BA8: UnknownInlinedFun (obmalloc.c:712)
==50552==    by 0x4927BA8: _PyType_AllocNoTrack (typeobject.c:1124)
==50552==    by 0x4927C94: PyType_GenericAlloc (typeobject.c:1148)
==50552==    by 0x4AF80AA: UnknownInlinedFun (typeobject.c:2744)
==50552==    by 0x4AF80AA: UnknownInlinedFun (typeobject.c:3156)
==50552==    by 0x4AF80AA: UnknownInlinedFun (typeobject.c:3179)
==50552==    by 0x4AF80AA: type_new (typeobject.c:3323)
==50552==    by 0x63A1A33: PyCPointerType_new (_ctypes.c:1130)
==50552==    by 0x494F8FD: type_call (typeobject.c:1091)
==50552==    by 0x49433BC: _PyObject_MakeTpCall (call.c:214)
==50552==    by 0x4936B60: UnknownInlinedFun (pycore_call.h:90)
==50552==    by 0x4936B60: UnknownInlinedFun (pycore_call.h:77)
==50552==    by 0x4936B60: _PyObject_CallFunctionVa (call.c:536)
==50552==    by 0x4936C91: PyObject_CallFunction (call.c:558)
==50552==    by 0x63A39C8: POINTER.part.0 (callproc.c:1931)
==50552==    by 0x4952E11: cfunction_vectorcall_O (methodobject.c:514)
==50552== 
==50552== 3,072 bytes in 4 blocks are still reachable in loss record 49 of 65
==50552==    at 0x4842788: malloc (vg_replace_malloc.c:446)
==50552==    by 0x4917F1C: UnknownInlinedFun (obmalloc.c:586)
==50552==    by 0x4917F1C: UnknownInlinedFun (obmalloc.c:2003)
==50552==    by 0x4917F1C: _PyObject_Malloc (obmalloc.c:1996)
==50552==    by 0x49A7496: UnknownInlinedFun (obmalloc.c:712)
==50552==    by 0x49A7496: new_keys_object (dictobject.c:632)
==50552==    by 0x492B7D2: UnknownInlinedFun (dictobject.c:5333)
==50552==    by 0x492B7D2: UnknownInlinedFun (typeobject.c:6412)
==50552==    by 0x492B7D2: type_ready (typeobject.c:6480)
==50552==    by 0x492C56D: PyType_Ready (typeobject.c:6507)
==50552==    by 0x4AF883E: UnknownInlinedFun (typeobject.c:3189)
==50552==    by 0x4AF883E: type_new (typeobject.c:3323)
==50552==    by 0x494F8FD: type_call (typeobject.c:1091)
==50552==    by 0x49433BC: _PyObject_MakeTpCall (call.c:214)
==50552==    by 0x49D9835: _PyObject_FastCallDictTstate (call.c:152)
==50552==    by 0x4AF3815: UnknownInlinedFun (call.c:165)
==50552==    by 0x4AF3815: builtin___build_class__ (bltinmodule.c:209)
==50552==    by 0x494F28C: cfunction_vectorcall_FASTCALL_KEYWORDS (methodobject.c:443)
==50552==    by 0x4943727: UnknownInlinedFun (pycore_call.h:92)
==50552==    by 0x4943727: PyObject_Vectorcall (call.c:299)
==50552== 
==50552== 3,840 bytes in 4 blocks are still reachable in loss record 50 of 65
==50552==    at 0x4842788: malloc (vg_replace_malloc.c:446)
==50552==    by 0x4917F1C: UnknownInlinedFun (obmalloc.c:586)
==50552==    by 0x4917F1C: UnknownInlinedFun (obmalloc.c:2003)
==50552==    by 0x4917F1C: _PyObject_Malloc (obmalloc.c:1996)
==50552==    by 0x4927BA8: UnknownInlinedFun (obmalloc.c:712)
==50552==    by 0x4927BA8: _PyType_AllocNoTrack (typeobject.c:1124)
==50552==    by 0x4927C94: PyType_GenericAlloc (typeobject.c:1148)
==50552==    by 0x4AF80AA: UnknownInlinedFun (typeobject.c:2744)
==50552==    by 0x4AF80AA: UnknownInlinedFun (typeobject.c:3156)
==50552==    by 0x4AF80AA: UnknownInlinedFun (typeobject.c:3179)
==50552==    by 0x4AF80AA: type_new (typeobject.c:3323)
==50552==    by 0x494F8FD: type_call (typeobject.c:1091)
==50552==    by 0x49433BC: _PyObject_MakeTpCall (call.c:214)
==50552==    by 0x49D9835: _PyObject_FastCallDictTstate (call.c:152)
==50552==    by 0x4AF3815: UnknownInlinedFun (call.c:165)
==50552==    by 0x4AF3815: builtin___build_class__ (bltinmodule.c:209)
==50552==    by 0x494F28C: cfunction_vectorcall_FASTCALL_KEYWORDS (methodobject.c:443)
==50552==    by 0x4943727: UnknownInlinedFun (pycore_call.h:92)
==50552==    by 0x4943727: PyObject_Vectorcall (call.c:299)
==50552==    by 0x4AE6016: _PyEval_EvalFrameDefault (ceval.c:4769)
==50552== 
==50552== 3,840 bytes in 5 blocks are still reachable in loss record 51 of 65
==50552==    at 0x4842788: malloc (vg_replace_malloc.c:446)
==50552==    by 0x4917F1C: UnknownInlinedFun (obmalloc.c:586)
==50552==    by 0x4917F1C: UnknownInlinedFun (obmalloc.c:2003)
==50552==    by 0x4917F1C: _PyObject_Malloc (obmalloc.c:1996)
==50552==    by 0x49A7496: UnknownInlinedFun (obmalloc.c:712)
==50552==    by 0x49A7496: new_keys_object (dictobject.c:632)
==50552==    by 0x492B7D2: UnknownInlinedFun (dictobject.c:5333)
==50552==    by 0x492B7D2: UnknownInlinedFun (typeobject.c:6412)
==50552==    by 0x492B7D2: type_ready (typeobject.c:6480)
==50552==    by 0x492C56D: PyType_Ready (typeobject.c:6507)
==50552==    by 0x4AF883E: UnknownInlinedFun (typeobject.c:3189)
==50552==    by 0x4AF883E: type_new (typeobject.c:3323)
==50552==    by 0x63A0F79: PyCFuncPtrType_new (_ctypes.c:2567)
==50552==    by 0x494F8FD: type_call (typeobject.c:1091)
==50552==    by 0x49433BC: _PyObject_MakeTpCall (call.c:214)
==50552==    by 0x4AF3815: UnknownInlinedFun (call.c:165)
==50552==    by 0x4AF3815: builtin___build_class__ (bltinmodule.c:209)
==50552==    by 0x494F28C: cfunction_vectorcall_FASTCALL_KEYWORDS (methodobject.c:443)
==50552==    by 0x4943727: UnknownInlinedFun (pycore_call.h:92)
==50552==    by 0x4943727: PyObject_Vectorcall (call.c:299)
==50552== 
==50552== 4,056 bytes in 17 blocks are still reachable in loss record 52 of 65
==50552==    at 0x4849BF3: calloc (vg_replace_malloc.c:1675)
==50552==    by 0x4013D77: calloc (rtld-malloc.h:44)
==50552==    by 0x4013D77: _dl_check_map_versions (dl-version.c:280)
==50552==    by 0x400CA4A: dl_open_worker_begin (dl-open.c:646)
==50552==    by 0x4001522: _dl_catch_exception (dl-catch.c:237)
==50552==    by 0x400C0DF: dl_open_worker (dl-open.c:803)
==50552==    by 0x4001522: _dl_catch_exception (dl-catch.c:237)
==50552==    by 0x400C533: _dl_open (dl-open.c:905)
==50552==    by 0x4E499E3: ??? (in /usr/lib/libc.so.6)
==50552==    by 0x4001522: _dl_catch_exception (dl-catch.c:237)
==50552==    by 0x4001678: _dl_catch_error (dl-catch.c:256)
==50552==    by 0x4E494C2: ??? (in /usr/lib/libc.so.6)
==50552==    by 0x4E49A9E: dlopen (in /usr/lib/libc.so.6)
==50552== 
==50552== 4,608 bytes in 6 blocks are still reachable in loss record 53 of 65
==50552==    at 0x4842788: malloc (vg_replace_malloc.c:446)
==50552==    by 0x4917F1C: UnknownInlinedFun (obmalloc.c:586)
==50552==    by 0x4917F1C: UnknownInlinedFun (obmalloc.c:2003)
==50552==    by 0x4917F1C: _PyObject_Malloc (obmalloc.c:1996)
==50552==    by 0x49A7496: UnknownInlinedFun (obmalloc.c:712)
==50552==    by 0x49A7496: new_keys_object (dictobject.c:632)
==50552==    by 0x492B7D2: UnknownInlinedFun (dictobject.c:5333)
==50552==    by 0x492B7D2: UnknownInlinedFun (typeobject.c:6412)
==50552==    by 0x492B7D2: type_ready (typeobject.c:6480)
==50552==    by 0x492C56D: PyType_Ready (typeobject.c:6507)
==50552==    by 0x4AF883E: UnknownInlinedFun (typeobject.c:3189)
==50552==    by 0x4AF883E: type_new (typeobject.c:3323)
==50552==    by 0x63A0F79: PyCFuncPtrType_new (_ctypes.c:2567)
==50552==    by 0x494F8FD: type_call (typeobject.c:1091)
==50552==    by 0x49433BC: _PyObject_MakeTpCall (call.c:214)
==50552==    by 0x4AF3815: UnknownInlinedFun (call.c:165)
==50552==    by 0x4AF3815: builtin___build_class__ (bltinmodule.c:209)
==50552==    by 0x4AE8257: _PyEval_EvalFrameDefault (ceval.c:5091)
==50552==    by 0x4AEE2A5: UnknownInlinedFun (pycore_ceval.h:73)
==50552==    by 0x4AEE2A5: _PyEval_Vector (ceval.c:6434)
==50552== 
==50552== 4,800 bytes in 5 blocks are still reachable in loss record 54 of 65
==50552==    at 0x4842788: malloc (vg_replace_malloc.c:446)
==50552==    by 0x4917F1C: UnknownInlinedFun (obmalloc.c:586)
==50552==    by 0x4917F1C: UnknownInlinedFun (obmalloc.c:2003)
==50552==    by 0x4917F1C: _PyObject_Malloc (obmalloc.c:1996)
==50552==    by 0x4927BA8: UnknownInlinedFun (obmalloc.c:712)
==50552==    by 0x4927BA8: _PyType_AllocNoTrack (typeobject.c:1124)
==50552==    by 0x4927C94: PyType_GenericAlloc (typeobject.c:1148)
==50552==    by 0x4AF80AA: UnknownInlinedFun (typeobject.c:2744)
==50552==    by 0x4AF80AA: UnknownInlinedFun (typeobject.c:3156)
==50552==    by 0x4AF80AA: UnknownInlinedFun (typeobject.c:3179)
==50552==    by 0x4AF80AA: type_new (typeobject.c:3323)
==50552==    by 0x63A0F79: PyCFuncPtrType_new (_ctypes.c:2567)
==50552==    by 0x494F8FD: type_call (typeobject.c:1091)
==50552==    by 0x49433BC: _PyObject_MakeTpCall (call.c:214)
==50552==    by 0x4AF3815: UnknownInlinedFun (call.c:165)
==50552==    by 0x4AF3815: builtin___build_class__ (bltinmodule.c:209)
==50552==    by 0x494F28C: cfunction_vectorcall_FASTCALL_KEYWORDS (methodobject.c:443)
==50552==    by 0x4943727: UnknownInlinedFun (pycore_call.h:92)
==50552==    by 0x4943727: PyObject_Vectorcall (call.c:299)
==50552==    by 0x4AE6016: _PyEval_EvalFrameDefault (ceval.c:4769)
==50552== 
==50552== 5,009 bytes in 4 blocks are still reachable in loss record 55 of 65
==50552==    at 0x4849BF3: calloc (vg_replace_malloc.c:1675)
==50552==    by 0x400BB7D: calloc (rtld-malloc.h:44)
==50552==    by 0x400BB7D: _dl_new_object (dl-object.c:92)
==50552==    by 0x4007269: _dl_map_object_from_fd (dl-load.c:1053)
==50552==    by 0x4008C97: _dl_map_object (dl-load.c:2249)
==50552==    by 0x400287C: openaux (dl-deps.c:64)
==50552==    by 0x4001522: _dl_catch_exception (dl-catch.c:237)
==50552==    by 0x4002D04: _dl_map_object_deps (dl-deps.c:232)
==50552==    by 0x400CA04: dl_open_worker_begin (dl-open.c:638)
==50552==    by 0x4001522: _dl_catch_exception (dl-catch.c:237)
==50552==    by 0x400C0DF: dl_open_worker (dl-open.c:803)
==50552==    by 0x4001522: _dl_catch_exception (dl-catch.c:237)
==50552==    by 0x400C533: _dl_open (dl-open.c:905)
==50552== 
==50552== 5,376 bytes in 7 blocks are still reachable in loss record 56 of 65
==50552==    at 0x4842788: malloc (vg_replace_malloc.c:446)
==50552==    by 0x4917F1C: UnknownInlinedFun (obmalloc.c:586)
==50552==    by 0x4917F1C: UnknownInlinedFun (obmalloc.c:2003)
==50552==    by 0x4917F1C: _PyObject_Malloc (obmalloc.c:1996)
==50552==    by 0x49A7496: UnknownInlinedFun (obmalloc.c:712)
==50552==    by 0x49A7496: new_keys_object (dictobject.c:632)
==50552==    by 0x492B7D2: UnknownInlinedFun (dictobject.c:5333)
==50552==    by 0x492B7D2: UnknownInlinedFun (typeobject.c:6412)
==50552==    by 0x492B7D2: type_ready (typeobject.c:6480)
==50552==    by 0x492C56D: PyType_Ready (typeobject.c:6507)
==50552==    by 0x4AF883E: UnknownInlinedFun (typeobject.c:3189)
==50552==    by 0x4AF883E: type_new (typeobject.c:3323)
==50552==    by 0x494F8FD: type_call (typeobject.c:1091)
==50552==    by 0x49433BC: _PyObject_MakeTpCall (call.c:214)
==50552==    by 0x49D9799: _PyObject_FastCallDictTstate (call.c:141)
==50552==    by 0x4AF3815: UnknownInlinedFun (call.c:165)
==50552==    by 0x4AF3815: builtin___build_class__ (bltinmodule.c:209)
==50552==    by 0x494F28C: cfunction_vectorcall_FASTCALL_KEYWORDS (methodobject.c:443)
==50552==    by 0x4943727: UnknownInlinedFun (pycore_call.h:92)
==50552==    by 0x4943727: PyObject_Vectorcall (call.c:299)
==50552== 
==50552== 5,760 bytes in 6 blocks are still reachable in loss record 57 of 65
==50552==    at 0x4842788: malloc (vg_replace_malloc.c:446)
==50552==    by 0x4917F1C: UnknownInlinedFun (obmalloc.c:586)
==50552==    by 0x4917F1C: UnknownInlinedFun (obmalloc.c:2003)
==50552==    by 0x4917F1C: _PyObject_Malloc (obmalloc.c:1996)
==50552==    by 0x4927BA8: UnknownInlinedFun (obmalloc.c:712)
==50552==    by 0x4927BA8: _PyType_AllocNoTrack (typeobject.c:1124)
==50552==    by 0x4927C94: PyType_GenericAlloc (typeobject.c:1148)
==50552==    by 0x4AF80AA: UnknownInlinedFun (typeobject.c:2744)
==50552==    by 0x4AF80AA: UnknownInlinedFun (typeobject.c:3156)
==50552==    by 0x4AF80AA: UnknownInlinedFun (typeobject.c:3179)
==50552==    by 0x4AF80AA: type_new (typeobject.c:3323)
==50552==    by 0x63A0F79: PyCFuncPtrType_new (_ctypes.c:2567)
==50552==    by 0x494F8FD: type_call (typeobject.c:1091)
==50552==    by 0x49433BC: _PyObject_MakeTpCall (call.c:214)
==50552==    by 0x4AF3815: UnknownInlinedFun (call.c:165)
==50552==    by 0x4AF3815: builtin___build_class__ (bltinmodule.c:209)
==50552==    by 0x4AE8257: _PyEval_EvalFrameDefault (ceval.c:5091)
==50552==    by 0x4AEE2A5: UnknownInlinedFun (pycore_ceval.h:73)
==50552==    by 0x4AEE2A5: _PyEval_Vector (ceval.c:6434)
==50552==    by 0x4AF379D: builtin___build_class__ (bltinmodule.c:201)
==50552== 
==50552== 6,144 bytes in 8 blocks are still reachable in loss record 58 of 65
==50552==    at 0x4842788: malloc (vg_replace_malloc.c:446)
==50552==    by 0x4917F1C: UnknownInlinedFun (obmalloc.c:586)
==50552==    by 0x4917F1C: UnknownInlinedFun (obmalloc.c:2003)
==50552==    by 0x4917F1C: _PyObject_Malloc (obmalloc.c:1996)
==50552==    by 0x49A7496: UnknownInlinedFun (obmalloc.c:712)
==50552==    by 0x49A7496: new_keys_object (dictobject.c:632)
==50552==    by 0x492B7D2: UnknownInlinedFun (dictobject.c:5333)
==50552==    by 0x492B7D2: UnknownInlinedFun (typeobject.c:6412)
==50552==    by 0x492B7D2: type_ready (typeobject.c:6480)
==50552==    by 0x492C56D: PyType_Ready (typeobject.c:6507)
==50552==    by 0x4AF883E: UnknownInlinedFun (typeobject.c:3189)
==50552==    by 0x4AF883E: type_new (typeobject.c:3323)
==50552==    by 0x63A741A: PyCSimpleType_new (_ctypes.c:2055)
==50552==    by 0x494F8FD: type_call (typeobject.c:1091)
==50552==    by 0x49433BC: _PyObject_MakeTpCall (call.c:214)
==50552==    by 0x4AF3815: UnknownInlinedFun (call.c:165)
==50552==    by 0x4AF3815: builtin___build_class__ (bltinmodule.c:209)
==50552==    by 0x494F28C: cfunction_vectorcall_FASTCALL_KEYWORDS (methodobject.c:443)
==50552==    by 0x4943727: UnknownInlinedFun (pycore_call.h:92)
==50552==    by 0x4943727: PyObject_Vectorcall (call.c:299)
==50552== 
==50552== 7,680 bytes in 8 blocks are still reachable in loss record 59 of 65
==50552==    at 0x4842788: malloc (vg_replace_malloc.c:446)
==50552==    by 0x4917F1C: UnknownInlinedFun (obmalloc.c:586)
==50552==    by 0x4917F1C: UnknownInlinedFun (obmalloc.c:2003)
==50552==    by 0x4917F1C: _PyObject_Malloc (obmalloc.c:1996)
==50552==    by 0x4927BA8: UnknownInlinedFun (obmalloc.c:712)
==50552==    by 0x4927BA8: _PyType_AllocNoTrack (typeobject.c:1124)
==50552==    by 0x4927C94: PyType_GenericAlloc (typeobject.c:1148)
==50552==    by 0x4AF80AA: UnknownInlinedFun (typeobject.c:2744)
==50552==    by 0x4AF80AA: UnknownInlinedFun (typeobject.c:3156)
==50552==    by 0x4AF80AA: UnknownInlinedFun (typeobject.c:3179)
==50552==    by 0x4AF80AA: type_new (typeobject.c:3323)
==50552==    by 0x63A741A: PyCSimpleType_new (_ctypes.c:2055)
==50552==    by 0x494F8FD: type_call (typeobject.c:1091)
==50552==    by 0x49433BC: _PyObject_MakeTpCall (call.c:214)
==50552==    by 0x4AF3815: UnknownInlinedFun (call.c:165)
==50552==    by 0x4AF3815: builtin___build_class__ (bltinmodule.c:209)
==50552==    by 0x494F28C: cfunction_vectorcall_FASTCALL_KEYWORDS (methodobject.c:443)
==50552==    by 0x4943727: UnknownInlinedFun (pycore_call.h:92)
==50552==    by 0x4943727: PyObject_Vectorcall (call.c:299)
==50552==    by 0x4AE6016: _PyEval_EvalFrameDefault (ceval.c:4769)
==50552== 
==50552== 8,640 bytes in 9 blocks are still reachable in loss record 60 of 65
==50552==    at 0x4842788: malloc (vg_replace_malloc.c:446)
==50552==    by 0x4917F1C: UnknownInlinedFun (obmalloc.c:586)
==50552==    by 0x4917F1C: UnknownInlinedFun (obmalloc.c:2003)
==50552==    by 0x4917F1C: _PyObject_Malloc (obmalloc.c:1996)
==50552==    by 0x4927BA8: UnknownInlinedFun (obmalloc.c:712)
==50552==    by 0x4927BA8: _PyType_AllocNoTrack (typeobject.c:1124)
==50552==    by 0x4927C94: PyType_GenericAlloc (typeobject.c:1148)
==50552==    by 0x4AF80AA: UnknownInlinedFun (typeobject.c:2744)
==50552==    by 0x4AF80AA: UnknownInlinedFun (typeobject.c:3156)
==50552==    by 0x4AF80AA: UnknownInlinedFun (typeobject.c:3179)
==50552==    by 0x4AF80AA: type_new (typeobject.c:3323)
==50552==    by 0x494F8FD: type_call (typeobject.c:1091)
==50552==    by 0x49433BC: _PyObject_MakeTpCall (call.c:214)
==50552==    by 0x49D9799: _PyObject_FastCallDictTstate (call.c:141)
==50552==    by 0x4AF3815: UnknownInlinedFun (call.c:165)
==50552==    by 0x4AF3815: builtin___build_class__ (bltinmodule.c:209)
==50552==    by 0x494F28C: cfunction_vectorcall_FASTCALL_KEYWORDS (methodobject.c:443)
==50552==    by 0x4943727: UnknownInlinedFun (pycore_call.h:92)
==50552==    by 0x4943727: PyObject_Vectorcall (call.c:299)
==50552==    by 0x4AE6016: _PyEval_EvalFrameDefault (ceval.c:4769)
==50552== 
==50552== 12,064 bytes in 4 blocks are still reachable in loss record 61 of 65
==50552==    at 0x4842788: malloc (vg_replace_malloc.c:446)
==50552==    by 0x4917F1C: UnknownInlinedFun (obmalloc.c:586)
==50552==    by 0x4917F1C: UnknownInlinedFun (obmalloc.c:2003)
==50552==    by 0x4917F1C: _PyObject_Malloc (obmalloc.c:1996)
==50552==    by 0x49A7496: UnknownInlinedFun (obmalloc.c:712)
==50552==    by 0x49A7496: new_keys_object (dictobject.c:632)
==50552==    by 0x49A7820: dictresize (dictobject.c:1429)
==50552==    by 0x49A7FEA: UnknownInlinedFun (dictobject.c:1183)
==50552==    by 0x49A7FEA: insertdict (dictobject.c:1248)
==50552==    by 0x4AEC1CC: _PyEval_EvalFrameDefault (ceval.c:2762)
==50552==    by 0x4AEE2A5: UnknownInlinedFun (pycore_ceval.h:73)
==50552==    by 0x4AEE2A5: _PyEval_Vector (ceval.c:6434)
==50552==    by 0x4AEE359: PyEval_EvalCode (ceval.c:1148)
==50552==    by 0x4AF30AA: UnknownInlinedFun (bltinmodule.c:1077)
==50552==    by 0x4AF30AA: builtin_exec (bltinmodule.c.h:465)
==50552==    by 0x494F28C: cfunction_vectorcall_FASTCALL_KEYWORDS (methodobject.c:443)
==50552==    by 0x4AE8B1A: _PyEval_EvalFrameDefault (ceval.c:5376)
==50552==    by 0x4AEE2A5: UnknownInlinedFun (pycore_ceval.h:73)
==50552==    by 0x4AEE2A5: _PyEval_Vector (ceval.c:6434)
==50552== 
==50552== 20,120 bytes in 3 blocks are still reachable in loss record 62 of 65
==50552==    at 0x4842788: malloc (vg_replace_malloc.c:446)
==50552==    by 0x4917F1C: UnknownInlinedFun (obmalloc.c:586)
==50552==    by 0x4917F1C: UnknownInlinedFun (obmalloc.c:2003)
==50552==    by 0x4917F1C: _PyObject_Malloc (obmalloc.c:1996)
==50552==    by 0x49A7496: UnknownInlinedFun (obmalloc.c:712)
==50552==    by 0x49A7496: new_keys_object (dictobject.c:632)
==50552==    by 0x49A7820: dictresize (dictobject.c:1429)
==50552==    by 0x49A7FEA: UnknownInlinedFun (dictobject.c:1183)
==50552==    by 0x49A7FEA: insertdict (dictobject.c:1248)
==50552==    by 0x49DB52D: UnknownInlinedFun (dictobject.c:1906)
==50552==    by 0x49DB52D: add_subclass (typeobject.c:6546)
==50552==    by 0x4928B8A: UnknownInlinedFun (typeobject.c:6346)
==50552==    by 0x4928B8A: type_ready (typeobject.c:6477)
==50552==    by 0x492C56D: PyType_Ready (typeobject.c:6507)
==50552==    by 0x4AF883E: UnknownInlinedFun (typeobject.c:3189)
==50552==    by 0x4AF883E: type_new (typeobject.c:3323)
==50552==    by 0x494F8FD: type_call (typeobject.c:1091)
==50552==    by 0x49433BC: _PyObject_MakeTpCall (call.c:214)
==50552==    by 0x49D9799: _PyObject_FastCallDictTstate (call.c:141)
==50552== 
==50552== 21,036 bytes in 16 blocks are still reachable in loss record 63 of 65
==50552==    at 0x4849BF3: calloc (vg_replace_malloc.c:1675)
==50552==    by 0x400BB7D: calloc (rtld-malloc.h:44)
==50552==    by 0x400BB7D: _dl_new_object (dl-object.c:92)
==50552==    by 0x4007269: _dl_map_object_from_fd (dl-load.c:1053)
==50552==    by 0x4008C97: _dl_map_object (dl-load.c:2249)
==50552==    by 0x400C99B: dl_open_worker_begin (dl-open.c:578)
==50552==    by 0x4001522: _dl_catch_exception (dl-catch.c:237)
==50552==    by 0x400C0DF: dl_open_worker (dl-open.c:803)
==50552==    by 0x4001522: _dl_catch_exception (dl-catch.c:237)
==50552==    by 0x400C533: _dl_open (dl-open.c:905)
==50552==    by 0x4E499E3: ??? (in /usr/lib/libc.so.6)
==50552==    by 0x4001522: _dl_catch_exception (dl-catch.c:237)
==50552==    by 0x4001678: _dl_catch_error (dl-catch.c:256)
==50552== 
==50552== 131,072 bytes in 1 blocks are still reachable in loss record 64 of 65
==50552==    at 0x4849BF3: calloc (vg_replace_malloc.c:1675)
==50552==    by 0x48EFDC6: UnknownInlinedFun (obmalloc.c:595)
==50552==    by 0x48EFDC6: UnknownInlinedFun (obmalloc.c:1471)
==50552==    by 0x48EFDC6: arena_map_mark_used (obmalloc.c:1514)
==50552==    by 0x4917A4C: UnknownInlinedFun (obmalloc.c:1644)
==50552==    by 0x4917A4C: allocate_from_new_pool (obmalloc.c:1824)
==50552==    by 0x4917F34: UnknownInlinedFun (obmalloc.c:1988)
==50552==    by 0x4917F34: _PyObject_Malloc (obmalloc.c:1998)
==50552==    by 0x49736AE: UnknownInlinedFun (obmalloc.c:712)
==50552==    by 0x49736AE: gc_alloc (gcmodule.c:2283)
==50552==    by 0x4973765: _PyObject_GC_New (gcmodule.c:2298)
==50552==    by 0x49A6074: PyList_New (listobject.c:179)
==50552==    by 0x4AFBED2: UnknownInlinedFun (gcmodule.c:164)
==50552==    by 0x4AFBED2: pycore_interp_init (pylifecycle.c:835)
==50552==    by 0x4AFF44C: UnknownInlinedFun (pylifecycle.c:901)
==50552==    by 0x4AFF44C: pyinit_core.constprop.0 (pylifecycle.c:1064)
==50552==    by 0x4B11454: Py_InitializeFromConfig.part.0 (pylifecycle.c:1254)
==50552==    by 0x4B118B8: UnknownInlinedFun (pylifecycle.c:1239)
==50552==    by 0x4B118B8: pymain_init (main.c:67)
==50552==    by 0x4B13D72: UnknownInlinedFun (main.c:701)
==50552==    by 0x4B13D72: Py_BytesMain (main.c:734)
==50552== 
==50552== 262,144 bytes in 1 blocks are still reachable in loss record 65 of 65
==50552==    at 0x4849BF3: calloc (vg_replace_malloc.c:1675)
==50552==    by 0x48EFE42: UnknownInlinedFun (obmalloc.c:595)
==50552==    by 0x48EFE42: UnknownInlinedFun (obmalloc.c:1459)
==50552==    by 0x48EFE42: arena_map_mark_used (obmalloc.c:1514)
==50552==    by 0x4917A4C: UnknownInlinedFun (obmalloc.c:1644)
==50552==    by 0x4917A4C: allocate_from_new_pool (obmalloc.c:1824)
==50552==    by 0x4917F34: UnknownInlinedFun (obmalloc.c:1988)
==50552==    by 0x4917F34: _PyObject_Malloc (obmalloc.c:1998)
==50552==    by 0x49736AE: UnknownInlinedFun (obmalloc.c:712)
==50552==    by 0x49736AE: gc_alloc (gcmodule.c:2283)
==50552==    by 0x4973765: _PyObject_GC_New (gcmodule.c:2298)
==50552==    by 0x49A6074: PyList_New (listobject.c:179)
==50552==    by 0x4AFBED2: UnknownInlinedFun (gcmodule.c:164)
==50552==    by 0x4AFBED2: pycore_interp_init (pylifecycle.c:835)
==50552==    by 0x4AFF44C: UnknownInlinedFun (pylifecycle.c:901)
==50552==    by 0x4AFF44C: pyinit_core.constprop.0 (pylifecycle.c:1064)
==50552==    by 0x4B11454: Py_InitializeFromConfig.part.0 (pylifecycle.c:1254)
==50552==    by 0x4B118B8: UnknownInlinedFun (pylifecycle.c:1239)
==50552==    by 0x4B118B8: pymain_init (main.c:67)
==50552==    by 0x4B13D72: UnknownInlinedFun (main.c:701)
==50552==    by 0x4B13D72: Py_BytesMain (main.c:734)
==50552== 
==50552== LEAK SUMMARY:
==50552==    definitely lost: 0 bytes in 0 blocks
==50552==    indirectly lost: 0 bytes in 0 blocks
==50552==      possibly lost: 0 bytes in 0 blocks
==50552==    still reachable: 569,430 bytes in 210 blocks
==50552==         suppressed: 0 bytes in 0 blocks
==50552== 
==50552== For lists of detected and suppressed errors, rerun with: -s
==50552== ERROR SUMMARY: 0 errors from 0 contexts (suppressed: 0 from 0)
